Workbook

Sheet Read me
B2: Build-up Explorer (thermal mass toolkit, model 1)
B4: What it does:
B5: Computes the ISO 13786 dynamic thermal properties of a layered wall, floor or roof (U, admittance |Y| and its time lead, decrement factor f and time lag, internal areal heat capacity κ₁) and compares them with the ISO 52016-1 / HEM five-node lump for each mass class.
B6: Everything is a live formula. The heat-transfer matrices are complex numbers, built with COMPLEX, IMPRODUCT, IMSUM and IMDIV and multiplied layer by layer from the room side out.
B8: How to use it:
B9: 1. Calculator: pick a build-up key in B4 (or 'Custom'), a period in B5 (24 h for the daily cycle), and optionally a five-node class in B6.
B10: 2. Library: the 29 build-ups from the Python model, plus a Custom row at the bottom you can edit. Layer values are mm, or m²K/W for a 'Cavity'.
B11: 3. Library results: every build-up at once, with the Python model's values alongside for checking.
B12: 4. Materials and Classes: edit material properties or the class node shares; everything follows.
B14: Far side: 'ext' adds Rse = 0.04; 'ground' adds 1 m of clay soil; 'adiabatic' (half a partition) adds a very large resistance; 'room' (an intermediate floor) adds Rsi on the far face.
B15: Companion files: the web app Build-up Explorer and models/buildups.py in gwilma/thermal_mass_in_buildings give the same numbers.
B17: Colour key:
... B20: Plain black: calculation steps and data.

Sheet Engine
A1: Calculation blocks for the Library results sheet (one ISO chain and one five-node chain per build-up)
A2: Period, hours | B2: 24
A5: W1 | B5: class | C5: =INDEX(Library!$F$5:$F$34,MATCH(A5,Library!$A$5:$A$34,0)) -> IE
A6: W1: ISO 13786 | T6: row → | U6: =MATCH($A$5,Library!$A$5:$A$34,0) -> 1 | V6: far side | W6: =INDEX(Library!$D$5:$D$34,$U$6) -> ext | X6: Rsi | Y6: =INDEX(Library!$E$5:$E$34,$U$6) -> 0.13
B7: Type | C7: Material | D7: d m | E7: λ | F7: ρ | G7: c | H7: R m²K/W | I7: δ m | J7: x = d/δ | K7: z11 | L7: z12 | M7: z21 | N7: z22 | O7: P11 | P7: P12 | Q7: P21 | R7: P22 | S7: R part | T7: ρcd J/m²K
A8: Rsi | B8: res | H8: =$Y$6 -> 0.13 | I8: =IF(B8="mass",SQRT(E8*($B$2*3600)/(PI()*F8*G8)),0) -> 0 | J8: =IF(B8="mass",D8/I8,0) -> 0 | K8: =IF(B8="mass",COMPLEX(COSH(J8)*COS(J8),SINH(J8)*SIN(J8)),COMPLEX(1,0)) -> 1 | L8: =IF(B8="mass",COMPLEX(-I8/(2*E8)*(SINH(J8)*COS(J8)+COSH(J8)*SIN(J8)),-I8/(2*E8)*(COSH(J8)*SIN(J8)-SINH(J8)*COS(J8))),COMPLEX(-H8,0)) -> -0.13 | M8: =IF(B8="mass",COMPLEX(-E8/I8*(SINH(J8)*COS(J8)-COSH(J8)*SIN(J8)),-E8/I8*(SINH(J8)*COS(J8)+COSH(J8)*SIN(J8))),COMPLEX(0,0)) -> 0 | N8: =K8 -> 1 | O8: =K8 -> 1 | P8: =L8 -> -0.13 | Q8: =M8 -> 0 | R8: =N8 -> 1 | S8: =IF(B8="mass",D8/E8,H8) -> 0.13 | T8: =IF(B8="mass",F8*G8*D8,0) -> 0
A9: Layer 1 | B9: =IF(C9="","none",IF(C9="Cavity","res","mass")) -> mass | C9: =IF(INDEX(Library!$G$5:$G$34,$U$6)="","",INDEX(Library!$G$5:$G$34,$U$6)) -> gypsum plaster | D9: =IF(B9="mass",INDEX(Library!$H$5:$H$34,$U$6)/1000,0) -> 0.013 | E9: =IF(B9="mass",INDEX(Materials!$B$5:$B$28,MATCH(C9,Materials!$A$5:$A$28,0)),0) -> 0.5 | F9: =IF(B9="mass",INDEX(Materials!$C$5:$C$28,MATCH(C9,Materials!$A$5:$A$28,0)),0) -> 1300 | G9: =IF(B9="mass",INDEX(Materials!$D$5:$D$28,MATCH(C9,Materials!$A$5:$A$28,0)),0) -> 1000 | H9: =IF(B9="res",INDEX(Library!$H$5:$H$34,$U$6),0) -> 0 | I9: =IF(B9="mass",SQRT(E9*($B$2*3600)/(PI()*F9*G9)),0) -> 0.10284786 | J9: =IF(B9="mass",D9/I9,0) -> 0.1264003 | K9: =IF(B9="mass",COMPLEX(COSH(J9)*COS(J9),SINH(J9)*SIN(J9)),COMPLEX(1,0)) -> 0.999957455752033+0.0159769895455509i | L9: =IF(B9="mass",COMPLEX(-I9/(2*E9)*(SINH(J9)*COS(J9)+COSH(J9)*SIN(J9)),-I9/(2*E9)*(COSH(J9)*SIN(J9)-SINH(J9)*COS(J9))),COMPLEX(-H9,0)) -> -0.0259997787698508-0.00013846746714729i | M9: =IF(B9="mass",COMPLEX(-E9/I9*(SINH(J9)*COS(J9)-COSH(J9)*SIN(J9)),-E9/I9*(SINH(J9)*COS(J9)+COSH(J9)*SIN(J9))),COMPLEX(0,0)) -> 0.00654526494000515-1.22899222421088i | N9: =K9 -> 0.999957455752033+0.0159769895455509i | O9: =IMSUM(IMPRODUCT(K9,O8),IMPRODUCT(L9,Q8)) -> 0.999957455752033+0.0159769895455509i | P9: =IMSUM(IMPRODUCT(K9,P8),IMPRODUCT(L9,R8)) -> -0.155994248017615-0.00221547610806891i | Q9: =IMSUM(IMPRODUCT(M9,O8),IMPRODUCT(N9,Q8)) -> 0.00654526494000515-1.22899222421088i | R9: =IMSUM(IMPRODUCT(M9,P8),IMPRODUCT(N9,R8)) -> 0.999106571309832+0.175745978692965i | S9: =IF(B9="mass",D9/E9,H9) -> 0.026 | T9: =IF(B9="mass",F9*G9*D9,0) -> 16900
A10: Layer 2 | B10: =IF(C10="","none",IF(C10="Cavity","res","mass")) -> mass | C10: =IF(INDEX(Library!$I$5:$I$34,$U$6)="","",INDEX(Library!$I$5:$I$34,$U$6)) -> dense block | D10: =IF(B10="mass",INDEX(Library!$J$5:$J$34,$U$6)/1000,0) -> 0.1 | E10: =IF(B10="mass",INDEX(Materials!$B$5:$B$28,MATCH(C10,Materials!$A$5:$A$28,0)),0) -> 1.13 | F10: =IF(B10="mass",INDEX(Materials!$C$5:$C$28,MATCH(C10,Materials!$A$5:$A$28,0)),0) -> 2000 | G10: =IF(B10="mass",INDEX(Materials!$D$5:$D$28,MATCH(C10,Materials!$A$5:$A$28,0)),0) -> 1000 | H10: =IF(B10="res",INDEX(Library!$J$5:$J$34,$U$6),0) -> 0 | I10: =IF(B10="mass",SQRT(E10*($B$2*3600)/(PI()*F10*G10)),0) -> 0.12465398 | J10: =IF(B10="mass",D10/I10,0) -> 0.80222066 | K10: =IF(B10="mass",COMPLEX(COSH(J10)*COS(J10),SINH(J10)*SIN(J10)),COMPLEX(1,0)) -> 0.931040246556561+0.640597397168838i | L10: =IF(B10="mass",COMPLEX(-I10/(2*E10)*(SINH(J10)*COS(J10)+COSH(J10)*SIN(J10)),-I10/(2*E10)*(COSH(J10)*SIN(J10)-SINH(J10)*COS(J10))),COMPLEX(-H10,0)) -> -0.0872745132646335-0.0189465784438884i | M10: =IF(B10="mass",COMPLEX(-E10/I10*(SINH(J10)*COS(J10)-COSH(J10)*SIN(J10)),-E10/I10*(SINH(J10)*COS(J10)+COSH(J10)*SIN(J10))),COMPLEX(0,0)) -> 3.11390498909631-14.3437266565329i | N10: =K10 -> 0.931040246556561+0.640597397168838i | O10: =IMSUM(IMPRODUCT(K10,O9),IMPRODUCT(L10,Q9)) -> 0.896909385837204+0.762581051518449i | P10: =IMSUM(IMPRODUCT(K10,P9),IMPRODUCT(L10,R9)) -> -0.227684449646465-0.136260002451062i | Q10: =IMSUM(IMPRODUCT(M10,O9),IMPRODUCT(N10,Q9)) -> 4.13632520623972-15.4334139297736i | R10: =IMSUM(IMPRODUCT(M10,P9),IMPRODUCT(N10,R9)) -> 0.300096561094385+3.03429171985891i | S10: =IF(B10="mass",D10/E10,H10) -> 0.088495575 | T10: =IF(B10="mass",F10*G10*D10,0) -> 200000
A11: Layer 3 | B11: =IF(C11="","none",IF(C11="Cavity","res","mass")) -> mass | C11: =IF(INDEX(Library!$K$5:$K$34,$U$6)="","",INDEX(Library!$K$5:$K$34,$U$6)) -> mineral wool | D11: =IF(B11="mass",INDEX(Library!$L$5:$L$34,$U$6)/1000,0) -> 0.15 | E11: =IF(B11="mass",INDEX(Materials!$B$5:$B$28,MATCH(C11,Materials!$A$5:$A$28,0)),0) -> 0.035 | F11: =IF(B11="mass",INDEX(Materials!$C$5:$C$28,MATCH(C11,Materials!$A$5:$A$28,0)),0) -> 30 | G11: =IF(B11="mass",INDEX(Materials!$D$5:$D$28,MATCH(C11,Materials!$A$5:$A$28,0)),0) -> 1030 | H11: =IF(B11="res",INDEX(Library!$L$5:$L$34,$U$6),0) -> 0 | I11: =IF(B11="mass",SQRT(E11*($B$2*3600)/(PI()*F11*G11)),0) -> 0.17649675 | J11: =IF(B11="mass",D11/I11,0) -> 0.849874 | K11: =IF(B11="mass",COMPLEX(COSH(J11)*COS(J11),SINH(J11)*SIN(J11)),COMPLEX(1,0)) -> 0.913158518565511+0.718100720020173i | L11: =IF(B11="mass",COMPLEX(-I11/(2*E11)*(SINH(J11)*COS(J11)+COSH(J11)*SIN(J11)),-I11/(2*E11)*(COSH(J11)*SIN(J11)-SINH(J11)*COS(J11))),COMPLEX(-H11,0)) -> -4.21123759620779-1.02927418634689i | M11: =IF(B11="mass",COMPLEX(-E11/I11*(SINH(J11)*COS(J11)-COSH(J11)*SIN(J11)),-E11/I11*(SINH(J11)*COS(J11)+COSH(J11)*SIN(J11))),COMPLEX(0,0)) -> 0.0809512819555347-0.331209202129424i | N11: =K11 -> 0.913158518565511+0.718100720020173i | O11: =IMSUM(IMPRODUCT(K11,O10),IMPRODUCT(L11,Q10)) -> -33.0328523398916+62.0767888768344i | P11: =IMSUM(IMPRODUCT(K11,P10),IMPRODUCT(L11,R10)) -> 1.74927663165403-13.3749323614843i | Q11: =IMSUM(IMPRODUCT(M11,O10),IMPRODUCT(N11,Q10)) -> 15.1850460791887-11.3581880200322i | R11: =IMSUM(IMPRODUCT(M11,P10),IMPRODUCT(N11,R10)) -> -1.96845325240057+3.05066965142642i | S11: =IF(B11="mass",D11/E11,H11) -> 4.2857143 | T11: =IF(B11="mass",F11*G11*D11,0) -> 4635
A12: Layer 4 | B12: =IF(C12="","none",IF(C12="Cavity","res","mass")) -> mass | C12: =IF(INDEX(Library!$M$5:$M$34,$U$6)="","",INDEX(Library!$M$5:$M$34,$U$6)) -> brick | D12: =IF(B12="mass",INDEX(Library!$N$5:$N$34,$U$6)/1000,0) -> 0.102 | E12: =IF(B12="mass",INDEX(Materials!$B$5:$B$28,MATCH(C12,Materials!$A$5:$A$28,0)),0) -> 0.77 | F12: =IF(B12="mass",INDEX(Materials!$C$5:$C$28,MATCH(C12,Materials!$A$5:$A$28,0)),0) -> 1700 | G12: =IF(B12="mass",INDEX(Materials!$D$5:$D$28,MATCH(C12,Materials!$A$5:$A$28,0)),0) -> 800 | H12: =IF(B12="res",INDEX(Library!$N$5:$N$34,$U$6),0) -> 0 | I12: =IF(B12="mass",SQRT(E12*($B$2*3600)/(PI()*F12*G12)),0) -> 0.1247837 | J12: =IF(B12="mass",D12/I12,0) -> 0.81741448 | K12: =IF(B12="mass",COMPLEX(COSH(J12)*COS(J12),SINH(J12)*SIN(J12)),COMPLEX(1,0)) -> 0.925671349743335+0.664853161913343i | L12: =IF(B12="mass",COMPLEX(-I12/(2*E12)*(SINH(J12)*COS(J12)+COSH(J12)*SIN(J12)),-I12/(2*E12)*(COSH(J12)*SIN(J12)-SINH(J12)*COS(J12))),COMPLEX(-H12,0)) -> -0.130497374771535-0.0294407447988599i | M12: =IF(B12="mass",COMPLEX(-E12/I12*(SINH(J12)*COS(J12)-COSH(J12)*SIN(J12)),-E12/I12*(SINH(J12)*COS(J12)+COSH(J12)*SIN(J12))),COMPLEX(0,0)) -> 2.24204617217389-9.93796663719564i | N12: =K12 -> 0.925671349743335+0.664853161913343i | O12: =IMSUM(IMPRODUCT(K12,O11),IMPRODUCT(L12,Q11)) -> -74.1655165415243+36.5358632745572i | P12: =IMSUM(IMPRODUCT(K12,P11),IMPRODUCT(L12,R11)) -> 10.8583133000796-11.5579312431186i | Q12: =IMSUM(IMPRODUCT(M12,O11),IMPRODUCT(N12,Q11)) -> 564.46376597634+467.040288031813i | R12: =IMSUM(IMPRODUCT(M12,P11),IMPRODUCT(N12,R11)) -> -132.848060749866-45.8562835838345i | S12: =IF(B12="mass",D12/E12,H12) -> 0.13246753 | T12: =IF(B12="mass",F12*G12*D12,0) -> 138720
A13: Layer 5 | B13: =IF(C13="","none",IF(C13="Cavity","res","mass")) -> none | C13: =IF(INDEX(Library!$O$5:$O$34,$U$6)="","",INDEX(Library!$O$5:$O$34,$U$6)) | D13: =IF(B13="mass",INDEX(Library!$P$5:$P$34,$U$6)/1000,0) -> 0 | E13: =IF(B13="mass",INDEX(Materials!$B$5:$B$28,MATCH(C13,Materials!$A$5:$A$28,0)),0) -> 0 | F13: =IF(B13="mass",INDEX(Materials!$C$5:$C$28,MATCH(C13,Materials!$A$5:$A$28,0)),0) -> 0 | G13: =IF(B13="mass",INDEX(Materials!$D$5:$D$28,MATCH(C13,Materials!$A$5:$A$28,0)),0) -> 0 | H13: =IF(B13="res",INDEX(Library!$P$5:$P$34,$U$6),0) -> 0 | I13: =IF(B13="mass",SQRT(E13*($B$2*3600)/(PI()*F13*G13)),0) -> 0 | J13: =IF(B13="mass",D13/I13,0) -> 0 | K13: =IF(B13="mass",COMPLEX(COSH(J13)*COS(J13),SINH(J13)*SIN(J13)),COMPLEX(1,0)) -> 1 | L13: =IF(B13="mass",COMPLEX(-I13/(2*E13)*(SINH(J13)*COS(J13)+COSH(J13)*SIN(J13)),-I13/(2*E13)*(COSH(J13)*SIN(J13)-SINH(J13)*COS(J13))),COMPLEX(-H13,0)) -> -0 | M13: =IF(B13="mass",COMPLEX(-E13/I13*(SINH(J13)*COS(J13)-COSH(J13)*SIN(J13)),-E13/I13*(SINH(J13)*COS(J13)+COSH(J13)*SIN(J13))),COMPLEX(0,0)) -> 0 | N13: =K13 -> 1 | O13: =IMSUM(IMPRODUCT(K13,O12),IMPRODUCT(L13,Q12)) -> -74.1655165415243+36.5358632745572i | P13: =IMSUM(IMPRODUCT(K13,P12),IMPRODUCT(L13,R12)) -> 10.8583133000796-11.5579312431186i | Q13: =IMSUM(IMPRODUCT(M13,O12),IMPRODUCT(N13,Q12)) -> 564.46376597634+467.040288031813i | R13: =IMSUM(IMPRODUCT(M13,P12),IMPRODUCT(N13,R12)) -> -132.848060749866-45.8562835838345i | S13: =IF(B13="mass",D13/E13,H13) -> 0 | T13: =IF(B13="mass",F13*G13*D13,0) -> 0
A14: Layer 6 | B14: =IF(C14="","none",IF(C14="Cavity","res","mass")) -> none | C14: =IF(INDEX(Library!$Q$5:$Q$34,$U$6)="","",INDEX(Library!$Q$5:$Q$34,$U$6)) | D14: =IF(B14="mass",INDEX(Library!$R$5:$R$34,$U$6)/1000,0) -> 0 | E14: =IF(B14="mass",INDEX(Materials!$B$5:$B$28,MATCH(C14,Materials!$A$5:$A$28,0)),0) -> 0 | F14: =IF(B14="mass",INDEX(Materials!$C$5:$C$28,MATCH(C14,Materials!$A$5:$A$28,0)),0) -> 0 | G14: =IF(B14="mass",INDEX(Materials!$D$5:$D$28,MATCH(C14,Materials!$A$5:$A$28,0)),0) -> 0 | H14: =IF(B14="res",INDEX(Library!$R$5:$R$34,$U$6),0) -> 0 | I14: =IF(B14="mass",SQRT(E14*($B$2*3600)/(PI()*F14*G14)),0) -> 0 | J14: =IF(B14="mass",D14/I14,0) -> 0 | K14: =IF(B14="mass",COMPLEX(COSH(J14)*COS(J14),SINH(J14)*SIN(J14)),COMPLEX(1,0)) -> 1 | L14: =IF(B14="mass",COMPLEX(-I14/(2*E14)*(SINH(J14)*COS(J14)+COSH(J14)*SIN(J14)),-I14/(2*E14)*(COSH(J14)*SIN(J14)-SINH(J14)*COS(J14))),COMPLEX(-H14,0)) -> -0 | M14: =IF(B14="mass",COMPLEX(-E14/I14*(SINH(J14)*COS(J14)-COSH(J14)*SIN(J14)),-E14/I14*(SINH(J14)*COS(J14)+COSH(J14)*SIN(J14))),COMPLEX(0,0)) -> 0 | N14: =K14 -> 1 | O14: =IMSUM(IMPRODUCT(K14,O13),IMPRODUCT(L14,Q13)) -> -74.1655165415243+36.5358632745572i | P14: =IMSUM(IMPRODUCT(K14,P13),IMPRODUCT(L14,R13)) -> 10.8583133000796-11.5579312431186i | Q14: =IMSUM(IMPRODUCT(M14,O13),IMPRODUCT(N14,Q13)) -> 564.46376597634+467.040288031813i | R14: =IMSUM(IMPRODUCT(M14,P13),IMPRODUCT(N14,R13)) -> -132.848060749866-45.8562835838345i | S14: =IF(B14="mass",D14/E14,H14) -> 0 | T14: =IF(B14="mass",F14*G14*D14,0) -> 0
A15: Layer 7 | B15: =IF(C15="","none",IF(C15="Cavity","res","mass")) -> none | C15: =IF(INDEX(Library!$S$5:$S$34,$U$6)="","",INDEX(Library!$S$5:$S$34,$U$6)) | D15: =IF(B15="mass",INDEX(Library!$T$5:$T$34,$U$6)/1000,0) -> 0 | E15: =IF(B15="mass",INDEX(Materials!$B$5:$B$28,MATCH(C15,Materials!$A$5:$A$28,0)),0) -> 0 | F15: =IF(B15="mass",INDEX(Materials!$C$5:$C$28,MATCH(C15,Materials!$A$5:$A$28,0)),0) -> 0 | G15: =IF(B15="mass",INDEX(Materials!$D$5:$D$28,MATCH(C15,Materials!$A$5:$A$28,0)),0) -> 0 | H15: =IF(B15="res",INDEX(Library!$T$5:$T$34,$U$6),0) -> 0 | I15: =IF(B15="mass",SQRT(E15*($B$2*3600)/(PI()*F15*G15)),0) -> 0 | J15: =IF(B15="mass",D15/I15,0) -> 0 | K15: =IF(B15="mass",COMPLEX(COSH(J15)*COS(J15),SINH(J15)*SIN(J15)),COMPLEX(1,0)) -> 1 | L15: =IF(B15="mass",COMPLEX(-I15/(2*E15)*(SINH(J15)*COS(J15)+COSH(J15)*SIN(J15)),-I15/(2*E15)*(COSH(J15)*SIN(J15)-SINH(J15)*COS(J15))),COMPLEX(-H15,0)) -> -0 | M15: =IF(B15="mass",COMPLEX(-E15/I15*(SINH(J15)*COS(J15)-COSH(J15)*SIN(J15)),-E15/I15*(SINH(J15)*COS(J15)+COSH(J15)*SIN(J15))),COMPLEX(0,0)) -> 0 | N15: =K15 -> 1 | O15: =IMSUM(IMPRODUCT(K15,O14),IMPRODUCT(L15,Q14)) -> -74.1655165415243+36.5358632745572i | P15: =IMSUM(IMPRODUCT(K15,P14),IMPRODUCT(L15,R14)) -> 10.8583133000796-11.5579312431186i | Q15: =IMSUM(IMPRODUCT(M15,O14),IMPRODUCT(N15,Q14)) -> 564.46376597634+467.040288031813i | R15: =IMSUM(IMPRODUCT(M15,P14),IMPRODUCT(N15,R14)) -> -132.848060749866-45.8562835838345i | S15: =IF(B15="mass",D15/E15,H15) -> 0 | T15: =IF(B15="mass",F15*G15*D15,0) -> 0
A16: Layer 8 | B16: =IF(C16="","none",IF(C16="Cavity","res","mass")) -> none | C16: =IF(INDEX(Library!$U$5:$U$34,$U$6)="","",INDEX(Library!$U$5:$U$34,$U$6)) | D16: =IF(B16="mass",INDEX(Library!$V$5:$V$34,$U$6)/1000,0) -> 0 | E16: =IF(B16="mass",INDEX(Materials!$B$5:$B$28,MATCH(C16,Materials!$A$5:$A$28,0)),0) -> 0 | F16: =IF(B16="mass",INDEX(Materials!$C$5:$C$28,MATCH(C16,Materials!$A$5:$A$28,0)),0) -> 0 | G16: =IF(B16="mass",INDEX(Materials!$D$5:$D$28,MATCH(C16,Materials!$A$5:$A$28,0)),0) -> 0 | H16: =IF(B16="res",INDEX(Library!$V$5:$V$34,$U$6),0) -> 0 | I16: =IF(B16="mass",SQRT(E16*($B$2*3600)/(PI()*F16*G16)),0) -> 0 | J16: =IF(B16="mass",D16/I16,0) -> 0 | K16: =IF(B16="mass",COMPLEX(COSH(J16)*COS(J16),SINH(J16)*SIN(J16)),COMPLEX(1,0)) -> 1 | L16: =IF(B16="mass",COMPLEX(-I16/(2*E16)*(SINH(J16)*COS(J16)+COSH(J16)*SIN(J16)),-I16/(2*E16)*(COSH(J16)*SIN(J16)-SINH(J16)*COS(J16))),COMPLEX(-H16,0)) -> -0 | M16: =IF(B16="mass",COMPLEX(-E16/I16*(SINH(J16)*COS(J16)-COSH(J16)*SIN(J16)),-E16/I16*(SINH(J16)*COS(J16)+COSH(J16)*SIN(J16))),COMPLEX(0,0)) -> 0 | N16: =K16 -> 1 | O16: =IMSUM(IMPRODUCT(K16,O15),IMPRODUCT(L16,Q15)) -> -74.1655165415243+36.5358632745572i | P16: =IMSUM(IMPRODUCT(K16,P15),IMPRODUCT(L16,R15)) -> 10.8583133000796-11.5579312431186i | Q16: =IMSUM(IMPRODUCT(M16,O15),IMPRODUCT(N16,Q15)) -> 564.46376597634+467.040288031813i | R16: =IMSUM(IMPRODUCT(M16,P15),IMPRODUCT(N16,R15)) -> -132.848060749866-45.8562835838345i | S16: =IF(B16="mass",D16/E16,H16) -> 0 | T16: =IF(B16="mass",F16*G16*D16,0) -> 0
A17: Far-side layer | B17: =IF($W$6="ground","mass",IF($W$6="adiabatic","res","none")) -> none | C17: =IF($W$6="ground","clay soil","") | D17: =IF(B17="mass",1,0) -> 0 | E17: =IF(B17="mass",INDEX(Materials!$B$5:$B$28,MATCH(C17,Materials!$A$5:$A$28,0)),0) -> 0 | F17: =IF(B17="mass",INDEX(Materials!$C$5:$C$28,MATCH(C17,Materials!$A$5:$A$28,0)),0) -> 0 | G17: =IF(B17="mass",INDEX(Materials!$D$5:$D$28,MATCH(C17,Materials!$A$5:$A$28,0)),0) -> 0 | H17: =IF(B17="res",1000000,0) -> 0 | I17: =IF(B17="mass",SQRT(E17*($B$2*3600)/(PI()*F17*G17)),0) -> 0 | J17: =IF(B17="mass",D17/I17,0) -> 0 | K17: =IF(B17="mass",COMPLEX(COSH(J17)*COS(J17),SINH(J17)*SIN(J17)),COMPLEX(1,0)) -> 1 | L17: =IF(B17="mass",COMPLEX(-I17/(2*E17)*(SINH(J17)*COS(J17)+COSH(J17)*SIN(J17)),-I17/(2*E17)*(COSH(J17)*SIN(J17)-SINH(J17)*COS(J17))),COMPLEX(-H17,0)) -> -0 | M17: =IF(B17="mass",COMPLEX(-E17/I17*(SINH(J17)*COS(J17)-COSH(J17)*SIN(J17)),-E17/I17*(SINH(J17)*COS(J17)+COSH(J17)*SIN(J17))),COMPLEX(0,0)) -> 0 | N17: =K17 -> 1 | O17: =IMSUM(IMPRODUCT(K17,O16),IMPRODUCT(L17,Q16)) -> -74.1655165415243+36.5358632745572i | P17: =IMSUM(IMPRODUCT(K17,P16),IMPRODUCT(L17,R16)) -> 10.8583133000796-11.5579312431186i | Q17: =IMSUM(IMPRODUCT(M17,O16),IMPRODUCT(N17,Q16)) -> 564.46376597634+467.040288031813i | R17: =IMSUM(IMPRODUCT(M17,P16),IMPRODUCT(N17,R16)) -> -132.848060749866-45.8562835838345i | S17: =IF(B17="mass",D17/E17,H17) -> 0 | T17: =IF(B17="mass",F17*G17*D17,0) -> 0
A18: Rse | B18: res | H18: =IF($W$6="ext",0.04,IF($W$6="room",$Y$6,0)) -> 0.04 | I18: =IF(B18="mass",SQRT(E18*($B$2*3600)/(PI()*F18*G18)),0) -> 0 | J18: =IF(B18="mass",D18/I18,0) -> 0 | K18: =IF(B18="mass",COMPLEX(COSH(J18)*COS(J18),SINH(J18)*SIN(J18)),COMPLEX(1,0)) -> 1 | L18: =IF(B18="mass",COMPLEX(-I18/(2*E18)*(SINH(J18)*COS(J18)+COSH(J18)*SIN(J18)),-I18/(2*E18)*(COSH(J18)*SIN(J18)-SINH(J18)*COS(J18))),COMPLEX(-H18,0)) -> -0.04 | M18: =IF(B18="mass",COMPLEX(-E18/I18*(SINH(J18)*COS(J18)-COSH(J18)*SIN(J18)),-E18/I18*(SINH(J18)*COS(J18)+COSH(J18)*SIN(J18))),COMPLEX(0,0)) -> 0 | N18: =K18 -> 1 | O18: =IMSUM(IMPRODUCT(K18,O17),IMPRODUCT(L18,Q17)) -> -96.7440671805779+17.8542517532847i | P18: =IMSUM(IMPRODUCT(K18,P17),IMPRODUCT(L18,R17)) -> 16.1722357300742-9.72367989976522i | Q18: =IMSUM(IMPRODUCT(M18,O17),IMPRODUCT(N18,Q17)) -> 564.46376597634+467.040288031813i | R18: =IMSUM(IMPRODUCT(M18,P17),IMPRODUCT(N18,R17)) -> -132.848060749866-45.8562835838345i | S18: =IF(B18="mass",D18/E18,H18) -> 0.04 | T18: =IF(B18="mass",F18*G18*D18,0) -> 0
A19: U W/m²K | B19: =IF(OR($W$6="ext",$W$6="ground"),1/SUM(S8:S18),"–") -> 0.21264482 | C19: |Y| W/m²K | D19: =IMABS(IMDIV(IMPRODUCT(O18,COMPLEX(-1,0)),P18)) -> 5.2133448 | E19: Y lead h | F19: =IMARGUMENT(IMDIV(IMPRODUCT(O18,COMPLEX(-1,0)),P18))*$B$2/(2*PI()) -> 1.3706898 | G19: f | H19: =IF($W$6="ext",IMABS(IMDIV(COMPLEX(-1,0),P18))*SUM(S8:S18),"–") -> 0.2492095 | I19: lag h | J19: =IF($W$6="ext",MOD(-IMARGUMENT(IMDIV(COMPLEX(-1,0),P18))*$B$2/(2*PI()),24),"–") -> 9.9322194 | K19: κ₁ kJ/m²K | L19: =($B$2*3600)/(2*PI())*IMABS(IMDIV(IMSUB(O18,COMPLEX(1,0)),P18))/1000 -> 72.405364 | M19: κ total kJ/m²K | N19: =SUM(T9:T16)/1000 -> 360.255 | O19: Rc m²K/W | P19: =SUM(S9:S16) -> 4.5326774
A21: W1: five-node
B22: Kind | C22: R or C | K22: z11 | L22: z12 | M22: z21 | N22: z22 | O22: P11 | P22: P12 | Q22: P21 | R22: P22
A23: Rsi | B23: res | C23: =$Y$6 -> 0.13 | K23: =COMPLEX(1,0) -> 1 | L23: =COMPLEX(-C23,0) -> -0.13 | M23: =COMPLEX(0,0) -> 0 | N23: =COMPLEX(1,0) -> 1 | O23: =K23 -> 1 | P23: =L23 -> -0.13 | Q23: =M23 -> 0 | R23: =N23 -> 1
A24: node 5 (room side) | B24: cap | C24: =INDEX(Classes!$B$5:$F$9,MATCH(Engine!$C$5,Classes!$A$5:$A$9,0),5)*(N19*1000) -> 180127.5 | K24: =COMPLEX(1,0) -> 1 | L24: =COMPLEX(0,0) -> 0 | M24: =COMPLEX(0,-(2*PI()/($B$2*3600))*C24) -> -13.0992414516087i | N24: =COMPLEX(1,0) -> 1 | O24: =IMSUM(IMPRODUCT(K24,O23),IMPRODUCT(L24,Q23)) -> 1 | P24: =IMSUM(IMPRODUCT(K24,P23),IMPRODUCT(L24,R23)) -> -0.13 | Q24: =IMSUM(IMPRODUCT(M24,O23),IMPRODUCT(N24,Q23)) -> -13.0992414516087i | R24: =IMSUM(IMPRODUCT(M24,P23),IMPRODUCT(N24,R23)) -> 1+1.70290138870913i
A25: 6/Rc | B25: res | C25: =P19/6 -> 0.75544623 | K25: =COMPLEX(1,0) -> 1 | L25: =COMPLEX(-C25,0) -> -0.755446232233843 | M25: =COMPLEX(0,0) -> 0 | N25: =COMPLEX(1,0) -> 1 | O25: =IMSUM(IMPRODUCT(K25,O24),IMPRODUCT(L25,Q24)) -> 1+9.89577259973917i | P25: =IMSUM(IMPRODUCT(K25,P24),IMPRODUCT(L25,R24)) -> -0.885446232233843-1.28645043796609i | Q25: =IMSUM(IMPRODUCT(M25,O24),IMPRODUCT(N25,Q24)) -> -13.0992414516087i | R25: =IMSUM(IMPRODUCT(M25,P24),IMPRODUCT(N25,R24)) -> 1+1.70290138870913i
A26: node 4 | B26: cap | C26: =INDEX(Classes!$B$5:$F$9,MATCH(Engine!$C$5,Classes!$A$5:$A$9,0),4)*(N19*1000) -> 0 | K26: =COMPLEX(1,0) -> 1 | L26: =COMPLEX(0,0) -> 0 | M26: =COMPLEX(0,-(2*PI()/($B$2*3600))*C26) -> 0 | N26: =COMPLEX(1,0) -> 1 | O26: =IMSUM(IMPRODUCT(K26,O25),IMPRODUCT(L26,Q25)) -> 1+9.89577259973917i | P26: =IMSUM(IMPRODUCT(K26,P25),IMPRODUCT(L26,R25)) -> -0.885446232233843-1.28645043796609i | Q26: =IMSUM(IMPRODUCT(M26,O25),IMPRODUCT(N26,Q25)) -> -13.0992414516087i | R26: =IMSUM(IMPRODUCT(M26,P25),IMPRODUCT(N26,R25)) -> 1+1.70290138870913i
A27: 3/Rc | B27: res | C27: =P19/3 -> 1.5108925 | K27: =COMPLEX(1,0) -> 1 | L27: =COMPLEX(-C27,0) -> -1.51089246446769 | M27: =COMPLEX(0,0) -> 0 | N27: =COMPLEX(1,0) -> 1 | O27: =IMSUM(IMPRODUCT(K27,O26),IMPRODUCT(L27,Q26)) -> 1+29.6873177992176i | P27: =IMSUM(IMPRODUCT(K27,P26),IMPRODUCT(L27,R26)) -> -2.39633869670153-3.85935131389828i | Q27: =IMSUM(IMPRODUCT(M27,O26),IMPRODUCT(N27,Q26)) -> -13.0992414516087i | R27: =IMSUM(IMPRODUCT(M27,P26),IMPRODUCT(N27,R26)) -> 1+1.70290138870913i
A28: node 3 | B28: cap | C28: =INDEX(Classes!$B$5:$F$9,MATCH(Engine!$C$5,Classes!$A$5:$A$9,0),3)*(N19*1000) -> 0 | K28: =COMPLEX(1,0) -> 1 | L28: =COMPLEX(0,0) -> 0 | M28: =COMPLEX(0,-(2*PI()/($B$2*3600))*C28) -> 0 | N28: =COMPLEX(1,0) -> 1 | O28: =IMSUM(IMPRODUCT(K28,O27),IMPRODUCT(L28,Q27)) -> 1+29.6873177992176i | P28: =IMSUM(IMPRODUCT(K28,P27),IMPRODUCT(L28,R27)) -> -2.39633869670153-3.85935131389828i | Q28: =IMSUM(IMPRODUCT(M28,O27),IMPRODUCT(N28,Q27)) -> -13.0992414516087i | R28: =IMSUM(IMPRODUCT(M28,P27),IMPRODUCT(N28,R27)) -> 1+1.70290138870913i
A29: 3/Rc | B29: res | C29: =P19/3 -> 1.5108925 | K29: =COMPLEX(1,0) -> 1 | L29: =COMPLEX(-C29,0) -> -1.51089246446769 | M29: =COMPLEX(0,0) -> 0 | N29: =COMPLEX(1,0) -> 1 | O29: =IMSUM(IMPRODUCT(K29,O28),IMPRODUCT(L29,Q28)) -> 1+49.478862998696i | P29: =IMSUM(IMPRODUCT(K29,P28),IMPRODUCT(L29,R28)) -> -3.90723116116922-6.43225218983047i | Q29: =IMSUM(IMPRODUCT(M29,O28),IMPRODUCT(N29,Q28)) -> -13.0992414516087i | R29: =IMSUM(IMPRODUCT(M29,P28),IMPRODUCT(N29,R28)) -> 1+1.70290138870913i
A30: node 2 | B30: cap | C30: =INDEX(Classes!$B$5:$F$9,MATCH(Engine!$C$5,Classes!$A$5:$A$9,0),2)*(N19*1000) -> 0 | K30: =COMPLEX(1,0) -> 1 | L30: =COMPLEX(0,0) -> 0 | M30: =COMPLEX(0,-(2*PI()/($B$2*3600))*C30) -> 0 | N30: =COMPLEX(1,0) -> 1 | O30: =IMSUM(IMPRODUCT(K30,O29),IMPRODUCT(L30,Q29)) -> 1+49.478862998696i | P30: =IMSUM(IMPRODUCT(K30,P29),IMPRODUCT(L30,R29)) -> -3.90723116116922-6.43225218983047i | Q30: =IMSUM(IMPRODUCT(M30,O29),IMPRODUCT(N30,Q29)) -> -13.0992414516087i | R30: =IMSUM(IMPRODUCT(M30,P29),IMPRODUCT(N30,R29)) -> 1+1.70290138870913i
A31: 6/Rc | B31: res | C31: =P19/6 -> 0.75544623 | K31: =COMPLEX(1,0) -> 1 | L31: =COMPLEX(-C31,0) -> -0.755446232233843 | M31: =COMPLEX(0,0) -> 0 | N31: =COMPLEX(1,0) -> 1 | O31: =IMSUM(IMPRODUCT(K31,O30),IMPRODUCT(L31,Q30)) -> 1+59.3746355984352i | P31: =IMSUM(IMPRODUCT(K31,P30),IMPRODUCT(L31,R30)) -> -4.66267739340306-7.71870262779656i | Q31: =IMSUM(IMPRODUCT(M31,O30),IMPRODUCT(N31,Q30)) -> -13.0992414516087i | R31: =IMSUM(IMPRODUCT(M31,P30),IMPRODUCT(N31,R30)) -> 1+1.70290138870913i
A32: node 1 (outer) | B32: cap | C32: =INDEX(Classes!$B$5:$F$9,MATCH(Engine!$C$5,Classes!$A$5:$A$9,0),1)*(N19*1000) -> 180127.5 | K32: =COMPLEX(1,0) -> 1 | L32: =COMPLEX(0,0) -> 0 | M32: =COMPLEX(0,-(2*PI()/($B$2*3600))*C32) -> -13.0992414516087i | N32: =COMPLEX(1,0) -> 1 | O32: =IMSUM(IMPRODUCT(K32,O31),IMPRODUCT(L32,Q31)) -> 1+59.3746355984352i | P32: =IMSUM(IMPRODUCT(K32,P31),IMPRODUCT(L32,R31)) -> -4.66267739340306-7.71870262779656i | Q32: =IMSUM(IMPRODUCT(M32,O31),IMPRODUCT(N32,Q31)) -> 777.762687805184-26.1984829032174i | R32: =IMSUM(IMPRODUCT(M32,P31),IMPRODUCT(N32,R31)) -> -100.109149414674+62.7804383758533i
A33: far-side layer | B33: as ISO | K33: =K17 -> 1 | L33: =L17 -> -0 | M33: =M17 -> 0 | N33: =N17 -> 1 | O33: =IMSUM(IMPRODUCT(K33,O32),IMPRODUCT(L33,Q32)) -> 1+59.3746355984352i | P33: =IMSUM(IMPRODUCT(K33,P32),IMPRODUCT(L33,R32)) -> -4.66267739340306-7.71870262779656i | Q33: =IMSUM(IMPRODUCT(M33,O32),IMPRODUCT(N33,Q32)) -> 777.762687805184-26.1984829032174i | R33: =IMSUM(IMPRODUCT(M33,P32),IMPRODUCT(N33,R32)) -> -100.109149414674+62.7804383758533i
A34: Rse | B34: as ISO | K34: =K18 -> 1 | L34: =L18 -> -0.04 | M34: =M18 -> 0 | N34: =N18 -> 1 | O34: =IMSUM(IMPRODUCT(K34,O33),IMPRODUCT(L34,Q33)) -> -30.1105075122074+60.4225749145639i | P34: =IMSUM(IMPRODUCT(K34,P33),IMPRODUCT(L34,R33)) -> -0.6583114168161-10.2299201628307i | Q34: =IMSUM(IMPRODUCT(M34,O33),IMPRODUCT(N34,Q33)) -> 777.762687805184-26.1984829032174i | R34: =IMSUM(IMPRODUCT(M34,P33),IMPRODUCT(N34,R33)) -> -100.109149414674+62.7804383758533i
A35: |Y| five-node W/m²K | B35: =IMABS(IMDIV(IMPRODUCT(O34,COMPLEX(-1,0)),P34)) -> 6.5855971
A38: W2 | B38: class | C38: =INDEX(Library!$F$5:$F$34,MATCH(A38,Library!$A$5:$A$34,0)) -> IE
A39: W2: ISO 13786 | T39: row → | U39: =MATCH($A$38,Library!$A$5:$A$34,0) -> 2 | V39: far side | W39: =INDEX(Library!$D$5:$D$34,$U$39) -> ext | X39: Rsi | Y39: =INDEX(Library!$E$5:$E$34,$U$39) -> 0.13
B40: Type | C40: Material | D40: d m | E40: λ | F40: ρ | G40: c | H40: R m²K/W | I40: δ m | J40: x = d/δ | K40: z11 | L40: z12 | M40: z21 | N40: z22 | O40: P11 | P40: P12 | Q40: P21 | R40: P22 | S40: R part | T40: ρcd J/m²K
A41: Rsi | B41: res | H41: =$Y$39 -> 0.13 | I41: =IF(B41="mass",SQRT(E41*($B$2*3600)/(PI()*F41*G41)),0) -> 0 | J41: =IF(B41="mass",D41/I41,0) -> 0 | K41: =IF(B41="mass",COMPLEX(COSH(J41)*COS(J41),SINH(J41)*SIN(J41)),COMPLEX(1,0)) -> 1 | L41: =IF(B41="mass",COMPLEX(-I41/(2*E41)*(SINH(J41)*COS(J41)+COSH(J41)*SIN(J41)),-I41/(2*E41)*(COSH(J41)*SIN(J41)-SINH(J41)*COS(J41))),COMPLEX(-H41,0)) -> -0.13 | M41: =IF(B41="mass",COMPLEX(-E41/I41*(SINH(J41)*COS(J41)-COSH(J41)*SIN(J41)),-E41/I41*(SINH(J41)*COS(J41)+COSH(J41)*SIN(J41))),COMPLEX(0,0)) -> 0 | N41: =K41 -> 1 | O41: =K41 -> 1 | P41: =L41 -> -0.13 | Q41: =M41 -> 0 | R41: =N41 -> 1 | S41: =IF(B41="mass",D41/E41,H41) -> 0.13 | T41: =IF(B41="mass",F41*G41*D41,0) -> 0
A42: Layer 1 | B42: =IF(C42="","none",IF(C42="Cavity","res","mass")) -> mass | C42: =IF(INDEX(Library!$G$5:$G$34,$U$39)="","",INDEX(Library!$G$5:$G$34,$U$39)) -> plasterboard | D42: =IF(B42="mass",INDEX(Library!$H$5:$H$34,$U$39)/1000,0) -> 0.0125 | E42: =IF(B42="mass",INDEX(Materials!$B$5:$B$28,MATCH(C42,Materials!$A$5:$A$28,0)),0) -> 0.21 | F42: =IF(B42="mass",INDEX(Materials!$C$5:$C$28,MATCH(C42,Materials!$A$5:$A$28,0)),0) -> 700 | G42: =IF(B42="mass",INDEX(Materials!$D$5:$D$28,MATCH(C42,Materials!$A$5:$A$28,0)),0) -> 1000 | H42: =IF(B42="res",INDEX(Library!$H$5:$H$34,$U$39),0) -> 0 | I42: =IF(B42="mass",SQRT(E42*($B$2*3600)/(PI()*F42*G42)),0) -> 0.090832771 | J42: =IF(B42="mass",D42/I42,0) -> 0.13761553 | K42: =IF(B42="mass",COMPLEX(COSH(J42)*COS(J42),SINH(J42)*SIN(J42)),COMPLEX(1,0)) -> 0.999940225193105+0.0189379589504749i | L42: =IF(B42="mass",COMPLEX(-I42/(2*E42)*(SINH(J42)*COS(J42)+COSH(J42)*SIN(J42)),-I42/(2*E42)*(COSH(J42)*SIN(J42)-SINH(J42)*COS(J42))),COMPLEX(-H42,0)) -> -0.0595230979186955-0.000375754009423939i | M42: =IF(B42="mass",COMPLEX(-E42/I42*(SINH(J42)*COS(J42)-COSH(J42)*SIN(J42)),-E42/I42*(SINH(J42)*COS(J42)+COSH(J42)*SIN(J42))),COMPLEX(0,0)) -> 0.00401686359323574-0.636310349296785i | N42: =K42 -> 0.999940225193105+0.0189379589504749i | O42: =IMSUM(IMPRODUCT(K42,O41),IMPRODUCT(L42,Q41)) -> 0.999940225193105+0.0189379589504749i | P42: =IMSUM(IMPRODUCT(K42,P41),IMPRODUCT(L42,R41)) -> -0.1895153271938-0.00283768867298567i | Q42: =IMSUM(IMPRODUCT(M42,O41),IMPRODUCT(N42,Q41)) -> 0.00401686359323574-0.636310349296785i | R42: =IMSUM(IMPRODUCT(M42,P41),IMPRODUCT(N42,R41)) -> 0.999418032925984+0.101658304359057i | S42: =IF(B42="mass",D42/E42,H42) -> 0.05952381 | T42: =IF(B42="mass",F42*G42*D42,0) -> 8750
A43: Layer 2 | B43: =IF(C43="","none",IF(C43="Cavity","res","mass")) -> res | C43: =IF(INDEX(Library!$I$5:$I$34,$U$39)="","",INDEX(Library!$I$5:$I$34,$U$39)) -> Cavity | D43: =IF(B43="mass",INDEX(Library!$J$5:$J$34,$U$39)/1000,0) -> 0 | E43: =IF(B43="mass",INDEX(Materials!$B$5:$B$28,MATCH(C43,Materials!$A$5:$A$28,0)),0) -> 0 | F43: =IF(B43="mass",INDEX(Materials!$C$5:$C$28,MATCH(C43,Materials!$A$5:$A$28,0)),0) -> 0 | G43: =IF(B43="mass",INDEX(Materials!$D$5:$D$28,MATCH(C43,Materials!$A$5:$A$28,0)),0) -> 0 | H43: =IF(B43="res",INDEX(Library!$J$5:$J$34,$U$39),0) -> 0.1 | I43: =IF(B43="mass",SQRT(E43*($B$2*3600)/(PI()*F43*G43)),0) -> 0 | J43: =IF(B43="mass",D43/I43,0) -> 0 | K43: =IF(B43="mass",COMPLEX(COSH(J43)*COS(J43),SINH(J43)*SIN(J43)),COMPLEX(1,0)) -> 1 | L43: =IF(B43="mass",COMPLEX(-I43/(2*E43)*(SINH(J43)*COS(J43)+COSH(J43)*SIN(J43)),-I43/(2*E43)*(COSH(J43)*SIN(J43)-SINH(J43)*COS(J43))),COMPLEX(-H43,0)) -> -0.1 | M43: =IF(B43="mass",COMPLEX(-E43/I43*(SINH(J43)*COS(J43)-COSH(J43)*SIN(J43)),-E43/I43*(SINH(J43)*COS(J43)+COSH(J43)*SIN(J43))),COMPLEX(0,0)) -> 0 | N43: =K43 -> 1 | O43: =IMSUM(IMPRODUCT(K43,O42),IMPRODUCT(L43,Q42)) -> 0.999538538833782+0.0825689938801534i | P43: =IMSUM(IMPRODUCT(K43,P42),IMPRODUCT(L43,R42)) -> -0.289457130486398-0.0130035191088914i | Q43: =IMSUM(IMPRODUCT(M43,O42),IMPRODUCT(N43,Q42)) -> 0.00401686359323574-0.636310349296785i | R43: =IMSUM(IMPRODUCT(M43,P42),IMPRODUCT(N43,R42)) -> 0.999418032925984+0.101658304359057i | S43: =IF(B43="mass",D43/E43,H43) -> 0.1 | T43: =IF(B43="mass",F43*G43*D43,0) -> 0
A44: Layer 3 | B44: =IF(C44="","none",IF(C44="Cavity","res","mass")) -> mass | C44: =IF(INDEX(Library!$K$5:$K$34,$U$39)="","",INDEX(Library!$K$5:$K$34,$U$39)) -> dense block | D44: =IF(B44="mass",INDEX(Library!$L$5:$L$34,$U$39)/1000,0) -> 0.1 | E44: =IF(B44="mass",INDEX(Materials!$B$5:$B$28,MATCH(C44,Materials!$A$5:$A$28,0)),0) -> 1.13 | F44: =IF(B44="mass",INDEX(Materials!$C$5:$C$28,MATCH(C44,Materials!$A$5:$A$28,0)),0) -> 2000 | G44: =IF(B44="mass",INDEX(Materials!$D$5:$D$28,MATCH(C44,Materials!$A$5:$A$28,0)),0) -> 1000 | H44: =IF(B44="res",INDEX(Library!$L$5:$L$34,$U$39),0) -> 0 | I44: =IF(B44="mass",SQRT(E44*($B$2*3600)/(PI()*F44*G44)),0) -> 0.12465398 | J44: =IF(B44="mass",D44/I44,0) -> 0.80222066 | K44: =IF(B44="mass",COMPLEX(COSH(J44)*COS(J44),SINH(J44)*SIN(J44)),COMPLEX(1,0)) -> 0.931040246556561+0.640597397168838i | L44: =IF(B44="mass",COMPLEX(-I44/(2*E44)*(SINH(J44)*COS(J44)+COSH(J44)*SIN(J44)),-I44/(2*E44)*(COSH(J44)*SIN(J44)-SINH(J44)*COS(J44))),COMPLEX(-H44,0)) -> -0.0872745132646335-0.0189465784438884i | M44: =IF(B44="mass",COMPLEX(-E44/I44*(SINH(J44)*COS(J44)-COSH(J44)*SIN(J44)),-E44/I44*(SINH(J44)*COS(J44)+COSH(J44)*SIN(J44))),COMPLEX(0,0)) -> 3.11390498909631-14.3437266565329i | N44: =K44 -> 0.931040246556561+0.640597397168838i | O44: =IMSUM(IMPRODUCT(K44,O43),IMPRODUCT(L44,Q43)) -> 0.865310651309553+0.772634412965928i | P44: =IMSUM(IMPRODUCT(K44,P43),IMPRODUCT(L44,R43)) -> -0.346463862973921-0.225340015210106i | Q44: =IMSUM(IMPRODUCT(M44,O43),IMPRODUCT(N44,Q43)) -> 4.70817373661176-14.6698529338472i | R44: =IMSUM(IMPRODUCT(M44,P43),IMPRODUCT(N44,R43)) -> -0.222484559806568+4.84627479878324i | S44: =IF(B44="mass",D44/E44,H44) -> 0.088495575 | T44: =IF(B44="mass",F44*G44*D44,0) -> 200000
A45: Layer 4 | B45: =IF(C45="","none",IF(C45="Cavity","res","mass")) -> mass | C45: =IF(INDEX(Library!$M$5:$M$34,$U$39)="","",INDEX(Library!$M$5:$M$34,$U$39)) -> mineral wool | D45: =IF(B45="mass",INDEX(Library!$N$5:$N$34,$U$39)/1000,0) -> 0.15 | E45: =IF(B45="mass",INDEX(Materials!$B$5:$B$28,MATCH(C45,Materials!$A$5:$A$28,0)),0) -> 0.035 | F45: =IF(B45="mass",INDEX(Materials!$C$5:$C$28,MATCH(C45,Materials!$A$5:$A$28,0)),0) -> 30 | G45: =IF(B45="mass",INDEX(Materials!$D$5:$D$28,MATCH(C45,Materials!$A$5:$A$28,0)),0) -> 1030 | H45: =IF(B45="res",INDEX(Library!$N$5:$N$34,$U$39),0) -> 0 | I45: =IF(B45="mass",SQRT(E45*($B$2*3600)/(PI()*F45*G45)),0) -> 0.17649675 | J45: =IF(B45="mass",D45/I45,0) -> 0.849874 | K45: =IF(B45="mass",COMPLEX(COSH(J45)*COS(J45),SINH(J45)*SIN(J45)),COMPLEX(1,0)) -> 0.913158518565511+0.718100720020173i | L45: =IF(B45="mass",COMPLEX(-I45/(2*E45)*(SINH(J45)*COS(J45)+COSH(J45)*SIN(J45)),-I45/(2*E45)*(COSH(J45)*SIN(J45)-SINH(J45)*COS(J45))),COMPLEX(-H45,0)) -> -4.21123759620779-1.02927418634689i | M45: =IF(B45="mass",COMPLEX(-E45/I45*(SINH(J45)*COS(J45)-COSH(J45)*SIN(J45)),-E45/I45*(SINH(J45)*COS(J45)+COSH(J45)*SIN(J45))),COMPLEX(0,0)) -> 0.0809512819555347-0.331209202129424i | N45: =K45 -> 0.913158518565511+0.718100720020173i | O45: =IMSUM(IMPRODUCT(K45,O44),IMPRODUCT(L45,Q44)) -> -34.6912027272261+58.2591524116088i | P45: =IMSUM(IMPRODUCT(K45,P44),IMPRODUCT(L45,R44)) -> 5.7705212924862-20.634384123846i | Q45: =IMSUM(IMPRODUCT(M45,O44),IMPRODUCT(N45,Q44)) -> 15.1596925428287-10.2390113266067i | R45: =IMSUM(IMPRODUCT(M45,P44),IMPRODUCT(N45,R44)) -> -3.78595847396311+4.36216124974294i | S45: =IF(B45="mass",D45/E45,H45) -> 4.2857143 | T45: =IF(B45="mass",F45*G45*D45,0) -> 4635
...

Sheet Calculator
A1: Build-up calculator
A2: Choose a build-up (or 'Custom' to use your own row on the Library sheet) and a period. Everything below recalculates.
A4: Build-up key | B4: W2 | C4: =INDEX(Library!$B$5:$B$34,MATCH(B4,Library!$A$5:$A$34,0)) -> Cavity: board on dabs, 100 dense block, 150 MW, brick | F4: Results
A5: Period, hours | B5: 24 | F5: U W/m²K | G5: |Y| W/m²K | H5: Y lead h | I5: f | J5: lag h | K5: κ₁ kJ/m²K | L5: κ total kJ/m²K | M5: Five-node |Y| (class)
A6: Five-node class | B6: rule | C6: =IF(B6="rule",INDEX(Library!$F$5:$F$34,MATCH(B4,Library!$A$5:$A$34,0)),B6) -> IE | D6: ← class used below | F6: =B22 -> 0.20677386 | G6: =D22 -> 3.1646834 | H6: =F22 -> 1.009561 | I6: =H22 -> 0.16133724 | J6: =J22 -> 10.476924 | K6: =L22 -> 43.972162 | L6: =N22 -> 352.105 | M6: =B39 -> 6.546181
A9: ISO 13786 matrix chain (room side first) | T9: row → | U9: =MATCH($B$4,Library!$A$5:$A$34,0) -> 2 | V9: far side | W9: =INDEX(Library!$D$5:$D$34,$U$9) -> ext | X9: Rsi | Y9: =INDEX(Library!$E$5:$E$34,$U$9) -> 0.13
B10: Type | C10: Material | D10: d m | E10: λ | F10: ρ | G10: c | H10: R m²K/W | I10: δ m | J10: x = d/δ | K10: z11 | L10: z12 | M10: z21 | N10: z22 | O10: P11 | P10: P12 | Q10: P21 | R10: P22 | S10: R part | T10: ρcd J/m²K
A11: Rsi | B11: res | H11: =$Y$9 -> 0.13 | I11: =IF(B11="mass",SQRT(E11*($B$5*3600)/(PI()*F11*G11)),0) -> 0 | J11: =IF(B11="mass",D11/I11,0) -> 0 | K11: =IF(B11="mass",COMPLEX(COSH(J11)*COS(J11),SINH(J11)*SIN(J11)),COMPLEX(1,0)) -> 1 | L11: =IF(B11="mass",COMPLEX(-I11/(2*E11)*(SINH(J11)*COS(J11)+COSH(J11)*SIN(J11)),-I11/(2*E11)*(COSH(J11)*SIN(J11)-SINH(J11)*COS(J11))),COMPLEX(-H11,0)) -> -0.13 | M11: =IF(B11="mass",COMPLEX(-E11/I11*(SINH(J11)*COS(J11)-COSH(J11)*SIN(J11)),-E11/I11*(SINH(J11)*COS(J11)+COSH(J11)*SIN(J11))),COMPLEX(0,0)) -> 0 | N11: =K11 -> 1 | O11: =K11 -> 1 | P11: =L11 -> -0.13 | Q11: =M11 -> 0 | R11: =N11 -> 1 | S11: =IF(B11="mass",D11/E11,H11) -> 0.13 | T11: =IF(B11="mass",F11*G11*D11,0) -> 0
A12: Layer 1 | B12: =IF(C12="","none",IF(C12="Cavity","res","mass")) -> mass | C12: =IF(INDEX(Library!$G$5:$G$34,$U$9)="","",INDEX(Library!$G$5:$G$34,$U$9)) -> plasterboard | D12: =IF(B12="mass",INDEX(Library!$H$5:$H$34,$U$9)/1000,0) -> 0.0125 | E12: =IF(B12="mass",INDEX(Materials!$B$5:$B$28,MATCH(C12,Materials!$A$5:$A$28,0)),0) -> 0.21 | F12: =IF(B12="mass",INDEX(Materials!$C$5:$C$28,MATCH(C12,Materials!$A$5:$A$28,0)),0) -> 700 | G12: =IF(B12="mass",INDEX(Materials!$D$5:$D$28,MATCH(C12,Materials!$A$5:$A$28,0)),0) -> 1000 | H12: =IF(B12="res",INDEX(Library!$H$5:$H$34,$U$9),0) -> 0 | I12: =IF(B12="mass",SQRT(E12*($B$5*3600)/(PI()*F12*G12)),0) -> 0.090832771 | J12: =IF(B12="mass",D12/I12,0) -> 0.13761553 | K12: =IF(B12="mass",COMPLEX(COSH(J12)*COS(J12),SINH(J12)*SIN(J12)),COMPLEX(1,0)) -> 0.999940225193105+0.0189379589504749i | L12: =IF(B12="mass",COMPLEX(-I12/(2*E12)*(SINH(J12)*COS(J12)+COSH(J12)*SIN(J12)),-I12/(2*E12)*(COSH(J12)*SIN(J12)-SINH(J12)*COS(J12))),COMPLEX(-H12,0)) -> -0.0595230979186955-0.000375754009423939i | M12: =IF(B12="mass",COMPLEX(-E12/I12*(SINH(J12)*COS(J12)-COSH(J12)*SIN(J12)),-E12/I12*(SINH(J12)*COS(J12)+COSH(J12)*SIN(J12))),COMPLEX(0,0)) -> 0.00401686359323574-0.636310349296785i | N12: =K12 -> 0.999940225193105+0.0189379589504749i | O12: =IMSUM(IMPRODUCT(K12,O11),IMPRODUCT(L12,Q11)) -> 0.999940225193105+0.0189379589504749i | P12: =IMSUM(IMPRODUCT(K12,P11),IMPRODUCT(L12,R11)) -> -0.1895153271938-0.00283768867298567i | Q12: =IMSUM(IMPRODUCT(M12,O11),IMPRODUCT(N12,Q11)) -> 0.00401686359323574-0.636310349296785i | R12: =IMSUM(IMPRODUCT(M12,P11),IMPRODUCT(N12,R11)) -> 0.999418032925984+0.101658304359057i | S12: =IF(B12="mass",D12/E12,H12) -> 0.05952381 | T12: =IF(B12="mass",F12*G12*D12,0) -> 8750
A13: Layer 2 | B13: =IF(C13="","none",IF(C13="Cavity","res","mass")) -> res | C13: =IF(INDEX(Library!$I$5:$I$34,$U$9)="","",INDEX(Library!$I$5:$I$34,$U$9)) -> Cavity | D13: =IF(B13="mass",INDEX(Library!$J$5:$J$34,$U$9)/1000,0) -> 0 | E13: =IF(B13="mass",INDEX(Materials!$B$5:$B$28,MATCH(C13,Materials!$A$5:$A$28,0)),0) -> 0 | F13: =IF(B13="mass",INDEX(Materials!$C$5:$C$28,MATCH(C13,Materials!$A$5:$A$28,0)),0) -> 0 | G13: =IF(B13="mass",INDEX(Materials!$D$5:$D$28,MATCH(C13,Materials!$A$5:$A$28,0)),0) -> 0 | H13: =IF(B13="res",INDEX(Library!$J$5:$J$34,$U$9),0) -> 0.1 | I13: =IF(B13="mass",SQRT(E13*($B$5*3600)/(PI()*F13*G13)),0) -> 0 | J13: =IF(B13="mass",D13/I13,0) -> 0 | K13: =IF(B13="mass",COMPLEX(COSH(J13)*COS(J13),SINH(J13)*SIN(J13)),COMPLEX(1,0)) -> 1 | L13: =IF(B13="mass",COMPLEX(-I13/(2*E13)*(SINH(J13)*COS(J13)+COSH(J13)*SIN(J13)),-I13/(2*E13)*(COSH(J13)*SIN(J13)-SINH(J13)*COS(J13))),COMPLEX(-H13,0)) -> -0.1 | M13: =IF(B13="mass",COMPLEX(-E13/I13*(SINH(J13)*COS(J13)-COSH(J13)*SIN(J13)),-E13/I13*(SINH(J13)*COS(J13)+COSH(J13)*SIN(J13))),COMPLEX(0,0)) -> 0 | N13: =K13 -> 1 | O13: =IMSUM(IMPRODUCT(K13,O12),IMPRODUCT(L13,Q12)) -> 0.999538538833782+0.0825689938801534i | P13: =IMSUM(IMPRODUCT(K13,P12),IMPRODUCT(L13,R12)) -> -0.289457130486398-0.0130035191088914i | Q13: =IMSUM(IMPRODUCT(M13,O12),IMPRODUCT(N13,Q12)) -> 0.00401686359323574-0.636310349296785i | R13: =IMSUM(IMPRODUCT(M13,P12),IMPRODUCT(N13,R12)) -> 0.999418032925984+0.101658304359057i | S13: =IF(B13="mass",D13/E13,H13) -> 0.1 | T13: =IF(B13="mass",F13*G13*D13,0) -> 0
A14: Layer 3 | B14: =IF(C14="","none",IF(C14="Cavity","res","mass")) -> mass | C14: =IF(INDEX(Library!$K$5:$K$34,$U$9)="","",INDEX(Library!$K$5:$K$34,$U$9)) -> dense block | D14: =IF(B14="mass",INDEX(Library!$L$5:$L$34,$U$9)/1000,0) -> 0.1 | E14: =IF(B14="mass",INDEX(Materials!$B$5:$B$28,MATCH(C14,Materials!$A$5:$A$28,0)),0) -> 1.13 | F14: =IF(B14="mass",INDEX(Materials!$C$5:$C$28,MATCH(C14,Materials!$A$5:$A$28,0)),0) -> 2000 | G14: =IF(B14="mass",INDEX(Materials!$D$5:$D$28,MATCH(C14,Materials!$A$5:$A$28,0)),0) -> 1000 | H14: =IF(B14="res",INDEX(Library!$L$5:$L$34,$U$9),0) -> 0 | I14: =IF(B14="mass",SQRT(E14*($B$5*3600)/(PI()*F14*G14)),0) -> 0.12465398 | J14: =IF(B14="mass",D14/I14,0) -> 0.80222066 | K14: =IF(B14="mass",COMPLEX(COSH(J14)*COS(J14),SINH(J14)*SIN(J14)),COMPLEX(1,0)) -> 0.931040246556561+0.640597397168838i | L14: =IF(B14="mass",COMPLEX(-I14/(2*E14)*(SINH(J14)*COS(J14)+COSH(J14)*SIN(J14)),-I14/(2*E14)*(COSH(J14)*SIN(J14)-SINH(J14)*COS(J14))),COMPLEX(-H14,0)) -> -0.0872745132646335-0.0189465784438884i | M14: =IF(B14="mass",COMPLEX(-E14/I14*(SINH(J14)*COS(J14)-COSH(J14)*SIN(J14)),-E14/I14*(SINH(J14)*COS(J14)+COSH(J14)*SIN(J14))),COMPLEX(0,0)) -> 3.11390498909631-14.3437266565329i | N14: =K14 -> 0.931040246556561+0.640597397168838i | O14: =IMSUM(IMPRODUCT(K14,O13),IMPRODUCT(L14,Q13)) -> 0.865310651309553+0.772634412965928i | P14: =IMSUM(IMPRODUCT(K14,P13),IMPRODUCT(L14,R13)) -> -0.346463862973921-0.225340015210106i | Q14: =IMSUM(IMPRODUCT(M14,O13),IMPRODUCT(N14,Q13)) -> 4.70817373661176-14.6698529338472i | R14: =IMSUM(IMPRODUCT(M14,P13),IMPRODUCT(N14,R13)) -> -0.222484559806568+4.84627479878324i | S14: =IF(B14="mass",D14/E14,H14) -> 0.088495575 | T14: =IF(B14="mass",F14*G14*D14,0) -> 200000
A15: Layer 4 | B15: =IF(C15="","none",IF(C15="Cavity","res","mass")) -> mass | C15: =IF(INDEX(Library!$M$5:$M$34,$U$9)="","",INDEX(Library!$M$5:$M$34,$U$9)) -> mineral wool | D15: =IF(B15="mass",INDEX(Library!$N$5:$N$34,$U$9)/1000,0) -> 0.15 | E15: =IF(B15="mass",INDEX(Materials!$B$5:$B$28,MATCH(C15,Materials!$A$5:$A$28,0)),0) -> 0.035 | F15: =IF(B15="mass",INDEX(Materials!$C$5:$C$28,MATCH(C15,Materials!$A$5:$A$28,0)),0) -> 30 | G15: =IF(B15="mass",INDEX(Materials!$D$5:$D$28,MATCH(C15,Materials!$A$5:$A$28,0)),0) -> 1030 | H15: =IF(B15="res",INDEX(Library!$N$5:$N$34,$U$9),0) -> 0 | I15: =IF(B15="mass",SQRT(E15*($B$5*3600)/(PI()*F15*G15)),0) -> 0.17649675 | J15: =IF(B15="mass",D15/I15,0) -> 0.849874 | K15: =IF(B15="mass",COMPLEX(COSH(J15)*COS(J15),SINH(J15)*SIN(J15)),COMPLEX(1,0)) -> 0.913158518565511+0.718100720020173i | L15: =IF(B15="mass",COMPLEX(-I15/(2*E15)*(SINH(J15)*COS(J15)+COSH(J15)*SIN(J15)),-I15/(2*E15)*(COSH(J15)*SIN(J15)-SINH(J15)*COS(J15))),COMPLEX(-H15,0)) -> -4.21123759620779-1.02927418634689i | M15: =IF(B15="mass",COMPLEX(-E15/I15*(SINH(J15)*COS(J15)-COSH(J15)*SIN(J15)),-E15/I15*(SINH(J15)*COS(J15)+COSH(J15)*SIN(J15))),COMPLEX(0,0)) -> 0.0809512819555347-0.331209202129424i | N15: =K15 -> 0.913158518565511+0.718100720020173i | O15: =IMSUM(IMPRODUCT(K15,O14),IMPRODUCT(L15,Q14)) -> -34.6912027272261+58.2591524116088i | P15: =IMSUM(IMPRODUCT(K15,P14),IMPRODUCT(L15,R14)) -> 5.7705212924862-20.634384123846i | Q15: =IMSUM(IMPRODUCT(M15,O14),IMPRODUCT(N15,Q14)) -> 15.1596925428287-10.2390113266067i | R15: =IMSUM(IMPRODUCT(M15,P14),IMPRODUCT(N15,R14)) -> -3.78595847396311+4.36216124974294i | S15: =IF(B15="mass",D15/E15,H15) -> 4.2857143 | T15: =IF(B15="mass",F15*G15*D15,0) -> 4635
A16: Layer 5 | B16: =IF(C16="","none",IF(C16="Cavity","res","mass")) -> mass | C16: =IF(INDEX(Library!$O$5:$O$34,$U$9)="","",INDEX(Library!$O$5:$O$34,$U$9)) -> brick | D16: =IF(B16="mass",INDEX(Library!$P$5:$P$34,$U$9)/1000,0) -> 0.102 | E16: =IF(B16="mass",INDEX(Materials!$B$5:$B$28,MATCH(C16,Materials!$A$5:$A$28,0)),0) -> 0.77 | F16: =IF(B16="mass",INDEX(Materials!$C$5:$C$28,MATCH(C16,Materials!$A$5:$A$28,0)),0) -> 1700 | G16: =IF(B16="mass",INDEX(Materials!$D$5:$D$28,MATCH(C16,Materials!$A$5:$A$28,0)),0) -> 800 | H16: =IF(B16="res",INDEX(Library!$P$5:$P$34,$U$9),0) -> 0 | I16: =IF(B16="mass",SQRT(E16*($B$5*3600)/(PI()*F16*G16)),0) -> 0.1247837 | J16: =IF(B16="mass",D16/I16,0) -> 0.81741448 | K16: =IF(B16="mass",COMPLEX(COSH(J16)*COS(J16),SINH(J16)*SIN(J16)),COMPLEX(1,0)) -> 0.925671349743335+0.664853161913343i | L16: =IF(B16="mass",COMPLEX(-I16/(2*E16)*(SINH(J16)*COS(J16)+COSH(J16)*SIN(J16)),-I16/(2*E16)*(COSH(J16)*SIN(J16)-SINH(J16)*COS(J16))),COMPLEX(-H16,0)) -> -0.130497374771535-0.0294407447988599i | M16: =IF(B16="mass",COMPLEX(-E16/I16*(SINH(J16)*COS(J16)-COSH(J16)*SIN(J16)),-E16/I16*(SINH(J16)*COS(J16)+COSH(J16)*SIN(J16))),COMPLEX(0,0)) -> 2.24204617217389-9.93796663719564i | N16: =K16 -> 0.925671349743335+0.664853161913343i | O16: =IMSUM(IMPRODUCT(K16,O15),IMPRODUCT(L16,Q15)) -> -73.1261783426225+31.7541238829791i | P16: =IMSUM(IMPRODUCT(K16,P15),IMPRODUCT(L16,R15)) -> 19.6829246803833-15.7218980300158i | Q16: =IMSUM(IMPRODUCT(M16,O15),IMPRODUCT(N16,Q15)) -> 522.038566808353+475.980735051902i | R16: =IMSUM(IMPRODUCT(M16,P15),IMPRODUCT(N16,R15)) -> -198.530795816927-102.089668794429i | S16: =IF(B16="mass",D16/E16,H16) -> 0.13246753 | T16: =IF(B16="mass",F16*G16*D16,0) -> 138720
A17: Layer 6 | B17: =IF(C17="","none",IF(C17="Cavity","res","mass")) -> none | C17: =IF(INDEX(Library!$Q$5:$Q$34,$U$9)="","",INDEX(Library!$Q$5:$Q$34,$U$9)) | D17: =IF(B17="mass",INDEX(Library!$R$5:$R$34,$U$9)/1000,0) -> 0 | E17: =IF(B17="mass",INDEX(Materials!$B$5:$B$28,MATCH(C17,Materials!$A$5:$A$28,0)),0) -> 0 | F17: =IF(B17="mass",INDEX(Materials!$C$5:$C$28,MATCH(C17,Materials!$A$5:$A$28,0)),0) -> 0 | G17: =IF(B17="mass",INDEX(Materials!$D$5:$D$28,MATCH(C17,Materials!$A$5:$A$28,0)),0) -> 0 | H17: =IF(B17="res",INDEX(Library!$R$5:$R$34,$U$9),0) -> 0 | I17: =IF(B17="mass",SQRT(E17*($B$5*3600)/(PI()*F17*G17)),0) -> 0 | J17: =IF(B17="mass",D17/I17,0) -> 0 | K17: =IF(B17="mass",COMPLEX(COSH(J17)*COS(J17),SINH(J17)*SIN(J17)),COMPLEX(1,0)) -> 1 | L17: =IF(B17="mass",COMPLEX(-I17/(2*E17)*(SINH(J17)*COS(J17)+COSH(J17)*SIN(J17)),-I17/(2*E17)*(COSH(J17)*SIN(J17)-SINH(J17)*COS(J17))),COMPLEX(-H17,0)) -> -0 | M17: =IF(B17="mass",COMPLEX(-E17/I17*(SINH(J17)*COS(J17)-COSH(J17)*SIN(J17)),-E17/I17*(SINH(J17)*COS(J17)+COSH(J17)*SIN(J17))),COMPLEX(0,0)) -> 0 | N17: =K17 -> 1 | O17: =IMSUM(IMPRODUCT(K17,O16),IMPRODUCT(L17,Q16)) -> -73.1261783426225+31.7541238829791i | P17: =IMSUM(IMPRODUCT(K17,P16),IMPRODUCT(L17,R16)) -> 19.6829246803833-15.7218980300158i | Q17: =IMSUM(IMPRODUCT(M17,O16),IMPRODUCT(N17,Q16)) -> 522.038566808353+475.980735051902i | R17: =IMSUM(IMPRODUCT(M17,P16),IMPRODUCT(N17,R16)) -> -198.530795816927-102.089668794429i | S17: =IF(B17="mass",D17/E17,H17) -> 0 | T17: =IF(B17="mass",F17*G17*D17,0) -> 0
A18: Layer 7 | B18: =IF(C18="","none",IF(C18="Cavity","res","mass")) -> none | C18: =IF(INDEX(Library!$S$5:$S$34,$U$9)="","",INDEX(Library!$S$5:$S$34,$U$9)) | D18: =IF(B18="mass",INDEX(Library!$T$5:$T$34,$U$9)/1000,0) -> 0 | E18: =IF(B18="mass",INDEX(Materials!$B$5:$B$28,MATCH(C18,Materials!$A$5:$A$28,0)),0) -> 0 | F18: =IF(B18="mass",INDEX(Materials!$C$5:$C$28,MATCH(C18,Materials!$A$5:$A$28,0)),0) -> 0 | G18: =IF(B18="mass",INDEX(Materials!$D$5:$D$28,MATCH(C18,Materials!$A$5:$A$28,0)),0) -> 0 | H18: =IF(B18="res",INDEX(Library!$T$5:$T$34,$U$9),0) -> 0 | I18: =IF(B18="mass",SQRT(E18*($B$5*3600)/(PI()*F18*G18)),0) -> 0 | J18: =IF(B18="mass",D18/I18,0) -> 0 | K18: =IF(B18="mass",COMPLEX(COSH(J18)*COS(J18),SINH(J18)*SIN(J18)),COMPLEX(1,0)) -> 1 | L18: =IF(B18="mass",COMPLEX(-I18/(2*E18)*(SINH(J18)*COS(J18)+COSH(J18)*SIN(J18)),-I18/(2*E18)*(COSH(J18)*SIN(J18)-SINH(J18)*COS(J18))),COMPLEX(-H18,0)) -> -0 | M18: =IF(B18="mass",COMPLEX(-E18/I18*(SINH(J18)*COS(J18)-COSH(J18)*SIN(J18)),-E18/I18*(SINH(J18)*COS(J18)+COSH(J18)*SIN(J18))),COMPLEX(0,0)) -> 0 | N18: =K18 -> 1 | O18: =IMSUM(IMPRODUCT(K18,O17),IMPRODUCT(L18,Q17)) -> -73.1261783426225+31.7541238829791i | P18: =IMSUM(IMPRODUCT(K18,P17),IMPRODUCT(L18,R17)) -> 19.6829246803833-15.7218980300158i | Q18: =IMSUM(IMPRODUCT(M18,O17),IMPRODUCT(N18,Q17)) -> 522.038566808353+475.980735051902i | R18: =IMSUM(IMPRODUCT(M18,P17),IMPRODUCT(N18,R17)) -> -198.530795816927-102.089668794429i | S18: =IF(B18="mass",D18/E18,H18) -> 0 | T18: =IF(B18="mass",F18*G18*D18,0) -> 0
A19: Layer 8 | B19: =IF(C19="","none",IF(C19="Cavity","res","mass")) -> none | C19: =IF(INDEX(Library!$U$5:$U$34,$U$9)="","",INDEX(Library!$U$5:$U$34,$U$9)) | D19: =IF(B19="mass",INDEX(Library!$V$5:$V$34,$U$9)/1000,0) -> 0 | E19: =IF(B19="mass",INDEX(Materials!$B$5:$B$28,MATCH(C19,Materials!$A$5:$A$28,0)),0) -> 0 | F19: =IF(B19="mass",INDEX(Materials!$C$5:$C$28,MATCH(C19,Materials!$A$5:$A$28,0)),0) -> 0 | G19: =IF(B19="mass",INDEX(Materials!$D$5:$D$28,MATCH(C19,Materials!$A$5:$A$28,0)),0) -> 0 | H19: =IF(B19="res",INDEX(Library!$V$5:$V$34,$U$9),0) -> 0 | I19: =IF(B19="mass",SQRT(E19*($B$5*3600)/(PI()*F19*G19)),0) -> 0 | J19: =IF(B19="mass",D19/I19,0) -> 0 | K19: =IF(B19="mass",COMPLEX(COSH(J19)*COS(J19),SINH(J19)*SIN(J19)),COMPLEX(1,0)) -> 1 | L19: =IF(B19="mass",COMPLEX(-I19/(2*E19)*(SINH(J19)*COS(J19)+COSH(J19)*SIN(J19)),-I19/(2*E19)*(COSH(J19)*SIN(J19)-SINH(J19)*COS(J19))),COMPLEX(-H19,0)) -> -0 | M19: =IF(B19="mass",COMPLEX(-E19/I19*(SINH(J19)*COS(J19)-COSH(J19)*SIN(J19)),-E19/I19*(SINH(J19)*COS(J19)+COSH(J19)*SIN(J19))),COMPLEX(0,0)) -> 0 | N19: =K19 -> 1 | O19: =IMSUM(IMPRODUCT(K19,O18),IMPRODUCT(L19,Q18)) -> -73.1261783426225+31.7541238829791i | P19: =IMSUM(IMPRODUCT(K19,P18),IMPRODUCT(L19,R18)) -> 19.6829246803833-15.7218980300158i | Q19: =IMSUM(IMPRODUCT(M19,O18),IMPRODUCT(N19,Q18)) -> 522.038566808353+475.980735051902i | R19: =IMSUM(IMPRODUCT(M19,P18),IMPRODUCT(N19,R18)) -> -198.530795816927-102.089668794429i | S19: =IF(B19="mass",D19/E19,H19) -> 0 | T19: =IF(B19="mass",F19*G19*D19,0) -> 0
A20: Far-side layer | B20: =IF($W$9="ground","mass",IF($W$9="adiabatic","res","none")) -> none | C20: =IF($W$9="ground","clay soil","") | D20: =IF(B20="mass",1,0) -> 0 | E20: =IF(B20="mass",INDEX(Materials!$B$5:$B$28,MATCH(C20,Materials!$A$5:$A$28,0)),0) -> 0 | F20: =IF(B20="mass",INDEX(Materials!$C$5:$C$28,MATCH(C20,Materials!$A$5:$A$28,0)),0) -> 0 | G20: =IF(B20="mass",INDEX(Materials!$D$5:$D$28,MATCH(C20,Materials!$A$5:$A$28,0)),0) -> 0 | H20: =IF(B20="res",1000000,0) -> 0 | I20: =IF(B20="mass",SQRT(E20*($B$5*3600)/(PI()*F20*G20)),0) -> 0 | J20: =IF(B20="mass",D20/I20,0) -> 0 | K20: =IF(B20="mass",COMPLEX(COSH(J20)*COS(J20),SINH(J20)*SIN(J20)),COMPLEX(1,0)) -> 1 | L20: =IF(B20="mass",COMPLEX(-I20/(2*E20)*(SINH(J20)*COS(J20)+COSH(J20)*SIN(J20)),-I20/(2*E20)*(COSH(J20)*SIN(J20)-SINH(J20)*COS(J20))),COMPLEX(-H20,0)) -> -0 | M20: =IF(B20="mass",COMPLEX(-E20/I20*(SINH(J20)*COS(J20)-COSH(J20)*SIN(J20)),-E20/I20*(SINH(J20)*COS(J20)+COSH(J20)*SIN(J20))),COMPLEX(0,0)) -> 0 | N20: =K20 -> 1 | O20: =IMSUM(IMPRODUCT(K20,O19),IMPRODUCT(L20,Q19)) -> -73.1261783426225+31.7541238829791i | P20: =IMSUM(IMPRODUCT(K20,P19),IMPRODUCT(L20,R19)) -> 19.6829246803833-15.7218980300158i | Q20: =IMSUM(IMPRODUCT(M20,O19),IMPRODUCT(N20,Q19)) -> 522.038566808353+475.980735051902i | R20: =IMSUM(IMPRODUCT(M20,P19),IMPRODUCT(N20,R19)) -> -198.530795816927-102.089668794429i | S20: =IF(B20="mass",D20/E20,H20) -> 0 | T20: =IF(B20="mass",F20*G20*D20,0) -> 0
A21: Rse | B21: res | H21: =IF($W$9="ext",0.04,IF($W$9="room",$Y$9,0)) -> 0.04 | I21: =IF(B21="mass",SQRT(E21*($B$5*3600)/(PI()*F21*G21)),0) -> 0 | J21: =IF(B21="mass",D21/I21,0) -> 0 | K21: =IF(B21="mass",COMPLEX(COSH(J21)*COS(J21),SINH(J21)*SIN(J21)),COMPLEX(1,0)) -> 1 | L21: =IF(B21="mass",COMPLEX(-I21/(2*E21)*(SINH(J21)*COS(J21)+COSH(J21)*SIN(J21)),-I21/(2*E21)*(COSH(J21)*SIN(J21)-SINH(J21)*COS(J21))),COMPLEX(-H21,0)) -> -0.04 | M21: =IF(B21="mass",COMPLEX(-E21/I21*(SINH(J21)*COS(J21)-COSH(J21)*SIN(J21)),-E21/I21*(SINH(J21)*COS(J21)+COSH(J21)*SIN(J21))),COMPLEX(0,0)) -> 0 | N21: =K21 -> 1 | O21: =IMSUM(IMPRODUCT(K21,O20),IMPRODUCT(L21,Q20)) -> -94.0077210149566+12.714894480903i | P21: =IMSUM(IMPRODUCT(K21,P20),IMPRODUCT(L21,R20)) -> 27.6241565130604-11.6383112782386i | Q21: =IMSUM(IMPRODUCT(M21,O20),IMPRODUCT(N21,Q20)) -> 522.038566808353+475.980735051902i | R21: =IMSUM(IMPRODUCT(M21,P20),IMPRODUCT(N21,R20)) -> -198.530795816927-102.089668794429i | S21: =IF(B21="mass",D21/E21,H21) -> 0.04 | T21: =IF(B21="mass",F21*G21*D21,0) -> 0
A22: U W/m²K | B22: =IF(OR($W$9="ext",$W$9="ground"),1/SUM(S11:S21),"–") -> 0.20677386 | C22: |Y| W/m²K | D22: =IMABS(IMDIV(IMPRODUCT(O21,COMPLEX(-1,0)),P21)) -> 3.1646834 | E22: Y lead h | F22: =IMARGUMENT(IMDIV(IMPRODUCT(O21,COMPLEX(-1,0)),P21))*$B$5/(2*PI()) -> 1.009561 | G22: f | H22: =IF($W$9="ext",IMABS(IMDIV(COMPLEX(-1,0),P21))*SUM(S11:S21),"–") -> 0.16133724 | I22: lag h | J22: =IF($W$9="ext",MOD(-IMARGUMENT(IMDIV(COMPLEX(-1,0),P21))*$B$5/(2*PI()),24),"–") -> 10.476924 | K22: κ₁ kJ/m²K | L22: =($B$5*3600)/(2*PI())*IMABS(IMDIV(IMSUB(O21,COMPLEX(1,0)),P21))/1000 -> 43.972162 | M22: κ total kJ/m²K | N22: =SUM(T12:T19)/1000 -> 352.105 | O22: Rc m²K/W | P22: =SUM(S12:S19) -> 4.6662012
A25: Five-node chain for the chosen class
B26: Kind | C26: R or C | K26: z11 | L26: z12 | M26: z21 | N26: z22 | O26: P11 | P26: P12 | Q26: P21 | R26: P22
A27: Rsi | B27: res | C27: =$Y$9 -> 0.13 | K27: =COMPLEX(1,0) -> 1 | L27: =COMPLEX(-C27,0) -> -0.13 | M27: =COMPLEX(0,0) -> 0 | N27: =COMPLEX(1,0) -> 1 | O27: =K27 -> 1 | P27: =L27 -> -0.13 | Q27: =M27 -> 0 | R27: =N27 -> 1
A28: node 5 (room side) | B28: cap | C28: =INDEX(Classes!$B$5:$F$9,MATCH($C$6,Classes!$A$5:$A$9,0),5)*(N22*1000) -> 176052.5 | K28: =COMPLEX(1,0) -> 1 | L28: =COMPLEX(0,0) -> 0 | M28: =COMPLEX(0,-(2*PI()/($B$5*3600))*C28) -> -12.8028990890305i | N28: =COMPLEX(1,0) -> 1 | O28: =IMSUM(IMPRODUCT(K28,O27),IMPRODUCT(L28,Q27)) -> 1 | P28: =IMSUM(IMPRODUCT(K28,P27),IMPRODUCT(L28,R27)) -> -0.13 | Q28: =IMSUM(IMPRODUCT(M28,O27),IMPRODUCT(N28,Q27)) -> -12.8028990890305i | R28: =IMSUM(IMPRODUCT(M28,P27),IMPRODUCT(N28,R27)) -> 1+1.66437688157397i
A29: 6/Rc | B29: res | C29: =P22/6 -> 0.7777002 | K29: =COMPLEX(1,0) -> 1 | L29: =COMPLEX(-C29,0) -> -0.777700200487811 | M29: =COMPLEX(0,0) -> 0 | N29: =COMPLEX(1,0) -> 1 | O29: =IMSUM(IMPRODUCT(K29,O28),IMPRODUCT(L29,Q28)) -> 1+9.95681718836423i | P29: =IMSUM(IMPRODUCT(K29,P28),IMPRODUCT(L29,R28)) -> -0.907700200487811-1.29438623448735i | Q29: =IMSUM(IMPRODUCT(M29,O28),IMPRODUCT(N29,Q28)) -> -12.8028990890305i | R29: =IMSUM(IMPRODUCT(M29,P28),IMPRODUCT(N29,R28)) -> 1+1.66437688157397i
A30: node 4 | B30: cap | C30: =INDEX(Classes!$B$5:$F$9,MATCH($C$6,Classes!$A$5:$A$9,0),4)*(N22*1000) -> 0 | K30: =COMPLEX(1,0) -> 1 | L30: =COMPLEX(0,0) -> 0 | M30: =COMPLEX(0,-(2*PI()/($B$5*3600))*C30) -> 0 | N30: =COMPLEX(1,0) -> 1 | O30: =IMSUM(IMPRODUCT(K30,O29),IMPRODUCT(L30,Q29)) -> 1+9.95681718836423i | P30: =IMSUM(IMPRODUCT(K30,P29),IMPRODUCT(L30,R29)) -> -0.907700200487811-1.29438623448735i | Q30: =IMSUM(IMPRODUCT(M30,O29),IMPRODUCT(N30,Q29)) -> -12.8028990890305i | R30: =IMSUM(IMPRODUCT(M30,P29),IMPRODUCT(N30,R29)) -> 1+1.66437688157397i
A31: 3/Rc | B31: res | C31: =P22/3 -> 1.5554004 | K31: =COMPLEX(1,0) -> 1 | L31: =COMPLEX(-C31,0) -> -1.55540040097562 | M31: =COMPLEX(0,0) -> 0 | N31: =COMPLEX(1,0) -> 1 | O31: =IMSUM(IMPRODUCT(K31,O30),IMPRODUCT(L31,Q30)) -> 1+29.8704515650926i | P31: =IMSUM(IMPRODUCT(K31,P30),IMPRODUCT(L31,R30)) -> -2.46310060146343-3.88315870346205i | Q31: =IMSUM(IMPRODUCT(M31,O30),IMPRODUCT(N31,Q30)) -> -12.8028990890305i | R31: =IMSUM(IMPRODUCT(M31,P30),IMPRODUCT(N31,R30)) -> 1+1.66437688157397i
A32: node 3 | B32: cap | C32: =INDEX(Classes!$B$5:$F$9,MATCH($C$6,Classes!$A$5:$A$9,0),3)*(N22*1000) -> 0 | K32: =COMPLEX(1,0) -> 1 | L32: =COMPLEX(0,0) -> 0 | M32: =COMPLEX(0,-(2*PI()/($B$5*3600))*C32) -> 0 | N32: =COMPLEX(1,0) -> 1 | O32: =IMSUM(IMPRODUCT(K32,O31),IMPRODUCT(L32,Q31)) -> 1+29.8704515650926i | P32: =IMSUM(IMPRODUCT(K32,P31),IMPRODUCT(L32,R31)) -> -2.46310060146343-3.88315870346205i | Q32: =IMSUM(IMPRODUCT(M32,O31),IMPRODUCT(N32,Q31)) -> -12.8028990890305i | R32: =IMSUM(IMPRODUCT(M32,P31),IMPRODUCT(N32,R31)) -> 1+1.66437688157397i
A33: 3/Rc | B33: res | C33: =P22/3 -> 1.5554004 | K33: =COMPLEX(1,0) -> 1 | L33: =COMPLEX(-C33,0) -> -1.55540040097562 | M33: =COMPLEX(0,0) -> 0 | N33: =COMPLEX(1,0) -> 1 | O33: =IMSUM(IMPRODUCT(K33,O32),IMPRODUCT(L33,Q32)) -> 1+49.784085941821i | P33: =IMSUM(IMPRODUCT(K33,P32),IMPRODUCT(L33,R32)) -> -4.01850100243905-6.47193117243675i | Q33: =IMSUM(IMPRODUCT(M33,O32),IMPRODUCT(N33,Q32)) -> -12.8028990890305i | R33: =IMSUM(IMPRODUCT(M33,P32),IMPRODUCT(N33,R32)) -> 1+1.66437688157397i
A34: node 2 | B34: cap | C34: =INDEX(Classes!$B$5:$F$9,MATCH($C$6,Classes!$A$5:$A$9,0),2)*(N22*1000) -> 0 | K34: =COMPLEX(1,0) -> 1 | L34: =COMPLEX(0,0) -> 0 | M34: =COMPLEX(0,-(2*PI()/($B$5*3600))*C34) -> 0 | N34: =COMPLEX(1,0) -> 1 | O34: =IMSUM(IMPRODUCT(K34,O33),IMPRODUCT(L34,Q33)) -> 1+49.784085941821i | P34: =IMSUM(IMPRODUCT(K34,P33),IMPRODUCT(L34,R33)) -> -4.01850100243905-6.47193117243675i | Q34: =IMSUM(IMPRODUCT(M34,O33),IMPRODUCT(N34,Q33)) -> -12.8028990890305i | R34: =IMSUM(IMPRODUCT(M34,P33),IMPRODUCT(N34,R33)) -> 1+1.66437688157397i
A35: 6/Rc | B35: res | C35: =P22/6 -> 0.7777002 | K35: =COMPLEX(1,0) -> 1 | L35: =COMPLEX(-C35,0) -> -0.777700200487811 | M35: =COMPLEX(0,0) -> 0 | N35: =COMPLEX(1,0) -> 1 | O35: =IMSUM(IMPRODUCT(K35,O34),IMPRODUCT(L35,Q34)) -> 1+59.7409031301852i | P35: =IMSUM(IMPRODUCT(K35,P34),IMPRODUCT(L35,R34)) -> -4.79620120292686-7.7663174069241i | Q35: =IMSUM(IMPRODUCT(M35,O34),IMPRODUCT(N35,Q34)) -> -12.8028990890305i | R35: =IMSUM(IMPRODUCT(M35,P34),IMPRODUCT(N35,R34)) -> 1+1.66437688157397i
A36: node 1 (outer) | B36: cap | C36: =INDEX(Classes!$B$5:$F$9,MATCH($C$6,Classes!$A$5:$A$9,0),1)*(N22*1000) -> 176052.5 | K36: =COMPLEX(1,0) -> 1 | L36: =COMPLEX(0,0) -> 0 | M36: =COMPLEX(0,-(2*PI()/($B$5*3600))*C36) -> -12.8028990890305i | N36: =COMPLEX(1,0) -> 1 | O36: =IMSUM(IMPRODUCT(K36,O35),IMPRODUCT(L36,Q35)) -> 1+59.7409031301852i | P36: =IMSUM(IMPRODUCT(K36,P35),IMPRODUCT(L36,R35)) -> -4.79620120292686-7.7663174069241i | Q36: =IMSUM(IMPRODUCT(M36,O35),IMPRODUCT(N36,Q35)) -> 764.856754263307-25.605798178061i | R36: =IMSUM(IMPRODUCT(M36,P35),IMPRODUCT(N36,R35)) -> -98.4313780542303+63.0696568933333i
A37: far-side layer | B37: as ISO | K37: =K20 -> 1 | L37: =L20 -> -0 | M37: =M20 -> 0 | N37: =N20 -> 1 | O37: =IMSUM(IMPRODUCT(K37,O36),IMPRODUCT(L37,Q36)) -> 1+59.7409031301852i | P37: =IMSUM(IMPRODUCT(K37,P36),IMPRODUCT(L37,R36)) -> -4.79620120292686-7.7663174069241i | Q37: =IMSUM(IMPRODUCT(M37,O36),IMPRODUCT(N37,Q36)) -> 764.856754263307-25.605798178061i | R37: =IMSUM(IMPRODUCT(M37,P36),IMPRODUCT(N37,R36)) -> -98.4313780542303+63.0696568933333i
A38: Rse | B38: as ISO | K38: =K21 -> 1 | L38: =L21 -> -0.04 | M38: =M21 -> 0 | N38: =N21 -> 1 | O38: =IMSUM(IMPRODUCT(K38,O37),IMPRODUCT(L38,Q37)) -> -29.5942701705323+60.7651350573076i | P38: =IMSUM(IMPRODUCT(K38,P37),IMPRODUCT(L38,R37)) -> -0.85894608075765-10.2891036826574i | Q38: =IMSUM(IMPRODUCT(M38,O37),IMPRODUCT(N38,Q37)) -> 764.856754263307-25.605798178061i | R38: =IMSUM(IMPRODUCT(M38,P37),IMPRODUCT(N38,R37)) -> -98.4313780542303+63.0696568933333i
A39: |Y| five-node W/m²K | B39: =IMABS(IMDIV(IMPRODUCT(O38,COMPLEX(-1,0)),P38)) -> 6.546181
A41: Five-node |Y| by class, same period
A42: Class | B42: |Y| W/m²K | C42: ÷ ISO
A43: I | B43: =B65 -> 7.3502914 | C43: =B43/D22 -> 2.3225992
A44: E | B44: =B82 -> 0.20765137 | C44: =B44/D22 -> 0.065615212
A45: IE | B45: =B99 -> 6.546181 | C45: =B45/D22 -> 2.0685105
A46: D | B46: =B116 -> 2.9363547 | C46: =B46/D22 -> 0.92785101
...

Sheet Library results
A1: All build-ups at the period on the Engine sheet (24 h)
A2: Live formulas. The last two columns are the Python model's values for the same build-up, for checking.
A4: Key | B4: Build-up | C4: Class | D4: U | E4: |Y| | F4: Y lead h | G4: f | H4: lag h | I4: κ₁ | J4: κ total | K4: Five-node |Y| | L4: 5-node ÷ ISO | M4: Python |Y| | N4: Python 5-node |Y|
A5: W1 | B5: =INDEX(Library!$B$5:$B$34,MATCH(A5,Library!$A$5:$A$34,0)) -> Cavity: wet plaster, 100 dense block, 150 MW, brick | C5: =Engine!C5 -> IE | D5: =Engine!B19 -> 0.21264482 | E5: =Engine!D19 -> 5.2133448 | F5: =Engine!F19 -> 1.3706898 | G5: =Engine!H19 -> 0.2492095 | H5: =Engine!J19 -> 9.9322194 | I5: =Engine!L19 -> 72.405364 | J5: =Engine!N19 -> 360.255 | K5: =Engine!B35 -> 6.5855971 | L5: =K5/E5 -> 1.2632192 | M5: 5.213 | N5: 6.586
A6: W2 | B6: =INDEX(Library!$B$5:$B$34,MATCH(A6,Library!$A$5:$A$34,0)) -> Cavity: board on dabs, 100 dense block, 150 MW, brick | C6: =Engine!C38 -> IE | D6: =Engine!B52 -> 0.20677386 | E6: =Engine!D52 -> 3.1646834 | F6: =Engine!F52 -> 1.009561 | G6: =Engine!H52 -> 0.16133724 | H6: =Engine!J52 -> 10.476924 | I6: =Engine!L52 -> 43.972162 | J6: =Engine!N52 -> 352.105 | K6: =Engine!B68 -> 6.546181 | L6: =K6/E6 -> 2.0685105 | M6: 3.165 | N6: 6.546
A7: W3 | B7: =INDEX(Library!$B$5:$B$34,MATCH(A7,Library!$A$5:$A$34,0)) -> Cavity: wet plaster, 100 aircrete, 150 MW, brick | C7: =Engine!C71 -> IE | D7: =Engine!B85 -> 0.18936351 | E7: =Engine!D85 -> 2.8161647 | F7: =Engine!F85 -> 2.7296702 | G7: =Engine!H85 -> 0.36293044 | H7: =Engine!J85 -> 10.115955 | I7: =Engine!L85 -> 39.64757 | J7: =Engine!N85 -> 220.255 | K7: =Engine!B101 -> 5.482666 | L7: =K7/E7 -> 1.9468556 | M7: 2.816 | N7: 5.483
A8: W4 | B8: =INDEX(Library!$B$5:$B$34,MATCH(A8,Library!$A$5:$A$34,0)) -> Cavity: board on dabs, 100 aircrete, 150 MW, brick | C8: =Engine!C104 -> IE | D8: =Engine!B118 -> 0.18469362 | E8: =Engine!D118 -> 2.026388 | F8: =Engine!F118 -> 2.315351 | G8: =Engine!H118 -> 0.30637913 | H8: =Engine!J118 -> 10.435761 | I8: =Engine!L118 -> 28.62836 | J8: =Engine!N118 -> 212.105 | K8: =Engine!B134 -> 5.3816737 | L8: =K8/E8 -> 2.6557963 | M8: 2.026 | N8: 5.382
