Workbook

Sheet Read me
B2: Conduction Lab (thermal mass toolkit, model 2)
B4: What it does:
B5: Drives one element with a sinusoidal room temperature for four days and steps the heat flow through it every five minutes, two ways: a fine finite-difference mesh (the reference) and the ISO 52016-1 / HEM five-node lump. It reports the heat taken in between 09:00 and 18:00 on the last day and the peak flux.
B7: How to use it:
B8: 1. Setup: choose the element (any Library key, or Custom), mesh cell size, five-node class, the room temperature cycle and the far-side temperature.
B9: 2. Results: absorbed heat, peak flux and timing for both methods, a chart of the last day, and the Python model's values for every build-up at the default set-up.
B11: How it works:
B12: FD mesh and 5N mesh build node capacities and conductances from the Library layers with formulas. 'FD A' and '5N A' hold the system matrix C/dt + G; the inverse sheets invert it once with MINVERSE; the run sheets step T(t+dt) = A⁻¹ (C/dt · T(t) + sources) with SUMPRODUCT.
B13: This is the same implicit Euler scheme as models/elements.py step_response, so with the same cell size the numbers match the Python model.
B14: The fine mesh has room for 60 nodes: use 10 mm cells for most elements and 20 mm for thick ones. A warning appears on FD mesh if the element needs more.
B16: Recalculation: about 100,000 formulas. Excel recalculates in a few seconds; if calculation is set to manual, press F9.
B18: Colour key:
... B21: Plain black: calculation steps and data.

Sheet Setup
A1: Conduction Lab: test set-up
A2: Change the blue cells. The four-day run recalculates (allow a few seconds).
A4: Element key | B4: W2 | C4: Any key on the Library sheet, or Custom
A5: Mesh cell size, mm | B5: 10 | C5: 10 or 20 (the sheet has room for 60 nodes)
A6: Five-node class | B6: rule | C6: rule, I, E, IE, D or M
A7: Room mean, °C | B7: 24
A8: Room amplitude, K | B8: 4
A9: Room peak hour | B9: 16
A10: Far-side temperature, °C | B10: 15 | C10: 15 for outdoor-facing elements, 24 for internal ones in the Python runs
A11: Time step, s | B11: 300 | C11: fixed: the run sheets have 1,152 rows
A13: Derived
A14: Row in library | B14: =MATCH(B4,Library!$A$5:$A$34,0) -> 2
A15: Build-up | B15: =INDEX(Library!$B$5:$B$34,B14) -> Cavity: board on dabs, 100 dense block, 150 MW, brick
A16: Far side | B16: =INDEX(Library!$D$5:$D$34,B14) -> ext
A17: Rsi | B17: =INDEX(Library!$E$5:$E$34,B14) -> 0.13
A18: Rse | B18: =IF(B16="ext",0.04,0) -> 0.04
A19: Class used | B19: =IF(B6="rule",INDEX(Library!$F$5:$F$34,B14),B6) -> IE
A20: Far-side conductance W/m²K | B20: =IF(B16="ext",IF(B18>0,1/B18,1000000),IF(B16="ground",1000000,0)) -> 25
A21: Room-coupled far face (1/0) | B21: =IF(B16="room",1,0) -> 0
A22: Far-side source W/m² | B22: =B20*B10+B21*B10/B17 -> 375

Sheet Results
A1: Conduction Lab: results
A2: =Setup!B4&": "&Setup!B15 -> W2: Cavity: board on dabs, 100 dense block, 150 MW, brick
B4: Fine mesh | C4: Five-node | D4: Five-node ÷ mesh
A5: Absorbed 09:00–18:00, last day, Wh/m² | B5: =SUMPRODUCT((MOD('FD run'!B869:B1156,24)>=9)*(MOD('FD run'!B869:B1156,24)<18),'FD run'!D869:D1156)*Setup!$B$11/3600 -> 100.51533 | C5: =SUMPRODUCT((MOD('5N run'!B869:B1156,24)>=9)*(MOD('5N run'!B869:B1156,24)<18),'5N run'!D869:D1156)*Setup!$B$11/3600 -> 199.10238 | D5: =C5/B5 -> 1.980816
A6: Peak flux into surface, W/m² | B6: =MAX('FD run'!D869:D1156) -> 14.665272 | C6: =MAX('5N run'!D869:D1156) -> 27.922315 | D6: =C6/B6 -> 1.9039752
A7: Hour of peak flux | B7: =MOD(INDEX('FD run'!B869:B1156,MATCH(B6,'FD run'!D869:D1156,0)),24) -> 15 | C7: =MOD(INDEX('5N run'!B869:B1156,MATCH(C6,'5N run'!D869:D1156,0)),24) -> 14
A8: Nodes used | B8: ='FD mesh'!B16 -> 40 | C8: ='5N mesh'!B7+1 -> 5
A10: Last-day flux (for the chart)
A11: hour | B11: fine mesh W/m² | C11: five-node W/m² | D11: room °C
A12: =MOD('FD run'!B869,24) -> 0 | B12: ='FD run'!D869 -> -6.698601 | C12: ='5N run'!D869 -> -20.836999 | D12: ='FD run'!C869 -> 22
A13: =MOD('FD run'!B870,24) -> 0.083333333 | B13: ='FD run'!D870 -> -6.8929636 | C13: ='5N run'!D870 -> -21.110996 | D13: ='FD run'!C870 -> 21.924907
A14: =MOD('FD run'!B871,24) -> 0.16666667 | B14: ='FD run'!D871 -> -7.0829608 | C14: ='5N run'!D871 -> -21.37406 | D14: ='FD run'!C871 -> 21.850802
A15: =MOD('FD run'!B872,24) -> 0.25 | B15: ='FD run'!D872 -> -7.2685033 | C15: ='5N run'!D872 -> -21.626065 | D15: ='FD run'!C872 -> 21.777719
A16: =MOD('FD run'!B873,24) -> 0.33333333 | B16: ='FD run'!D873 -> -7.4495037 | C16: ='5N run'!D873 -> -21.86689 | D16: ='FD run'!C873 -> 21.705694
A17: =MOD('FD run'!B874,24) -> 0.41666667 | B17: ='FD run'!D874 -> -7.6258769 | C17: ='5N run'!D874 -> -22.096422 | D17: ='FD run'!C874 -> 21.634761
A18: =MOD('FD run'!B875,24) -> 0.5 | B18: ='FD run'!D875 -> -7.7975398 | C18: ='5N run'!D875 -> -22.314551 | D18: ='FD run'!C875 -> 21.564954
A19: =MOD('FD run'!B876,24) -> 0.58333333 | B19: ='FD run'!D876 -> -7.9644117 | C19: ='5N run'!D876 -> -22.521174 | D19: ='FD run'!C876 -> 21.496306
A20: =MOD('FD run'!B877,24) -> 0.66666667 | B20: ='FD run'!D877 -> -8.1264142 | C20: ='5N run'!D877 -> -22.716191 | D20: ='FD run'!C877 -> 21.42885
A21: =MOD('FD run'!B878,24) -> 0.75 | B21: ='FD run'!D878 -> -8.2834711 | C21: ='5N run'!D878 -> -22.899511 | D21: ='FD run'!C878 -> 21.362617
A22: =MOD('FD run'!B879,24) -> 0.83333333 | B22: ='FD run'!D879 -> -8.4355086 | C22: ='5N run'!D879 -> -23.071046 | D22: ='FD run'!C879 -> 21.297639
A23: =MOD('FD run'!B880,24) -> 0.91666667 | B23: ='FD run'!D880 -> -8.5824553 | C23: ='5N run'!D880 -> -23.230713 | D23: ='FD run'!C880 -> 21.233948
A24: =MOD('FD run'!B881,24) -> 1 | B24: ='FD run'!D881 -> -8.7242422 | C24: ='5N run'!D881 -> -23.378439 | D24: ='FD run'!C881 -> 21.171573 | G24: Python reference (default set-up, 10 mm cells, library class)
A25: =MOD('FD run'!B882,24) -> 1.0833333 | B25: ='FD run'!D882 -> -8.8608028 | C25: ='5N run'!D882 -> -23.514151 | D25: ='FD run'!C882 -> 21.110544 | G25: Build-up | H25: Absorbed fine Wh/m² | I25: Absorbed 5-node Wh/m² | J25: Peak fine W/m² | K25: Peak 5-node W/m²
A26: =MOD('FD run'!B883,24) -> 1.1666667 | B26: ='FD run'!D883 -> -8.9920729 | C26: ='5N run'!D883 -> -23.637786 | D26: ='FD run'!C883 -> 21.050891 | G26: W1 · Cavity: wet plaster, 100 dense block, 150 MW, brick | H26: 157.25 | I26: 200.44 | J26: 22.72 | K26: 28.13
A27: =MOD('FD run'!B884,24) -> 1.25 | B27: ='FD run'!D884 -> -9.117991 | C27: ='5N run'!D884 -> -23.749284 | D27: ='FD run'!C884 -> 20.992641 | G27: W2 · Cavity: board on dabs, 100 dense block, 150 MW, brick | H27: 100.52 | I27: 199.1 | J27: 14.67 | K27: 27.92
A28: =MOD('FD run'!B885,24) -> 1.3333333 | B28: ='FD run'!D885 -> -9.2384981 | C28: ='5N run'!D885 -> -23.848593 | D28: ='FD run'!C885 -> 20.935822 | G28: W3 · Cavity: wet plaster, 100 aircrete, 150 MW, brick | H28: 94.62 | I28: 168.8 | J28: 12.95 | K28: 23.52
A29: =MOD('FD run'!B886,24) -> 1.4166667 | B29: ='FD run'!D886 -> -9.3535378 | C29: ='5N run'!D886 -> -23.935665 | D29: ='FD run'!C886 -> 20.880462 | G29: W4 · Cavity: board on dabs, 100 aircrete, 150 MW, brick | H29: 72 | I29: 165.35 | J29: 9.76 | K29: 23.08
A30: =MOD('FD run'!B887,24) -> 1.5 | B30: ='FD run'!D887 -> -9.4630562 | C30: ='5N run'!D887 -> -24.010459 | D30: ='FD run'!C887 -> 20.826587 | G30: W5 · Timber frame: board, 140 MW studs, OSB, cavity, brick | H30: 42.6 | I30: 25.13 | J30: 5.75 | K30: 3.16
A31: =MOD('FD run'!B888,24) -> 1.5833333 | B31: ='FD run'!D888 -> -9.5670022 | C31: ='5N run'!D888 -> -24.072939 | D31: ='FD run'!C888 -> 20.774222 | G31: W6 · Timber frame: board, 140 MW studs, 60 wood fibre, render | H31: 38.89 | I31: 43.62 | J31: 5.38 | K31: 5.79
A32: =MOD('FD run'!B889,24) -> 1.6666667 | B32: ='FD run'!D889 -> -9.6653271 | C32: ='5N run'!D889 -> -24.123075 | D32: ='FD run'!C889 -> 20.723392 | G32: W7 · SIPs: board, OSB, 142 PUR, OSB, ventilated cladding | H32: 54.56 | I32: 50.53 | J32: 7.8 | K32: 7.95
A33: =MOD('FD run'!B890,24) -> 1.75 | B33: ='FD run'!D890 -> -9.757985 | C33: ='5N run'!D890 -> -24.160845 | D33: ='FD run'!C890 -> 20.674122 | G33: W8 · Exposed 100 CLT, 160 wood fibre, render | H33: 77.38 | I33: 189.33 | J33: 10.5 | K33: 26.38
A34: =MOD('FD run'!B891,24) -> 1.8333333 | B34: ='FD run'!D891 -> -9.8449327 | C34: ='5N run'!D891 -> -24.186229 | D34: ='FD run'!C891 -> 20.626434 | G34: W9 · Lined CLT: board, 100 CLT, 160 MW, cladding | H34: 65.29 | I34: 149 | J34: 8.86 | K34: 21.01
A35: =MOD('FD run'!B892,24) -> 1.9166667 | B35: ='FD run'!D892 -> -9.9261298 | C35: ='5N run'!D892 -> -24.199215 | D35: ='FD run'!C892 -> 20.580353 | G35: W10 · ICF: board on dabs, 70 EPS, 150 concrete, 70 EPS, render | H35: 45.33 | I35: 34.63 | J35: 5.77 | K35: 4.45
A36: =MOD('FD run'!B893,24) -> 2 | B36: ='FD run'!D893 -> -10.001539 | C36: ='5N run'!D893 -> -24.199798 | D36: ='FD run'!C893 -> 20.535898 | G36: W11 · Solid 215 brick, wet plaster, uninsulated | H36: 285.22 | I36: 299.71 | J36: 35.94 | K36: 37.77
A37: =MOD('FD run'!B894,24) -> 2.0833333 | B37: ='FD run'!D894 -> -10.071124 | C37: ='5N run'!D894 -> -24.187977 | D37: ='FD run'!C894 -> 20.493093 | G37: W12 · Solid brick + IWI: board, 80 PIR, 215 brick | H37: 38.48 | I37: 24.94 | J37: 5.12 | K37: 3.14
... A54: =MOD('FD run'!B911,24) -> 3.5 | B54: ='FD run'!D911 -> -10.342757 | C54: ='5N run'!D911 -> -22.117422 | D54: ='FD run'!C911 -> 20.034221 | G54: R2 · Exposed 200 concrete roof slab, 150 PIR | H54: 207.45 | I54: 263.13 | J54: 31.16 | K54: 39.76
A55: =MOD('FD run'!B912,24) -> 3.5833333 | B55: ='FD run'!D912 -> -10.304742 | C55: ='5N run'!D912 -> -21.888959 | D55: ='FD run'!C912 -> 20.023775
A56: =MOD('FD run'!B913,24) -> 3.6666667 | B56: ='FD run'!D913 -> -10.260775 | C56: ='5N run'!D913 -> -21.649192 | D56: ='FD run'!C913 -> 20.015221 | G56: Set the far-side temperature to 24 °C for internal elements (partitions, floors) to match these rows.
A57: =MOD('FD run'!B914,24) -> 3.75 | B57: ='FD run'!D914 -> -10.210878 | C57: ='5N run'!D914 -> -21.398235 | D57: ='FD run'!C914 -> 20.008564
A58: =MOD('FD run'!B915,24) -> 3.8333333 | B58: ='FD run'!D915 -> -10.155076 | C58: ='5N run'!D915 -> -21.136208 | D58: ='FD run'!C915 -> 20.003807
...

Sheet FD mesh
A1: Fine mesh: layers → cells → nodes
A4: Layer | B4: Material | C4: Type | D4: d m | E4: λ | F4: ρ | G4: c | H4: R | I4: cells | J4: h m | K4: g cell W/m²K | L4: C cell J/m²K | M4: first cell − 1 | N4: R part
A5: Layer 1 | B5: =IF(INDEX(Library!$G$5:$G$34,Setup!$B$14)="","",INDEX(Library!$G$5:$G$34,Setup!$B$14)) -> plasterboard | C5: =IF(B5="","none",IF(B5="Cavity","res","mass")) -> mass | D5: =IF(C5="mass",INDEX(Library!$H$5:$H$34,Setup!$B$14)/1000,0) -> 0.0125 | E5: =IF(C5="mass",INDEX(Materials!$B$5:$B$28,MATCH(B5,Materials!$A$5:$A$28,0)),0) -> 0.21 | F5: =IF(C5="mass",INDEX(Materials!$C$5:$C$28,MATCH(B5,Materials!$A$5:$A$28,0)),0) -> 700 | G5: =IF(C5="mass",INDEX(Materials!$D$5:$D$28,MATCH(B5,Materials!$A$5:$A$28,0)),0) -> 1000 | H5: =IF(C5="res",INDEX(Library!$H$5:$H$34,Setup!$B$14),0) -> 0 | I5: =IF(C5="mass",MAX(1,CEILING(D5/(Setup!$B$5/1000)-0.000000001,1)),IF(C5="res",1,0)) -> 2 | J5: =IF(I5>0,D5/I5,0) -> 0.00625 | K5: =IF(C5="mass",E5/J5,IF(C5="res",1/H5,0)) -> 33.6 | L5: =IF(C5="mass",F5*G5*J5,0) -> 4375 | M5: =0 -> 0 | N5: =IF(C5="mass",D5/E5,H5) -> 0.05952381
A6: Layer 2 | B6: =IF(INDEX(Library!$I$5:$I$34,Setup!$B$14)="","",INDEX(Library!$I$5:$I$34,Setup!$B$14)) -> Cavity | C6: =IF(B6="","none",IF(B6="Cavity","res","mass")) -> res | D6: =IF(C6="mass",INDEX(Library!$J$5:$J$34,Setup!$B$14)/1000,0) -> 0 | E6: =IF(C6="mass",INDEX(Materials!$B$5:$B$28,MATCH(B6,Materials!$A$5:$A$28,0)),0) -> 0 | F6: =IF(C6="mass",INDEX(Materials!$C$5:$C$28,MATCH(B6,Materials!$A$5:$A$28,0)),0) -> 0 | G6: =IF(C6="mass",INDEX(Materials!$D$5:$D$28,MATCH(B6,Materials!$A$5:$A$28,0)),0) -> 0 | H6: =IF(C6="res",INDEX(Library!$J$5:$J$34,Setup!$B$14),0) -> 0.1 | I6: =IF(C6="mass",MAX(1,CEILING(D6/(Setup!$B$5/1000)-0.000000001,1)),IF(C6="res",1,0)) -> 1 | J6: =IF(I6>0,D6/I6,0) -> 0 | K6: =IF(C6="mass",E6/J6,IF(C6="res",1/H6,0)) -> 10 | L6: =IF(C6="mass",F6*G6*J6,0) -> 0 | M6: =M5+I5 -> 2 | N6: =IF(C6="mass",D6/E6,H6) -> 0.1
A7: Layer 3 | B7: =IF(INDEX(Library!$K$5:$K$34,Setup!$B$14)="","",INDEX(Library!$K$5:$K$34,Setup!$B$14)) -> dense block | C7: =IF(B7="","none",IF(B7="Cavity","res","mass")) -> mass | D7: =IF(C7="mass",INDEX(Library!$L$5:$L$34,Setup!$B$14)/1000,0) -> 0.1 | E7: =IF(C7="mass",INDEX(Materials!$B$5:$B$28,MATCH(B7,Materials!$A$5:$A$28,0)),0) -> 1.13 | F7: =IF(C7="mass",INDEX(Materials!$C$5:$C$28,MATCH(B7,Materials!$A$5:$A$28,0)),0) -> 2000 | G7: =IF(C7="mass",INDEX(Materials!$D$5:$D$28,MATCH(B7,Materials!$A$5:$A$28,0)),0) -> 1000 | H7: =IF(C7="res",INDEX(Library!$L$5:$L$34,Setup!$B$14),0) -> 0 | I7: =IF(C7="mass",MAX(1,CEILING(D7/(Setup!$B$5/1000)-0.000000001,1)),IF(C7="res",1,0)) -> 10 | J7: =IF(I7>0,D7/I7,0) -> 0.01 | K7: =IF(C7="mass",E7/J7,IF(C7="res",1/H7,0)) -> 113 | L7: =IF(C7="mass",F7*G7*J7,0) -> 20000 | M7: =M6+I6 -> 3 | N7: =IF(C7="mass",D7/E7,H7) -> 0.088495575
A8: Layer 4 | B8: =IF(INDEX(Library!$M$5:$M$34,Setup!$B$14)="","",INDEX(Library!$M$5:$M$34,Setup!$B$14)) -> mineral wool | C8: =IF(B8="","none",IF(B8="Cavity","res","mass")) -> mass | D8: =IF(C8="mass",INDEX(Library!$N$5:$N$34,Setup!$B$14)/1000,0) -> 0.15 | E8: =IF(C8="mass",INDEX(Materials!$B$5:$B$28,MATCH(B8,Materials!$A$5:$A$28,0)),0) -> 0.035 | F8: =IF(C8="mass",INDEX(Materials!$C$5:$C$28,MATCH(B8,Materials!$A$5:$A$28,0)),0) -> 30 | G8: =IF(C8="mass",INDEX(Materials!$D$5:$D$28,MATCH(B8,Materials!$A$5:$A$28,0)),0) -> 1030 | H8: =IF(C8="res",INDEX(Library!$N$5:$N$34,Setup!$B$14),0) -> 0 | I8: =IF(C8="mass",MAX(1,CEILING(D8/(Setup!$B$5/1000)-0.000000001,1)),IF(C8="res",1,0)) -> 15 | J8: =IF(I8>0,D8/I8,0) -> 0.01 | K8: =IF(C8="mass",E8/J8,IF(C8="res",1/H8,0)) -> 3.5 | L8: =IF(C8="mass",F8*G8*J8,0) -> 309 | M8: =M7+I7 -> 13 | N8: =IF(C8="mass",D8/E8,H8) -> 4.2857143
A9: Layer 5 | B9: =IF(INDEX(Library!$O$5:$O$34,Setup!$B$14)="","",INDEX(Library!$O$5:$O$34,Setup!$B$14)) -> brick | C9: =IF(B9="","none",IF(B9="Cavity","res","mass")) -> mass | D9: =IF(C9="mass",INDEX(Library!$P$5:$P$34,Setup!$B$14)/1000,0) -> 0.102 | E9: =IF(C9="mass",INDEX(Materials!$B$5:$B$28,MATCH(B9,Materials!$A$5:$A$28,0)),0) -> 0.77 | F9: =IF(C9="mass",INDEX(Materials!$C$5:$C$28,MATCH(B9,Materials!$A$5:$A$28,0)),0) -> 1700 | G9: =IF(C9="mass",INDEX(Materials!$D$5:$D$28,MATCH(B9,Materials!$A$5:$A$28,0)),0) -> 800 | H9: =IF(C9="res",INDEX(Library!$P$5:$P$34,Setup!$B$14),0) -> 0 | I9: =IF(C9="mass",MAX(1,CEILING(D9/(Setup!$B$5/1000)-0.000000001,1)),IF(C9="res",1,0)) -> 11 | J9: =IF(I9>0,D9/I9,0) -> 0.0092727273 | K9: =IF(C9="mass",E9/J9,IF(C9="res",1/H9,0)) -> 83.039216 | L9: =IF(C9="mass",F9*G9*J9,0) -> 12610.909 | M9: =M8+I8 -> 28 | N9: =IF(C9="mass",D9/E9,H9) -> 0.13246753
A10: Layer 6 | B10: =IF(INDEX(Library!$Q$5:$Q$34,Setup!$B$14)="","",INDEX(Library!$Q$5:$Q$34,Setup!$B$14)) | C10: =IF(B10="","none",IF(B10="Cavity","res","mass")) -> none | D10: =IF(C10="mass",INDEX(Library!$R$5:$R$34,Setup!$B$14)/1000,0) -> 0 | E10: =IF(C10="mass",INDEX(Materials!$B$5:$B$28,MATCH(B10,Materials!$A$5:$A$28,0)),0) -> 0 | F10: =IF(C10="mass",INDEX(Materials!$C$5:$C$28,MATCH(B10,Materials!$A$5:$A$28,0)),0) -> 0 | G10: =IF(C10="mass",INDEX(Materials!$D$5:$D$28,MATCH(B10,Materials!$A$5:$A$28,0)),0) -> 0 | H10: =IF(C10="res",INDEX(Library!$R$5:$R$34,Setup!$B$14),0) -> 0 | I10: =IF(C10="mass",MAX(1,CEILING(D10/(Setup!$B$5/1000)-0.000000001,1)),IF(C10="res",1,0)) -> 0 | J10: =IF(I10>0,D10/I10,0) -> 0 | K10: =IF(C10="mass",E10/J10,IF(C10="res",1/H10,0)) -> 0 | L10: =IF(C10="mass",F10*G10*J10,0) -> 0 | M10: =M9+I9 -> 39 | N10: =IF(C10="mass",D10/E10,H10) -> 0
A11: Layer 7 | B11: =IF(INDEX(Library!$S$5:$S$34,Setup!$B$14)="","",INDEX(Library!$S$5:$S$34,Setup!$B$14)) | C11: =IF(B11="","none",IF(B11="Cavity","res","mass")) -> none | D11: =IF(C11="mass",INDEX(Library!$T$5:$T$34,Setup!$B$14)/1000,0) -> 0 | E11: =IF(C11="mass",INDEX(Materials!$B$5:$B$28,MATCH(B11,Materials!$A$5:$A$28,0)),0) -> 0 | F11: =IF(C11="mass",INDEX(Materials!$C$5:$C$28,MATCH(B11,Materials!$A$5:$A$28,0)),0) -> 0 | G11: =IF(C11="mass",INDEX(Materials!$D$5:$D$28,MATCH(B11,Materials!$A$5:$A$28,0)),0) -> 0 | H11: =IF(C11="res",INDEX(Library!$T$5:$T$34,Setup!$B$14),0) -> 0 | I11: =IF(C11="mass",MAX(1,CEILING(D11/(Setup!$B$5/1000)-0.000000001,1)),IF(C11="res",1,0)) -> 0 | J11: =IF(I11>0,D11/I11,0) -> 0 | K11: =IF(C11="mass",E11/J11,IF(C11="res",1/H11,0)) -> 0 | L11: =IF(C11="mass",F11*G11*J11,0) -> 0 | M11: =M10+I10 -> 39 | N11: =IF(C11="mass",D11/E11,H11) -> 0
A12: Layer 8 | B12: =IF(INDEX(Library!$U$5:$U$34,Setup!$B$14)="","",INDEX(Library!$U$5:$U$34,Setup!$B$14)) | C12: =IF(B12="","none",IF(B12="Cavity","res","mass")) -> none | D12: =IF(C12="mass",INDEX(Library!$V$5:$V$34,Setup!$B$14)/1000,0) -> 0 | E12: =IF(C12="mass",INDEX(Materials!$B$5:$B$28,MATCH(B12,Materials!$A$5:$A$28,0)),0) -> 0 | F12: =IF(C12="mass",INDEX(Materials!$C$5:$C$28,MATCH(B12,Materials!$A$5:$A$28,0)),0) -> 0 | G12: =IF(C12="mass",INDEX(Materials!$D$5:$D$28,MATCH(B12,Materials!$A$5:$A$28,0)),0) -> 0 | H12: =IF(C12="res",INDEX(Library!$V$5:$V$34,Setup!$B$14),0) -> 0 | I12: =IF(C12="mass",MAX(1,CEILING(D12/(Setup!$B$5/1000)-0.000000001,1)),IF(C12="res",1,0)) -> 0 | J12: =IF(I12>0,D12/I12,0) -> 0 | K12: =IF(C12="mass",E12/J12,IF(C12="res",1/H12,0)) -> 0 | L12: =IF(C12="mass",F12*G12*J12,0) -> 0 | M12: =M11+I11 -> 39 | N12: =IF(C12="mass",D12/E12,H12) -> 0
A13: Soil (ground floors) | B13: =IF(Setup!$B$16="ground","clay soil","") | C13: =IF(B13="","none","mass") -> none | D13: =IF(C13="mass",1,0) -> 0 | E13: =IF(C13="mass",INDEX(Materials!$B$5:$B$28,MATCH(B13,Materials!$A$5:$A$28,0)),0) -> 0 | F13: =IF(C13="mass",INDEX(Materials!$C$5:$C$28,MATCH(B13,Materials!$A$5:$A$28,0)),0) -> 0 | G13: =IF(C13="mass",INDEX(Materials!$D$5:$D$28,MATCH(B13,Materials!$A$5:$A$28,0)),0) -> 0 | H13: 0 | I13: =IF(C13="mass",20,0) -> 0 | J13: =IF(I13>0,D13/I13,0) -> 0 | K13: =IF(C13="mass",E13/J13,IF(C13="res",1/H13,0)) -> 0 | L13: =IF(C13="mass",F13*G13*J13,0) -> 0 | M13: =M12+I12 -> 39 | N13: =IF(C13="mass",D13/E13,H13) -> 0
A15: Cells in total | B15: =SUM(I5:I13) -> 39
A16: Nodes | B16: =B15+1 -> 40 | C16: =IF(B16>60,"Too many nodes: use 20 mm cells","")
A19: Cell j | B19: layer | C19: g W/m²K | D19: C J/m²K | F19: Node k | G19: valid | H19: C node J/m²K | I19: g to next | J19: C/dt | K19: diagonal of A
A20: 1 | B20: =IF(A20<=$B$15,COUNTIF($M$5:$M$13,"<="&(A20-1)),0) -> 1 | C20: =IF(B20>0,INDEX($K$5:$K$13,B20),0) -> 33.6 | D20: =IF(B20>0,INDEX($L$5:$L$13,B20),0) -> 4375 | F20: 0 | G20: =IF(F20<=$B$15,1,0) -> 1 | H20: =IF(G20=1,(0+D20)/2,0) -> 2187.5 | I20: =IF(F20<$B$15,C20,0) -> 33.6 | J20: =H20/Setup!$B$11 -> 7.2916667 | K20: =IF(G20=1,J20+0+I20+IF(F20=0,1/Setup!$B$17,0)+IF(F20=$B$15,Setup!$B$20+Setup!$B$21/Setup!$B$17,0),1) -> 48.583974
A21: 2 | B21: =IF(A21<=$B$15,COUNTIF($M$5:$M$13,"<="&(A21-1)),0) -> 1 | C21: =IF(B21>0,INDEX($K$5:$K$13,B21),0) -> 33.6 | D21: =IF(B21>0,INDEX($L$5:$L$13,B21),0) -> 4375 | F21: 1 | G21: =IF(F21<=$B$15,1,0) -> 1 | H21: =IF(G21=1,(D20+D21)/2,0) -> 4375 | I21: =IF(F21<$B$15,C21,0) -> 33.6 | J21: =H21/Setup!$B$11 -> 14.583333 | K21: =IF(G21=1,J21+I20+I21+IF(F21=0,1/Setup!$B$17,0)+IF(F21=$B$15,Setup!$B$20+Setup!$B$21/Setup!$B$17,0),1) -> 81.783333
A22: 3 | B22: =IF(A22<=$B$15,COUNTIF($M$5:$M$13,"<="&(A22-1)),0) -> 2 | C22: =IF(B22>0,INDEX($K$5:$K$13,B22),0) -> 10 | D22: =IF(B22>0,INDEX($L$5:$L$13,B22),0) -> 0 | F22: 2 | G22: =IF(F22<=$B$15,1,0) -> 1 | H22: =IF(G22=1,(D21+D22)/2,0) -> 2187.5 | I22: =IF(F22<$B$15,C22,0) -> 10 | J22: =H22/Setup!$B$11 -> 7.2916667 | K22: =IF(G22=1,J22+I21+I22+IF(F22=0,1/Setup!$B$17,0)+IF(F22=$B$15,Setup!$B$20+Setup!$B$21/Setup!$B$17,0),1) -> 50.891667
A23: 4 | B23: =IF(A23<=$B$15,COUNTIF($M$5:$M$13,"<="&(A23-1)),0) -> 3 | C23: =IF(B23>0,INDEX($K$5:$K$13,B23),0) -> 113 | D23: =IF(B23>0,INDEX($L$5:$L$13,B23),0) -> 20000 | F23: 3 | G23: =IF(F23<=$B$15,1,0) -> 1 | H23: =IF(G23=1,(D22+D23)/2,0) -> 10000 | I23: =IF(F23<$B$15,C23,0) -> 113 | J23: =H23/Setup!$B$11 -> 33.333333 | K23: =IF(G23=1,J23+I22+I23+IF(F23=0,1/Setup!$B$17,0)+IF(F23=$B$15,Setup!$B$20+Setup!$B$21/Setup!$B$17,0),1) -> 156.33333
A24: 5 | B24: =IF(A24<=$B$15,COUNTIF($M$5:$M$13,"<="&(A24-1)),0) -> 3 | C24: =IF(B24>0,INDEX($K$5:$K$13,B24),0) -> 113 | D24: =IF(B24>0,INDEX($L$5:$L$13,B24),0) -> 20000 | F24: 4 | G24: =IF(F24<=$B$15,1,0) -> 1 | H24: =IF(G24=1,(D23+D24)/2,0) -> 20000 | I24: =IF(F24<$B$15,C24,0) -> 113 | J24: =H24/Setup!$B$11 -> 66.666667 | K24: =IF(G24=1,J24+I23+I24+IF(F24=0,1/Setup!$B$17,0)+IF(F24=$B$15,Setup!$B$20+Setup!$B$21/Setup!$B$17,0),1) -> 292.66667
A25: 6 | B25: =IF(A25<=$B$15,COUNTIF($M$5:$M$13,"<="&(A25-1)),0) -> 3 | C25: =IF(B25>0,INDEX($K$5:$K$13,B25),0) -> 113 | D25: =IF(B25>0,INDEX($L$5:$L$13,B25),0) -> 20000 | F25: 5 | G25: =IF(F25<=$B$15,1,0) -> 1 | H25: =IF(G25=1,(D24+D25)/2,0) -> 20000 | I25: =IF(F25<$B$15,C25,0) -> 113 | J25: =H25/Setup!$B$11 -> 66.666667 | K25: =IF(G25=1,J25+I24+I25+IF(F25=0,1/Setup!$B$17,0)+IF(F25=$B$15,Setup!$B$20+Setup!$B$21/Setup!$B$17,0),1) -> 292.66667
A26: 7 | B26: =IF(A26<=$B$15,COUNTIF($M$5:$M$13,"<="&(A26-1)),0) -> 3 | C26: =IF(B26>0,INDEX($K$5:$K$13,B26),0) -> 113 | D26: =IF(B26>0,INDEX($L$5:$L$13,B26),0) -> 20000 | F26: 6 | G26: =IF(F26<=$B$15,1,0) -> 1 | H26: =IF(G26=1,(D25+D26)/2,0) -> 20000 | I26: =IF(F26<$B$15,C26,0) -> 113 | J26: =H26/Setup!$B$11 -> 66.666667 | K26: =IF(G26=1,J26+I25+I26+IF(F26=0,1/Setup!$B$17,0)+IF(F26=$B$15,Setup!$B$20+Setup!$B$21/Setup!$B$17,0),1) -> 292.66667
A27: 8 | B27: =IF(A27<=$B$15,COUNTIF($M$5:$M$13,"<="&(A27-1)),0) -> 3 | C27: =IF(B27>0,INDEX($K$5:$K$13,B27),0) -> 113 | D27: =IF(B27>0,INDEX($L$5:$L$13,B27),0) -> 20000 | F27: 7 | G27: =IF(F27<=$B$15,1,0) -> 1 | H27: =IF(G27=1,(D26+D27)/2,0) -> 20000 | I27: =IF(F27<$B$15,C27,0) -> 113 | J27: =H27/Setup!$B$11 -> 66.666667 | K27: =IF(G27=1,J27+I26+I27+IF(F27=0,1/Setup!$B$17,0)+IF(F27=$B$15,Setup!$B$20+Setup!$B$21/Setup!$B$17,0),1) -> 292.66667
A28: 9 | B28: =IF(A28<=$B$15,COUNTIF($M$5:$M$13,"<="&(A28-1)),0) -> 3 | C28: =IF(B28>0,INDEX($K$5:$K$13,B28),0) -> 113 | D28: =IF(B28>0,INDEX($L$5:$L$13,B28),0) -> 20000 | F28: 8 | G28: =IF(F28<=$B$15,1,0) -> 1 | H28: =IF(G28=1,(D27+D28)/2,0) -> 20000 | I28: =IF(F28<$B$15,C28,0) -> 113 | J28: =H28/Setup!$B$11 -> 66.666667 | K28: =IF(G28=1,J28+I27+I28+IF(F28=0,1/Setup!$B$17,0)+IF(F28=$B$15,Setup!$B$20+Setup!$B$21/Setup!$B$17,0),1) -> 292.66667
A29: 10 | B29: =IF(A29<=$B$15,COUNTIF($M$5:$M$13,"<="&(A29-1)),0) -> 3 | C29: =IF(B29>0,INDEX($K$5:$K$13,B29),0) -> 113 | D29: =IF(B29>0,INDEX($L$5:$L$13,B29),0) -> 20000 | F29: 9 | G29: =IF(F29<=$B$15,1,0) -> 1 | H29: =IF(G29=1,(D28+D29)/2,0) -> 20000 | I29: =IF(F29<$B$15,C29,0) -> 113 | J29: =H29/Setup!$B$11 -> 66.666667 | K29: =IF(G29=1,J29+I28+I29+IF(F29=0,1/Setup!$B$17,0)+IF(F29=$B$15,Setup!$B$20+Setup!$B$21/Setup!$B$17,0),1) -> 292.66667
A30: 11 | B30: =IF(A30<=$B$15,COUNTIF($M$5:$M$13,"<="&(A30-1)),0) -> 3 | C30: =IF(B30>0,INDEX($K$5:$K$13,B30),0) -> 113 | D30: =IF(B30>0,INDEX($L$5:$L$13,B30),0) -> 20000 | F30: 10 | G30: =IF(F30<=$B$15,1,0) -> 1 | H30: =IF(G30=1,(D29+D30)/2,0) -> 20000 | I30: =IF(F30<$B$15,C30,0) -> 113 | J30: =H30/Setup!$B$11 -> 66.666667 | K30: =IF(G30=1,J30+I29+I30+IF(F30=0,1/Setup!$B$17,0)+IF(F30=$B$15,Setup!$B$20+Setup!$B$21/Setup!$B$17,0),1) -> 292.66667
A31: 12 | B31: =IF(A31<=$B$15,COUNTIF($M$5:$M$13,"<="&(A31-1)),0) -> 3 | C31: =IF(B31>0,INDEX($K$5:$K$13,B31),0) -> 113 | D31: =IF(B31>0,INDEX($L$5:$L$13,B31),0) -> 20000 | F31: 11 | G31: =IF(F31<=$B$15,1,0) -> 1 | H31: =IF(G31=1,(D30+D31)/2,0) -> 20000 | I31: =IF(F31<$B$15,C31,0) -> 113 | J31: =H31/Setup!$B$11 -> 66.666667 | K31: =IF(G31=1,J31+I30+I31+IF(F31=0,1/Setup!$B$17,0)+IF(F31=$B$15,Setup!$B$20+Setup!$B$21/Setup!$B$17,0),1) -> 292.66667
A32: 13 | B32: =IF(A32<=$B$15,COUNTIF($M$5:$M$13,"<="&(A32-1)),0) -> 3 | C32: =IF(B32>0,INDEX($K$5:$K$13,B32),0) -> 113 | D32: =IF(B32>0,INDEX($L$5:$L$13,B32),0) -> 20000 | F32: 12 | G32: =IF(F32<=$B$15,1,0) -> 1 | H32: =IF(G32=1,(D31+D32)/2,0) -> 20000 | I32: =IF(F32<$B$15,C32,0) -> 113 | J32: =H32/Setup!$B$11 -> 66.666667 | K32: =IF(G32=1,J32+I31+I32+IF(F32=0,1/Setup!$B$17,0)+IF(F32=$B$15,Setup!$B$20+Setup!$B$21/Setup!$B$17,0),1) -> 292.66667
... A78: 59 | B78: =IF(A78<=$B$15,COUNTIF($M$5:$M$13,"<="&(A78-1)),0) -> 0 | C78: =IF(B78>0,INDEX($K$5:$K$13,B78),0) -> 0 | D78: =IF(B78>0,INDEX($L$5:$L$13,B78),0) -> 0 | F78: 58 | G78: =IF(F78<=$B$15,1,0) -> 0 | H78: =IF(G78=1,(D77+D78)/2,0) -> 0 | I78: =IF(F78<$B$15,C78,0) -> 0 | J78: =H78/Setup!$B$11 -> 0 | K78: =IF(G78=1,J78+I77+I78+IF(F78=0,1/Setup!$B$17,0)+IF(F78=$B$15,Setup!$B$20+Setup!$B$21/Setup!$B$17,0),1) -> 1
F79: 59 | G79: =IF(F79<=$B$15,1,0) -> 0 | H79: =IF(G79=1,(D78+0)/2,0) -> 0 | I79: =0 -> 0 | J79: =H79/Setup!$B$11 -> 0 | K79: =IF(G79=1,J79+I78+I79+IF(F79=0,1/Setup!$B$17,0)+IF(F79=$B$15,Setup!$B$20+Setup!$B$21/Setup!$B$17,0),1) -> 1
A84: C/dt as a row | B84: =J20 -> 7.2916667 | C84: =J21 -> 14.583333 | D84: =J22 -> 7.2916667 | E84: =J23 -> 33.333333 | F84: =J24 -> 66.666667 | G84: =J25 -> 66.666667 | H84: =J26 -> 66.666667 | I84: =J27 -> 66.666667 | J84: =J28 -> 66.666667 | K84: =J29 -> 66.666667 | L84: =J30 -> 66.666667 | M84: =J31 -> 66.666667 | N84: =J32 -> 66.666667 | O84: =J33 -> 33.848333 | P84: =J34 -> 1.03 | Q84: =J35 -> 1.03 | R84: =J36 -> 1.03 | S84: =J37 -> 1.03 | T84: =J38 -> 1.03 | U84: =J39 -> 1.03 | V84: =J40 -> 1.03 | W84: =J41 -> 1.03 | X84: =J42 -> 1.03 | Y84: =J43 -> 1.03 | Z84: =J44 -> 1.03 | AA84: =J45 -> 1.03 | AB84: =J46 -> 1.03 | AC84: =J47 -> 1.03 | AD84: =J48 -> 21.533182 | AE84: =J49 -> 42.036364 | AF84: =J50 -> 42.036364 | AG84: =J51 -> 42.036364 | AH84: =J52 -> 42.036364 | AI84: =J53 -> 42.036364 | AJ84: =J54 -> 42.036364 | AK84: =J55 -> 42.036364 | AL84: =J56 -> 42.036364 | AM84: =J57 -> 42.036364 | AN84: =J58 -> 42.036364 | AO84: =J59 -> 21.018182 | AP84: =J60 -> 0 | AQ84: =J61 -> 0 | AR84: =J62 -> 0 | AS84: =J63 -> 0 | AT84: =J64 -> 0 | AU84: =J65 -> 0 | AV84: =J66 -> 0 | AW84: =J67 -> 0 | AX84: =J68 -> 0 | AY84: =J69 -> 0 | AZ84: =J70 -> 0 | BA84: =J71 -> 0 | BB84: =J72 -> 0 | BC84: =J73 -> 0 | BD84: =J74 -> 0 | BE84: =J75 -> 0 | BF84: =J76 -> 0 | BG84: =J77 -> 0 | BH84: =J78 -> 0 | BI84: =J79 -> 0

Sheet 5N mesh
A1: Five-node lump: nodes
A2: Node 0 is the room-side node (class node 5). Ground floors add the same 1 m of soil as the fine mesh, in 20 cells of 50 mm.
A4: Rc m²K/W | B4: =SUM('FD mesh'!N5:N12) -> 4.6662012
A5: κ total J/m²K | B5: =SUMPRODUCT('FD mesh'!F5:F12,'FD mesh'!G5:G12,'FD mesh'!D5:D12) -> 352105
A6: Ground floor (1/0) | B6: =IF(Setup!$B$16="ground",1,0) -> 0
A7: Last node | B7: =IF(B6=1,24,4) -> 4
A9: Node k | B9: valid | C9: C node J/m²K | D9: g to next | E9: C/dt | F9: diagonal of A
A10: 0 | B10: =IF(A10<=$B$7,1,0) -> 1 | C10: =INDEX(Classes!$B$5:$F$9,MATCH(Setup!$B$19,Classes!$A$5:$A$9,0),5)*$B$5 -> 176052.5 | D10: =6/$B$4 -> 1.2858425 | E10: =C10/Setup!$B$11 -> 586.84167 | F10: =IF(B10=1,E10+0+D10+IF(A10=0,1/Setup!$B$17,0)+IF(A10=$B$7,Setup!$B$20+Setup!$B$21/Setup!$B$17,0),1) -> 595.81982
A11: 1 | B11: =IF(A11<=$B$7,1,0) -> 1 | C11: =INDEX(Classes!$B$5:$F$9,MATCH(Setup!$B$19,Classes!$A$5:$A$9,0),4)*$B$5 -> 0 | D11: =3/$B$4 -> 0.64292127 | E11: =C11/Setup!$B$11 -> 0 | F11: =IF(B11=1,E11+D10+D11+IF(A11=0,1/Setup!$B$17,0)+IF(A11=$B$7,Setup!$B$20+Setup!$B$21/Setup!$B$17,0),1) -> 1.9287638
A12: 2 | B12: =IF(A12<=$B$7,1,0) -> 1 | C12: =INDEX(Classes!$B$5:$F$9,MATCH(Setup!$B$19,Classes!$A$5:$A$9,0),3)*$B$5 -> 0 | D12: =3/$B$4 -> 0.64292127 | E12: =C12/Setup!$B$11 -> 0 | F12: =IF(B12=1,E12+D11+D12+IF(A12=0,1/Setup!$B$17,0)+IF(A12=$B$7,Setup!$B$20+Setup!$B$21/Setup!$B$17,0),1) -> 1.2858425
A13: 3 | B13: =IF(A13<=$B$7,1,0) -> 1 | C13: =INDEX(Classes!$B$5:$F$9,MATCH(Setup!$B$19,Classes!$A$5:$A$9,0),2)*$B$5 -> 0 | D13: =6/$B$4 -> 1.2858425 | E13: =C13/Setup!$B$11 -> 0 | F13: =IF(B13=1,E13+D12+D13+IF(A13=0,1/Setup!$B$17,0)+IF(A13=$B$7,Setup!$B$20+Setup!$B$21/Setup!$B$17,0),1) -> 1.9287638
A14: 4 | B14: =IF(A14<=$B$7,1,0) -> 1 | C14: =INDEX(Classes!$B$5:$F$9,MATCH(Setup!$B$19,Classes!$A$5:$A$9,0),1)*$B$5+$B$6*75000 -> 176052.5 | D14: =IF(A14<$B$7,30,0) -> 0 | E14: =C14/Setup!$B$11 -> 586.84167 | F14: =IF(B14=1,E14+D13+D14+IF(A14=0,1/Setup!$B$17,0)+IF(A14=$B$7,Setup!$B$20+Setup!$B$21/Setup!$B$17,0),1) -> 613.12751
A15: 5 | B15: =IF(A15<=$B$7,1,0) -> 0 | C15: =IF(B15=1,150000,0) -> 0 | D15: =IF(A15<$B$7,30,0) -> 0 | E15: =C15/Setup!$B$11 -> 0 | F15: =IF(B15=1,E15+D14+D15+IF(A15=0,1/Setup!$B$17,0)+IF(A15=$B$7,Setup!$B$20+Setup!$B$21/Setup!$B$17,0),1) -> 1
A16: 6 | B16: =IF(A16<=$B$7,1,0) -> 0 | C16: =IF(B16=1,150000,0) -> 0 | D16: =IF(A16<$B$7,30,0) -> 0 | E16: =C16/Setup!$B$11 -> 0 | F16: =IF(B16=1,E16+D15+D16+IF(A16=0,1/Setup!$B$17,0)+IF(A16=$B$7,Setup!$B$20+Setup!$B$21/Setup!$B$17,0),1) -> 1
A17: 7 | B17: =IF(A17<=$B$7,1,0) -> 0 | C17: =IF(B17=1,150000,0) -> 0 | D17: =IF(A17<$B$7,30,0) -> 0 | E17: =C17/Setup!$B$11 -> 0 | F17: =IF(B17=1,E17+D16+D17+IF(A17=0,1/Setup!$B$17,0)+IF(A17=$B$7,Setup!$B$20+Setup!$B$21/Setup!$B$17,0),1) -> 1
A18: 8 | B18: =IF(A18<=$B$7,1,0) -> 0 | C18: =IF(B18=1,150000,0) -> 0 | D18: =IF(A18<$B$7,30,0) -> 0 | E18: =C18/Setup!$B$11 -> 0 | F18: =IF(B18=1,E18+D17+D18+IF(A18=0,1/Setup!$B$17,0)+IF(A18=$B$7,Setup!$B$20+Setup!$B$21/Setup!$B$17,0),1) -> 1
A19: 9 | B19: =IF(A19<=$B$7,1,0) -> 0 | C19: =IF(B19=1,150000,0) -> 0 | D19: =IF(A19<$B$7,30,0) -> 0 | E19: =C19/Setup!$B$11 -> 0 | F19: =IF(B19=1,E19+D18+D19+IF(A19=0,1/Setup!$B$17,0)+IF(A19=$B$7,Setup!$B$20+Setup!$B$21/Setup!$B$17,0),1) -> 1
A20: 10 | B20: =IF(A20<=$B$7,1,0) -> 0 | C20: =IF(B20=1,150000,0) -> 0 | D20: =IF(A20<$B$7,30,0) -> 0 | E20: =C20/Setup!$B$11 -> 0 | F20: =IF(B20=1,E20+D19+D20+IF(A20=0,1/Setup!$B$17,0)+IF(A20=$B$7,Setup!$B$20+Setup!$B$21/Setup!$B$17,0),1) -> 1
A21: 11 | B21: =IF(A21<=$B$7,1,0) -> 0 | C21: =IF(B21=1,150000,0) -> 0 | D21: =IF(A21<$B$7,30,0) -> 0 | E21: =C21/Setup!$B$11 -> 0 | F21: =IF(B21=1,E21+D20+D21+IF(A21=0,1/Setup!$B$17,0)+IF(A21=$B$7,Setup!$B$20+Setup!$B$21/Setup!$B$17,0),1) -> 1
A22: 12 | B22: =IF(A22<=$B$7,1,0) -> 0 | C22: =IF(B22=1,150000,0) -> 0 | D22: =IF(A22<$B$7,30,0) -> 0 | E22: =C22/Setup!$B$11 -> 0 | F22: =IF(B22=1,E22+D21+D22+IF(A22=0,1/Setup!$B$17,0)+IF(A22=$B$7,Setup!$B$20+Setup!$B$21/Setup!$B$17,0),1) -> 1
A23: 13 | B23: =IF(A23<=$B$7,1,0) -> 0 | C23: =IF(B23=1,150000,0) -> 0 | D23: =IF(A23<$B$7,30,0) -> 0 | E23: =C23/Setup!$B$11 -> 0 | F23: =IF(B23=1,E23+D22+D23+IF(A23=0,1/Setup!$B$17,0)+IF(A23=$B$7,Setup!$B$20+Setup!$B$21/Setup!$B$17,0),1) -> 1
A24: 14 | B24: =IF(A24<=$B$7,1,0) -> 0 | C24: =IF(B24=1,150000,0) -> 0 | D24: =IF(A24<$B$7,30,0) -> 0 | E24: =C24/Setup!$B$11 -> 0 | F24: =IF(B24=1,E24+D23+D24+IF(A24=0,1/Setup!$B$17,0)+IF(A24=$B$7,Setup!$B$20+Setup!$B$21/Setup!$B$17,0),1) -> 1
A25: 15 | B25: =IF(A25<=$B$7,1,0) -> 0 | C25: =IF(B25=1,150000,0) -> 0 | D25: =IF(A25<$B$7,30,0) -> 0 | E25: =C25/Setup!$B$11 -> 0 | F25: =IF(B25=1,E25+D24+D25+IF(A25=0,1/Setup!$B$17,0)+IF(A25=$B$7,Setup!$B$20+Setup!$B$21/Setup!$B$17,0),1) -> 1
A26: 16 | B26: =IF(A26<=$B$7,1,0) -> 0 | C26: =IF(B26=1,150000,0) -> 0 | D26: =IF(A26<$B$7,30,0) -> 0 | E26: =C26/Setup!$B$11 -> 0 | F26: =IF(B26=1,E26+D25+D26+IF(A26=0,1/Setup!$B$17,0)+IF(A26=$B$7,Setup!$B$20+Setup!$B$21/Setup!$B$17,0),1) -> 1
... A33: 23 | B33: =IF(A33<=$B$7,1,0) -> 0 | C33: =IF(B33=1,150000,0) -> 0 | D33: =IF(A33<$B$7,30,0) -> 0 | E33: =C33/Setup!$B$11 -> 0 | F33: =IF(B33=1,E33+D32+D33+IF(A33=0,1/Setup!$B$17,0)+IF(A33=$B$7,Setup!$B$20+Setup!$B$21/Setup!$B$17,0),1) -> 1
A34: 24 | B34: =IF(A34<=$B$7,1,0) -> 0 | C34: =IF(B34=1,75000,0) -> 0 | D34: =0 -> 0 | E34: =C34/Setup!$B$11 -> 0 | F34: =IF(B34=1,E34+D33+D34+IF(A34=0,1/Setup!$B$17,0)+IF(A34=$B$7,Setup!$B$20+Setup!$B$21/Setup!$B$17,0),1) -> 1
A37: C/dt as a row | B37: =E10 -> 586.84167 | C37: =E11 -> 0 | D37: =E12 -> 0 | E37: =E13 -> 0 | F37: =E14 -> 586.84167 | G37: =E15 -> 0 | H37: =E16 -> 0 | I37: =E17 -> 0 | J37: =E18 -> 0 | K37: =E19 -> 0 | L37: =E20 -> 0 | M37: =E21 -> 0 | N37: =E22 -> 0 | O37: =E23 -> 0 | P37: =E24 -> 0 | Q37: =E25 -> 0 | R37: =E26 -> 0 | S37: =E27 -> 0 | T37: =E28 -> 0 | U37: =E29 -> 0 | V37: =E30 -> 0 | W37: =E31 -> 0 | X37: =E32 -> 0 | Y37: =E33 -> 0 | Z37: =E34 -> 0

Sheet FD A
A1: FD: system matrix A = C/dt + G (with boundary conductances)
A3: ='FD mesh'!K20 -> 48.583974 | B3: =IF('FD mesh'!G21=1,-'FD mesh'!I20,0) -> -33.6 | C3: 0 | D3: 0 | E3: 0 | F3: 0 | G3: 0 | H3: 0 | I3: 0 | J3: 0 | K3: 0 | L3: 0 | M3: 0 | N3: 0 | O3: 0 | P3: 0 | Q3: 0 | R3: 0 | S3: 0 | T3: 0 | U3: 0 | V3: 0 | W3: 0 | X3: 0 | Y3: 0 | Z3: 0 | AA3: 0 | AB3: 0 | AC3: 0 | AD3: 0 | AE3: 0 | AF3: 0 | AG3: 0 | AH3: 0 | AI3: 0 | AJ3: 0 | AK3: 0 | AL3: 0 | AM3: 0 | AN3: 0 | AO3: 0 | AP3: 0 | AQ3: 0 | AR3: 0 | AS3: 0 | AT3: 0 | AU3: 0 | AV3: 0 | AW3: 0 | AX3: 0 | AY3: 0 | AZ3: 0 | BA3: 0 | BB3: 0 | BC3: 0 | BD3: 0 | BE3: 0 | BF3: 0 | BG3: 0 | BH3: 0
A4: =IF('FD mesh'!G21=1,-'FD mesh'!I20,0) -> -33.6 | B4: ='FD mesh'!K21 -> 81.783333 | C4: =IF('FD mesh'!G22=1,-'FD mesh'!I21,0) -> -33.6 | D4: 0 | E4: 0 | F4: 0 | G4: 0 | H4: 0 | I4: 0 | J4: 0 | K4: 0 | L4: 0 | M4: 0 | N4: 0 | O4: 0 | P4: 0 | Q4: 0 | R4: 0 | S4: 0 | T4: 0 | U4: 0 | V4: 0 | W4: 0 | X4: 0 | Y4: 0 | Z4: 0 | AA4: 0 | AB4: 0 | AC4: 0 | AD4: 0 | AE4: 0 | AF4: 0 | AG4: 0 | AH4: 0 | AI4: 0 | AJ4: 0 | AK4: 0 | AL4: 0 | AM4: 0 | AN4: 0 | AO4: 0 | AP4: 0 | AQ4: 0 | AR4: 0 | AS4: 0 | AT4: 0 | AU4: 0 | AV4: 0 | AW4: 0 | AX4: 0 | AY4: 0 | AZ4: 0 | BA4: 0 | BB4: 0 | BC4: 0 | BD4: 0 | BE4: 0 | BF4: 0 | BG4: 0 | BH4: 0
A5: 0 | B5: =IF('FD mesh'!G22=1,-'FD mesh'!I21,0) -> -33.6 | C5: ='FD mesh'!K22 -> 50.891667 | D5: =IF('FD mesh'!G23=1,-'FD mesh'!I22,0) -> -10 | E5: 0 | F5: 0 | G5: 0 | H5: 0 | I5: 0 | J5: 0 | K5: 0 | L5: 0 | M5: 0 | N5: 0 | O5: 0 | P5: 0 | Q5: 0 | R5: 0 | S5: 0 | T5: 0 | U5: 0 | V5: 0 | W5: 0 | X5: 0 | Y5: 0 | Z5: 0 | AA5: 0 | AB5: 0 | AC5: 0 | AD5: 0 | AE5: 0 | AF5: 0 | AG5: 0 | AH5: 0 | AI5: 0 | AJ5: 0 | AK5: 0 | AL5: 0 | AM5: 0 | AN5: 0 | AO5: 0 | AP5: 0 | AQ5: 0 | AR5: 0 | AS5: 0 | AT5: 0 | AU5: 0 | AV5: 0 | AW5: 0 | AX5: 0 | AY5: 0 | AZ5: 0 | BA5: 0 | BB5: 0 | BC5: 0 | BD5: 0 | BE5: 0 | BF5: 0 | BG5: 0 | BH5: 0
A6: 0 | B6: 0 | C6: =IF('FD mesh'!G23=1,-'FD mesh'!I22,0) -> -10 | D6: ='FD mesh'!K23 -> 156.33333 | E6: =IF('FD mesh'!G24=1,-'FD mesh'!I23,0) -> -113 | F6: 0 | G6: 0 | H6: 0 | I6: 0 | J6: 0 | K6: 0 | L6: 0 | M6: 0 | N6: 0 | O6: 0 | P6: 0 | Q6: 0 | R6: 0 | S6: 0 | T6: 0 | U6: 0 | V6: 0 | W6: 0 | X6: 0 | Y6: 0 | Z6: 0 | AA6: 0 | AB6: 0 | AC6: 0 | AD6: 0 | AE6: 0 | AF6: 0 | AG6: 0 | AH6: 0 | AI6: 0 | AJ6: 0 | AK6: 0 | AL6: 0 | AM6: 0 | AN6: 0 | AO6: 0 | AP6: 0 | AQ6: 0 | AR6: 0 | AS6: 0 | AT6: 0 | AU6: 0 | AV6: 0 | AW6: 0 | AX6: 0 | AY6: 0 | AZ6: 0 | BA6: 0 | BB6: 0 | BC6: 0 | BD6: 0 | BE6: 0 | BF6: 0 | BG6: 0 | BH6: 0
A7: 0 | B7: 0 | C7: 0 | D7: =IF('FD mesh'!G24=1,-'FD mesh'!I23,0) -> -113 | E7: ='FD mesh'!K24 -> 292.66667 | F7: =IF('FD mesh'!G25=1,-'FD mesh'!I24,0) -> -113 | G7: 0 | H7: 0 | I7: 0 | J7: 0 | K7: 0 | L7: 0 | M7: 0 | N7: 0 | O7: 0 | P7: 0 | Q7: 0 | R7: 0 | S7: 0 | T7: 0 | U7: 0 | V7: 0 | W7: 0 | X7: 0 | Y7: 0 | Z7: 0 | AA7: 0 | AB7: 0 | AC7: 0 | AD7: 0 | AE7: 0 | AF7: 0 | AG7: 0 | AH7: 0 | AI7: 0 | AJ7: 0 | AK7: 0 | AL7: 0 | AM7: 0 | AN7: 0 | AO7: 0 | AP7: 0 | AQ7: 0 | AR7: 0 | AS7: 0 | AT7: 0 | AU7: 0 | AV7: 0 | AW7: 0 | AX7: 0 | AY7: 0 | AZ7: 0 | BA7: 0 | BB7: 0 | BC7: 0 | BD7: 0 | BE7: 0 | BF7: 0 | BG7: 0 | BH7: 0
A8: 0 | B8: 0 | C8: 0 | D8: 0 | E8: =IF('FD mesh'!G25=1,-'FD mesh'!I24,0) -> -113 | F8: ='FD mesh'!K25 -> 292.66667 | G8: =IF('FD mesh'!G26=1,-'FD mesh'!I25,0) -> -113 | H8: 0 | I8: 0 | J8: 0 | K8: 0 | L8: 0 | M8: 0 | N8: 0 | O8: 0 | P8: 0 | Q8: 0 | R8: 0 | S8: 0 | T8: 0 | U8: 0 | V8: 0 | W8: 0 | X8: 0 | Y8: 0 | Z8: 0 | AA8: 0 | AB8: 0 | AC8: 0 | AD8: 0 | AE8: 0 | AF8: 0 | AG8: 0 | AH8: 0 | AI8: 0 | AJ8: 0 | AK8: 0 | AL8: 0 | AM8: 0 | AN8: 0 | AO8: 0 | AP8: 0 | AQ8: 0 | AR8: 0 | AS8: 0 | AT8: 0 | AU8: 0 | AV8: 0 | AW8: 0 | AX8: 0 | AY8: 0 | AZ8: 0 | BA8: 0 | BB8: 0 | BC8: 0 | BD8: 0 | BE8: 0 | BF8: 0 | BG8: 0 | BH8: 0
A9: 0 | B9: 0 | C9: 0 | D9: 0 | E9: 0 | F9: =IF('FD mesh'!G26=1,-'FD mesh'!I25,0) -> -113 | G9: ='FD mesh'!K26 -> 292.66667 | H9: =IF('FD mesh'!G27=1,-'FD mesh'!I26,0) -> -113 | I9: 0 | J9: 0 | K9: 0 | L9: 0 | M9: 0 | N9: 0 | O9: 0 | P9: 0 | Q9: 0 | R9: 0 | S9: 0 | T9: 0 | U9: 0 | V9: 0 | W9: 0 | X9: 0 | Y9: 0 | Z9: 0 | AA9: 0 | AB9: 0 | AC9: 0 | AD9: 0 | AE9: 0 | AF9: 0 | AG9: 0 | AH9: 0 | AI9: 0 | AJ9: 0 | AK9: 0 | AL9: 0 | AM9: 0 | AN9: 0 | AO9: 0 | AP9: 0 | AQ9: 0 | AR9: 0 | AS9: 0 | AT9: 0 | AU9: 0 | AV9: 0 | AW9: 0 | AX9: 0 | AY9: 0 | AZ9: 0 | BA9: 0 | BB9: 0 | BC9: 0 | BD9: 0 | BE9: 0 | BF9: 0 | BG9: 0 | BH9: 0
A10: 0 | B10: 0 | C10: 0 | D10: 0 | E10: 0 | F10: 0 | G10: =IF('FD mesh'!G27=1,-'FD mesh'!I26,0) -> -113 | H10: ='FD mesh'!K27 -> 292.66667 | I10: =IF('FD mesh'!G28=1,-'FD mesh'!I27,0) -> -113 | J10: 0 | K10: 0 | L10: 0 | M10: 0 | N10: 0 | O10: 0 | P10: 0 | Q10: 0 | R10: 0 | S10: 0 | T10: 0 | U10: 0 | V10: 0 | W10: 0 | X10: 0 | Y10: 0 | Z10: 0 | AA10: 0 | AB10: 0 | AC10: 0 | AD10: 0 | AE10: 0 | AF10: 0 | AG10: 0 | AH10: 0 | AI10: 0 | AJ10: 0 | AK10: 0 | AL10: 0 | AM10: 0 | AN10: 0 | AO10: 0 | AP10: 0 | AQ10: 0 | AR10: 0 | AS10: 0 | AT10: 0 | AU10: 0 | AV10: 0 | AW10: 0 | AX10: 0 | AY10: 0 | AZ10: 0 | BA10: 0 | BB10: 0 | BC10: 0 | BD10: 0 | BE10: 0 | BF10: 0 | BG10: 0 | BH10: 0
A11: 0 | B11: 0 | C11: 0 | D11: 0 | E11: 0 | F11: 0 | G11: 0 | H11: =IF('FD mesh'!G28=1,-'FD mesh'!I27,0) -> -113 | I11: ='FD mesh'!K28 -> 292.66667 | J11: =IF('FD mesh'!G29=1,-'FD mesh'!I28,0) -> -113 | K11: 0 | L11: 0 | M11: 0 | N11: 0 | O11: 0 | P11: 0 | Q11: 0 | R11: 0 | S11: 0 | T11: 0 | U11: 0 | V11: 0 | W11: 0 | X11: 0 | Y11: 0 | Z11: 0 | AA11: 0 | AB11: 0 | AC11: 0 | AD11: 0 | AE11: 0 | AF11: 0 | AG11: 0 | AH11: 0 | AI11: 0 | AJ11: 0 | AK11: 0 | AL11: 0 | AM11: 0 | AN11: 0 | AO11: 0 | AP11: 0 | AQ11: 0 | AR11: 0 | AS11: 0 | AT11: 0 | AU11: 0 | AV11: 0 | AW11: 0 | AX11: 0 | AY11: 0 | AZ11: 0 | BA11: 0 | BB11: 0 | BC11: 0 | BD11: 0 | BE11: 0 | BF11: 0 | BG11: 0 | BH11: 0
A12: 0 | B12: 0 | C12: 0 | D12: 0 | E12: 0 | F12: 0 | G12: 0 | H12: 0 | I12: =IF('FD mesh'!G29=1,-'FD mesh'!I28,0) -> -113 | J12: ='FD mesh'!K29 -> 292.66667 | K12: =IF('FD mesh'!G30=1,-'FD mesh'!I29,0) -> -113 | L12: 0 | M12: 0 | N12: 0 | O12: 0 | P12: 0 | Q12: 0 | R12: 0 | S12: 0 | T12: 0 | U12: 0 | V12: 0 | W12: 0 | X12: 0 | Y12: 0 | Z12: 0 | AA12: 0 | AB12: 0 | AC12: 0 | AD12: 0 | AE12: 0 | AF12: 0 | AG12: 0 | AH12: 0 | AI12: 0 | AJ12: 0 | AK12: 0 | AL12: 0 | AM12: 0 | AN12: 0 | AO12: 0 | AP12: 0 | AQ12: 0 | AR12: 0 | AS12: 0 | AT12: 0 | AU12: 0 | AV12: 0 | AW12: 0 | AX12: 0 | AY12: 0 | AZ12: 0 | BA12: 0 | BB12: 0 | BC12: 0 | BD12: 0 | BE12: 0 | BF12: 0 | BG12: 0 | BH12: 0
A13: 0 | B13: 0 | C13: 0 | D13: 0 | E13: 0 | F13: 0 | G13: 0 | H13: 0 | I13: 0 | J13: =IF('FD mesh'!G30=1,-'FD mesh'!I29,0) -> -113 | K13: ='FD mesh'!K30 -> 292.66667 | L13: =IF('FD mesh'!G31=1,-'FD mesh'!I30,0) -> -113 | M13: 0 | N13: 0 | O13: 0 | P13: 0 | Q13: 0 | R13: 0 | S13: 0 | T13: 0 | U13: 0 | V13: 0 | W13: 0 | X13: 0 | Y13: 0 | Z13: 0 | AA13: 0 | AB13: 0 | AC13: 0 | AD13: 0 | AE13: 0 | AF13: 0 | AG13: 0 | AH13: 0 | AI13: 0 | AJ13: 0 | AK13: 0 | AL13: 0 | AM13: 0 | AN13: 0 | AO13: 0 | AP13: 0 | AQ13: 0 | AR13: 0 | AS13: 0 | AT13: 0 | AU13: 0 | AV13: 0 | AW13: 0 | AX13: 0 | AY13: 0 | AZ13: 0 | BA13: 0 | BB13: 0 | BC13: 0 | BD13: 0 | BE13: 0 | BF13: 0 | BG13: 0 | BH13: 0
A14: 0 | B14: 0 | C14: 0 | D14: 0 | E14: 0 | F14: 0 | G14: 0 | H14: 0 | I14: 0 | J14: 0 | K14: =IF('FD mesh'!G31=1,-'FD mesh'!I30,0) -> -113 | L14: ='FD mesh'!K31 -> 292.66667 | M14: =IF('FD mesh'!G32=1,-'FD mesh'!I31,0) -> -113 | N14: 0 | O14: 0 | P14: 0 | Q14: 0 | R14: 0 | S14: 0 | T14: 0 | U14: 0 | V14: 0 | W14: 0 | X14: 0 | Y14: 0 | Z14: 0 | AA14: 0 | AB14: 0 | AC14: 0 | AD14: 0 | AE14: 0 | AF14: 0 | AG14: 0 | AH14: 0 | AI14: 0 | AJ14: 0 | AK14: 0 | AL14: 0 | AM14: 0 | AN14: 0 | AO14: 0 | AP14: 0 | AQ14: 0 | AR14: 0 | AS14: 0 | AT14: 0 | AU14: 0 | AV14: 0 | AW14: 0 | AX14: 0 | AY14: 0 | AZ14: 0 | BA14: 0 | BB14: 0 | BC14: 0 | BD14: 0 | BE14: 0 | BF14: 0 | BG14: 0 | BH14: 0
A15: 0 | B15: 0 | C15: 0 | D15: 0 | E15: 0 | F15: 0 | G15: 0 | H15: 0 | I15: 0 | J15: 0 | K15: 0 | L15: =IF('FD mesh'!G32=1,-'FD mesh'!I31,0) -> -113 | M15: ='FD mesh'!K32 -> 292.66667 | N15: =IF('FD mesh'!G33=1,-'FD mesh'!I32,0) -> -113 | O15: 0 | P15: 0 | Q15: 0 | R15: 0 | S15: 0 | T15: 0 | U15: 0 | V15: 0 | W15: 0 | X15: 0 | Y15: 0 | Z15: 0 | AA15: 0 | AB15: 0 | AC15: 0 | AD15: 0 | AE15: 0 | AF15: 0 | AG15: 0 | AH15: 0 | AI15: 0 | AJ15: 0 | AK15: 0 | AL15: 0 | AM15: 0 | AN15: 0 | AO15: 0 | AP15: 0 | AQ15: 0 | AR15: 0 | AS15: 0 | AT15: 0 | AU15: 0 | AV15: 0 | AW15: 0 | AX15: 0 | AY15: 0 | AZ15: 0 | BA15: 0 | BB15: 0 | BC15: 0 | BD15: 0 | BE15: 0 | BF15: 0 | BG15: 0 | BH15: 0
A16: 0 | B16: 0 | C16: 0 | D16: 0 | E16: 0 | F16: 0 | G16: 0 | H16: 0 | I16: 0 | J16: 0 | K16: 0 | L16: 0 | M16: =IF('FD mesh'!G33=1,-'FD mesh'!I32,0) -> -113 | N16: ='FD mesh'!K33 -> 150.34833 | O16: =IF('FD mesh'!G34=1,-'FD mesh'!I33,0) -> -3.5 | P16: 0 | Q16: 0 | R16: 0 | S16: 0 | T16: 0 | U16: 0 | V16: 0 | W16: 0 | X16: 0 | Y16: 0 | Z16: 0 | AA16: 0 | AB16: 0 | AC16: 0 | AD16: 0 | AE16: 0 | AF16: 0 | AG16: 0 | AH16: 0 | AI16: 0 | AJ16: 0 | AK16: 0 | AL16: 0 | AM16: 0 | AN16: 0 | AO16: 0 | AP16: 0 | AQ16: 0 | AR16: 0 | AS16: 0 | AT16: 0 | AU16: 0 | AV16: 0 | AW16: 0 | AX16: 0 | AY16: 0 | AZ16: 0 | BA16: 0 | BB16: 0 | BC16: 0 | BD16: 0 | BE16: 0 | BF16: 0 | BG16: 0 | BH16: 0
A17: 0 | B17: 0 | C17: 0 | D17: 0 | E17: 0 | F17: 0 | G17: 0 | H17: 0 | I17: 0 | J17: 0 | K17: 0 | L17: 0 | M17: 0 | N17: =IF('FD mesh'!G34=1,-'FD mesh'!I33,0) -> -3.5 | O17: ='FD mesh'!K34 -> 8.03 | P17: =IF('FD mesh'!G35=1,-'FD mesh'!I34,0) -> -3.5 | Q17: 0 | R17: 0 | S17: 0 | T17: 0 | U17: 0 | V17: 0 | W17: 0 | X17: 0 | Y17: 0 | Z17: 0 | AA17: 0 | AB17: 0 | AC17: 0 | AD17: 0 | AE17: 0 | AF17: 0 | AG17: 0 | AH17: 0 | AI17: 0 | AJ17: 0 | AK17: 0 | AL17: 0 | AM17: 0 | AN17: 0 | AO17: 0 | AP17: 0 | AQ17: 0 | AR17: 0 | AS17: 0 | AT17: 0 | AU17: 0 | AV17: 0 | AW17: 0 | AX17: 0 | AY17: 0 | AZ17: 0 | BA17: 0 | BB17: 0 | BC17: 0 | BD17: 0 | BE17: 0 | BF17: 0 | BG17: 0 | BH17: 0
A18: 0 | B18: 0 | C18: 0 | D18: 0 | E18: 0 | F18: 0 | G18: 0 | H18: 0 | I18: 0 | J18: 0 | K18: 0 | L18: 0 | M18: 0 | N18: 0 | O18: =IF('FD mesh'!G35=1,-'FD mesh'!I34,0) -> -3.5 | P18: ='FD mesh'!K35 -> 8.03 | Q18: =IF('FD mesh'!G36=1,-'FD mesh'!I35,0) -> -3.5 | R18: 0 | S18: 0 | T18: 0 | U18: 0 | V18: 0 | W18: 0 | X18: 0 | Y18: 0 | Z18: 0 | AA18: 0 | AB18: 0 | AC18: 0 | AD18: 0 | AE18: 0 | AF18: 0 | AG18: 0 | AH18: 0 | AI18: 0 | AJ18: 0 | AK18: 0 | AL18: 0 | AM18: 0 | AN18: 0 | AO18: 0 | AP18: 0 | AQ18: 0 | AR18: 0 | AS18: 0 | AT18: 0 | AU18: 0 | AV18: 0 | AW18: 0 | AX18: 0 | AY18: 0 | AZ18: 0 | BA18: 0 | BB18: 0 | BC18: 0 | BD18: 0 | BE18: 0 | BF18: 0 | BG18: 0 | BH18: 0
A19: 0 | B19: 0 | C19: 0 | D19: 0 | E19: 0 | F19: 0 | G19: 0 | H19: 0 | I19: 0 | J19: 0 | K19: 0 | L19: 0 | M19: 0 | N19: 0 | O19: 0 | P19: =IF('FD mesh'!G36=1,-'FD mesh'!I35,0) -> -3.5 | Q19: ='FD mesh'!K36 -> 8.03 | R19: =IF('FD mesh'!G37=1,-'FD mesh'!I36,0) -> -3.5 | S19: 0 | T19: 0 | U19: 0 | V19: 0 | W19: 0 | X19: 0 | Y19: 0 | Z19: 0 | AA19: 0 | AB19: 0 | AC19: 0 | AD19: 0 | AE19: 0 | AF19: 0 | AG19: 0 | AH19: 0 | AI19: 0 | AJ19: 0 | AK19: 0 | AL19: 0 | AM19: 0 | AN19: 0 | AO19: 0 | AP19: 0 | AQ19: 0 | AR19: 0 | AS19: 0 | AT19: 0 | AU19: 0 | AV19: 0 | AW19: 0 | AX19: 0 | AY19: 0 | AZ19: 0 | BA19: 0 | BB19: 0 | BC19: 0 | BD19: 0 | BE19: 0 | BF19: 0 | BG19: 0 | BH19: 0
A20: 0 | B20: 0 | C20: 0 | D20: 0 | E20: 0 | F20: 0 | G20: 0 | H20: 0 | I20: 0 | J20: 0 | K20: 0 | L20: 0 | M20: 0 | N20: 0 | O20: 0 | P20: 0 | Q20: =IF('FD mesh'!G37=1,-'FD mesh'!I36,0) -> -3.5 | R20: ='FD mesh'!K37 -> 8.03 | S20: =IF('FD mesh'!G38=1,-'FD mesh'!I37,0) -> -3.5 | T20: 0 | U20: 0 | V20: 0 | W20: 0 | X20: 0 | Y20: 0 | Z20: 0 | AA20: 0 | AB20: 0 | AC20: 0 | AD20: 0 | AE20: 0 | AF20: 0 | AG20: 0 | AH20: 0 | AI20: 0 | AJ20: 0 | AK20: 0 | AL20: 0 | AM20: 0 | AN20: 0 | AO20: 0 | AP20: 0 | AQ20: 0 | AR20: 0 | AS20: 0 | AT20: 0 | AU20: 0 | AV20: 0 | AW20: 0 | AX20: 0 | AY20: 0 | AZ20: 0 | BA20: 0 | BB20: 0 | BC20: 0 | BD20: 0 | BE20: 0 | BF20: 0 | BG20: 0 | BH20: 0
A21: 0 | B21: 0 | C21: 0 | D21: 0 | E21: 0 | F21: 0 | G21: 0 | H21: 0 | I21: 0 | J21: 0 | K21: 0 | L21: 0 | M21: 0 | N21: 0 | O21: 0 | P21: 0 | Q21: 0 | R21: =IF('FD mesh'!G38=1,-'FD mesh'!I37,0) -> -3.5 | S21: ='FD mesh'!K38 -> 8.03 | T21: =IF('FD mesh'!G39=1,-'FD mesh'!I38,0) -> -3.5 | U21: 0 | V21: 0 | W21: 0 | X21: 0 | Y21: 0 | Z21: 0 | AA21: 0 | AB21: 0 | AC21: 0 | AD21: 0 | AE21: 0 | AF21: 0 | AG21: 0 | AH21: 0 | AI21: 0 | AJ21: 0 | AK21: 0 | AL21: 0 | AM21: 0 | AN21: 0 | AO21: 0 | AP21: 0 | AQ21: 0 | AR21: 0 | AS21: 0 | AT21: 0 | AU21: 0 | AV21: 0 | AW21: 0 | AX21: 0 | AY21: 0 | AZ21: 0 | BA21: 0 | BB21: 0 | BC21: 0 | BD21: 0 | BE21: 0 | BF21: 0 | BG21: 0 | BH21: 0
A22: 0 | B22: 0 | C22: 0 | D22: 0 | E22: 0 | F22: 0 | G22: 0 | H22: 0 | I22: 0 | J22: 0 | K22: 0 | L22: 0 | M22: 0 | N22: 0 | O22: 0 | P22: 0 | Q22: 0 | R22: 0 | S22: =IF('FD mesh'!G39=1,-'FD mesh'!I38,0) -> -3.5 | T22: ='FD mesh'!K39 -> 8.03 | U22: =IF('FD mesh'!G40=1,-'FD mesh'!I39,0) -> -3.5 | V22: 0 | W22: 0 | X22: 0 | Y22: 0 | Z22: 0 | AA22: 0 | AB22: 0 | AC22: 0 | AD22: 0 | AE22: 0 | AF22: 0 | AG22: 0 | AH22: 0 | AI22: 0 | AJ22: 0 | AK22: 0 | AL22: 0 | AM22: 0 | AN22: 0 | AO22: 0 | AP22: 0 | AQ22: 0 | AR22: 0 | AS22: 0 | AT22: 0 | AU22: 0 | AV22: 0 | AW22: 0 | AX22: 0 | AY22: 0 | AZ22: 0 | BA22: 0 | BB22: 0 | BC22: 0 | BD22: 0 | BE22: 0 | BF22: 0 | BG22: 0 | BH22: 0
A23: 0 | B23: 0 | C23: 0 | D23: 0 | E23: 0 | F23: 0 | G23: 0 | H23: 0 | I23: 0 | J23: 0 | K23: 0 | L23: 0 | M23: 0 | N23: 0 | O23: 0 | P23: 0 | Q23: 0 | R23: 0 | S23: 0 | T23: =IF('FD mesh'!G40=1,-'FD mesh'!I39,0) -> -3.5 | U23: ='FD mesh'!K40 -> 8.03 | V23: =IF('FD mesh'!G41=1,-'FD mesh'!I40,0) -> -3.5 | W23: 0 | X23: 0 | Y23: 0 | Z23: 0 | AA23: 0 | AB23: 0 | AC23: 0 | AD23: 0 | AE23: 0 | AF23: 0 | AG23: 0 | AH23: 0 | AI23: 0 | AJ23: 0 | AK23: 0 | AL23: 0 | AM23: 0 | AN23: 0 | AO23: 0 | AP23: 0 | AQ23: 0 | AR23: 0 | AS23: 0 | AT23: 0 | AU23: 0 | AV23: 0 | AW23: 0 | AX23: 0 | AY23: 0 | AZ23: 0 | BA23: 0 | BB23: 0 | BC23: 0 | BD23: 0 | BE23: 0 | BF23: 0 | BG23: 0 | BH23: 0
A24: 0 | B24: 0 | C24: 0 | D24: 0 | E24: 0 | F24: 0 | G24: 0 | H24: 0 | I24: 0 | J24: 0 | K24: 0 | L24: 0 | M24: 0 | N24: 0 | O24: 0 | P24: 0 | Q24: 0 | R24: 0 | S24: 0 | T24: 0 | U24: =IF('FD mesh'!G41=1,-'FD mesh'!I40,0) -> -3.5 | V24: ='FD mesh'!K41 -> 8.03 | W24: =IF('FD mesh'!G42=1,-'FD mesh'!I41,0) -> -3.5 | X24: 0 | Y24: 0 | Z24: 0 | AA24: 0 | AB24: 0 | AC24: 0 | AD24: 0 | AE24: 0 | AF24: 0 | AG24: 0 | AH24: 0 | AI24: 0 | AJ24: 0 | AK24: 0 | AL24: 0 | AM24: 0 | AN24: 0 | AO24: 0 | AP24: 0 | AQ24: 0 | AR24: 0 | AS24: 0 | AT24: 0 | AU24: 0 | AV24: 0 | AW24: 0 | AX24: 0 | AY24: 0 | AZ24: 0 | BA24: 0 | BB24: 0 | BC24: 0 | BD24: 0 | BE24: 0 | BF24: 0 | BG24: 0 | BH24: 0
A25: 0 | B25: 0 | C25: 0 | D25: 0 | E25: 0 | F25: 0 | G25: 0 | H25: 0 | I25: 0 | J25: 0 | K25: 0 | L25: 0 | M25: 0 | N25: 0 | O25: 0 | P25: 0 | Q25: 0 | R25: 0 | S25: 0 | T25: 0 | U25: 0 | V25: =IF('FD mesh'!G42=1,-'FD mesh'!I41,0) -> -3.5 | W25: ='FD mesh'!K42 -> 8.03 | X25: =IF('FD mesh'!G43=1,-'FD mesh'!I42,0) -> -3.5 | Y25: 0 | Z25: 0 | AA25: 0 | AB25: 0 | AC25: 0 | AD25: 0 | AE25: 0 | AF25: 0 | AG25: 0 | AH25: 0 | AI25: 0 | AJ25: 0 | AK25: 0 | AL25: 0 | AM25: 0 | AN25: 0 | AO25: 0 | AP25: 0 | AQ25: 0 | AR25: 0 | AS25: 0 | AT25: 0 | AU25: 0 | AV25: 0 | AW25: 0 | AX25: 0 | AY25: 0 | AZ25: 0 | BA25: 0 | BB25: 0 | BC25: 0 | BD25: 0 | BE25: 0 | BF25: 0 | BG25: 0 | BH25: 0
A26: 0 | B26: 0 | C26: 0 | D26: 0 | E26: 0 | F26: 0 | G26: 0 | H26: 0 | I26: 0 | J26: 0 | K26: 0 | L26: 0 | M26: 0 | N26: 0 | O26: 0 | P26: 0 | Q26: 0 | R26: 0 | S26: 0 | T26: 0 | U26: 0 | V26: 0 | W26: =IF('FD mesh'!G43=1,-'FD mesh'!I42,0) -> -3.5 | X26: ='FD mesh'!K43 -> 8.03 | Y26: =IF('FD mesh'!G44=1,-'FD mesh'!I43,0) -> -3.5 | Z26: 0 | AA26: 0 | AB26: 0 | AC26: 0 | AD26: 0 | AE26: 0 | AF26: 0 | AG26: 0 | AH26: 0 | AI26: 0 | AJ26: 0 | AK26: 0 | AL26: 0 | AM26: 0 | AN26: 0 | AO26: 0 | AP26: 0 | AQ26: 0 | AR26: 0 | AS26: 0 | AT26: 0 | AU26: 0 | AV26: 0 | AW26: 0 | AX26: 0 | AY26: 0 | AZ26: 0 | BA26: 0 | BB26: 0 | BC26: 0 | BD26: 0 | BE26: 0 | BF26: 0 | BG26: 0 | BH26: 0
A27: 0 | B27: 0 | C27: 0 | D27: 0 | E27: 0 | F27: 0 | G27: 0 | H27: 0 | I27: 0 | J27: 0 | K27: 0 | L27: 0 | M27: 0 | N27: 0 | O27: 0 | P27: 0 | Q27: 0 | R27: 0 | S27: 0 | T27: 0 | U27: 0 | V27: 0 | W27: 0 | X27: =IF('FD mesh'!G44=1,-'FD mesh'!I43,0) -> -3.5 | Y27: ='FD mesh'!K44 -> 8.03 | Z27: =IF('FD mesh'!G45=1,-'FD mesh'!I44,0) -> -3.5 | AA27: 0 | AB27: 0 | AC27: 0 | AD27: 0 | AE27: 0 | AF27: 0 | AG27: 0 | AH27: 0 | AI27: 0 | AJ27: 0 | AK27: 0 | AL27: 0 | AM27: 0 | AN27: 0 | AO27: 0 | AP27: 0 | AQ27: 0 | AR27: 0 | AS27: 0 | AT27: 0 | AU27: 0 | AV27: 0 | AW27: 0 | AX27: 0 | AY27: 0 | AZ27: 0 | BA27: 0 | BB27: 0 | BC27: 0 | BD27: 0 | BE27: 0 | BF27: 0 | BG27: 0 | BH27: 0
A28: 0 | B28: 0 | C28: 0 | D28: 0 | E28: 0 | F28: 0 | G28: 0 | H28: 0 | I28: 0 | J28: 0 | K28: 0 | L28: 0 | M28: 0 | N28: 0 | O28: 0 | P28: 0 | Q28: 0 | R28: 0 | S28: 0 | T28: 0 | U28: 0 | V28: 0 | W28: 0 | X28: 0 | Y28: =IF('FD mesh'!G45=1,-'FD mesh'!I44,0) -> -3.5 | Z28: ='FD mesh'!K45 -> 8.03 | AA28: =IF('FD mesh'!G46=1,-'FD mesh'!I45,0) -> -3.5 | AB28: 0 | AC28: 0 | AD28: 0 | AE28: 0 | AF28: 0 | AG28: 0 | AH28: 0 | AI28: 0 | AJ28: 0 | AK28: 0 | AL28: 0 | AM28: 0 | AN28: 0 | AO28: 0 | AP28: 0 | AQ28: 0 | AR28: 0 | AS28: 0 | AT28: 0 | AU28: 0 | AV28: 0 | AW28: 0 | AX28: 0 | AY28: 0 | AZ28: 0 | BA28: 0 | BB28: 0 | BC28: 0 | BD28: 0 | BE28: 0 | BF28: 0 | BG28: 0 | BH28: 0
A29: 0 | B29: 0 | C29: 0 | D29: 0 | E29: 0 | F29: 0 | G29: 0 | H29: 0 | I29: 0 | J29: 0 | K29: 0 | L29: 0 | M29: 0 | N29: 0 | O29: 0 | P29: 0 | Q29: 0 | R29: 0 | S29: 0 | T29: 0 | U29: 0 | V29: 0 | W29: 0 | X29: 0 | Y29: 0 | Z29: =IF('FD mesh'!G46=1,-'FD mesh'!I45,0) -> -3.5 | AA29: ='FD mesh'!K46 -> 8.03 | AB29: =IF('FD mesh'!G47=1,-'FD mesh'!I46,0) -> -3.5 | AC29: 0 | AD29: 0 | AE29: 0 | AF29: 0 | AG29: 0 | AH29: 0 | AI29: 0 | AJ29: 0 | AK29: 0 | AL29: 0 | AM29: 0 | AN29: 0 | AO29: 0 | AP29: 0 | AQ29: 0 | AR29: 0 | AS29: 0 | AT29: 0 | AU29: 0 | AV29: 0 | AW29: 0 | AX29: 0 | AY29: 0 | AZ29: 0 | BA29: 0 | BB29: 0 | BC29: 0 | BD29: 0 | BE29: 0 | BF29: 0 | BG29: 0 | BH29: 0
A30: 0 | B30: 0 | C30: 0 | D30: 0 | E30: 0 | F30: 0 | G30: 0 | H30: 0 | I30: 0 | J30: 0 | K30: 0 | L30: 0 | M30: 0 | N30: 0 | O30: 0 | P30: 0 | Q30: 0 | R30: 0 | S30: 0 | T30: 0 | U30: 0 | V30: 0 | W30: 0 | X30: 0 | Y30: 0 | Z30: 0 | AA30: =IF('FD mesh'!G47=1,-'FD mesh'!I46,0) -> -3.5 | AB30: ='FD mesh'!K47 -> 8.03 | AC30: =IF('FD mesh'!G48=1,-'FD mesh'!I47,0) -> -3.5 | AD30: 0 | AE30: 0 | AF30: 0 | AG30: 0 | AH30: 0 | AI30: 0 | AJ30: 0 | AK30: 0 | AL30: 0 | AM30: 0 | AN30: 0 | AO30: 0 | AP30: 0 | AQ30: 0 | AR30: 0 | AS30: 0 | AT30: 0 | AU30: 0 | AV30: 0 | AW30: 0 | AX30: 0 | AY30: 0 | AZ30: 0 | BA30: 0 | BB30: 0 | BC30: 0 | BD30: 0 | BE30: 0 | BF30: 0 | BG30: 0 | BH30: 0
A31: 0 | B31: 0 | C31: 0 | D31: 0 | E31: 0 | F31: 0 | G31: 0 | H31: 0 | I31: 0 | J31: 0 | K31: 0 | L31: 0 | M31: 0 | N31: 0 | O31: 0 | P31: 0 | Q31: 0 | R31: 0 | S31: 0 | T31: 0 | U31: 0 | V31: 0 | W31: 0 | X31: 0 | Y31: 0 | Z31: 0 | AA31: 0 | AB31: =IF('FD mesh'!G48=1,-'FD mesh'!I47,0) -> -3.5 | AC31: ='FD mesh'!K48 -> 108.0724 | AD31: =IF('FD mesh'!G49=1,-'FD mesh'!I48,0) -> -83.039216 | AE31: 0 | AF31: 0 | AG31: 0 | AH31: 0 | AI31: 0 | AJ31: 0 | AK31: 0 | AL31: 0 | AM31: 0 | AN31: 0 | AO31: 0 | AP31: 0 | AQ31: 0 | AR31: 0 | AS31: 0 | AT31: 0 | AU31: 0 | AV31: 0 | AW31: 0 | AX31: 0 | AY31: 0 | AZ31: 0 | BA31: 0 | BB31: 0 | BC31: 0 | BD31: 0 | BE31: 0 | BF31: 0 | BG31: 0 | BH31: 0
A32: 0 | B32: 0 | C32: 0 | D32: 0 | E32: 0 | F32: 0 | G32: 0 | H32: 0 | I32: 0 | J32: 0 | K32: 0 | L32: 0 | M32: 0 | N32: 0 | O32: 0 | P32: 0 | Q32: 0 | R32: 0 | S32: 0 | T32: 0 | U32: 0 | V32: 0 | W32: 0 | X32: 0 | Y32: 0 | Z32: 0 | AA32: 0 | AB32: 0 | AC32: =IF('FD mesh'!G49=1,-'FD mesh'!I48,0) -> -83.039216 | AD32: ='FD mesh'!K49 -> 208.1148 | AE32: =IF('FD mesh'!G50=1,-'FD mesh'!I49,0) -> -83.039216 | AF32: 0 | AG32: 0 | AH32: 0 | AI32: 0 | AJ32: 0 | AK32: 0 | AL32: 0 | AM32: 0 | AN32: 0 | AO32: 0 | AP32: 0 | AQ32: 0 | AR32: 0 | AS32: 0 | AT32: 0 | AU32: 0 | AV32: 0 | AW32: 0 | AX32: 0 | AY32: 0 | AZ32: 0 | BA32: 0 | BB32: 0 | BC32: 0 | BD32: 0 | BE32: 0 | BF32: 0 | BG32: 0 | BH32: 0
A33: 0 | B33: 0 | C33: 0 | D33: 0 | E33: 0 | F33: 0 | G33: 0 | H33: 0 | I33: 0 | J33: 0 | K33: 0 | L33: 0 | M33: 0 | N33: 0 | O33: 0 | P33: 0 | Q33: 0 | R33: 0 | S33: 0 | T33: 0 | U33: 0 | V33: 0 | W33: 0 | X33: 0 | Y33: 0 | Z33: 0 | AA33: 0 | AB33: 0 | AC33: 0 | AD33: =IF('FD mesh'!G50=1,-'FD mesh'!I49,0) -> -83.039216 | AE33: ='FD mesh'!K50 -> 208.1148 | AF33: =IF('FD mesh'!G51=1,-'FD mesh'!I50,0) -> -83.039216 | AG33: 0 | AH33: 0 | AI33: 0 | AJ33: 0 | AK33: 0 | AL33: 0 | AM33: 0 | AN33: 0 | AO33: 0 | AP33: 0 | AQ33: 0 | AR33: 0 | AS33: 0 | AT33: 0 | AU33: 0 | AV33: 0 | AW33: 0 | AX33: 0 | AY33: 0 | AZ33: 0 | BA33: 0 | BB33: 0 | BC33: 0 | BD33: 0 | BE33: 0 | BF33: 0 | BG33: 0 | BH33: 0
A34: 0 | B34: 0 | C34: 0 | D34: 0 | E34: 0 | F34: 0 | G34: 0 | H34: 0 | I34: 0 | J34: 0 | K34: 0 | L34: 0 | M34: 0 | N34: 0 | O34: 0 | P34: 0 | Q34: 0 | R34: 0 | S34: 0 | T34: 0 | U34: 0 | V34: 0 | W34: 0 | X34: 0 | Y34: 0 | Z34: 0 | AA34: 0 | AB34: 0 | AC34: 0 | AD34: 0 | AE34: =IF('FD mesh'!G51=1,-'FD mesh'!I50,0) -> -83.039216 | AF34: ='FD mesh'!K51 -> 208.1148 | AG34: =IF('FD mesh'!G52=1,-'FD mesh'!I51,0) -> -83.039216 | AH34: 0 | AI34: 0 | AJ34: 0 | AK34: 0 | AL34: 0 | AM34: 0 | AN34: 0 | AO34: 0 | AP34: 0 | AQ34: 0 | AR34: 0 | AS34: 0 | AT34: 0 | AU34: 0 | AV34: 0 | AW34: 0 | AX34: 0 | AY34: 0 | AZ34: 0 | BA34: 0 | BB34: 0 | BC34: 0 | BD34: 0 | BE34: 0 | BF34: 0 | BG34: 0 | BH34: 0
A35: 0 | B35: 0 | C35: 0 | D35: 0 | E35: 0 | F35: 0 | G35: 0 | H35: 0 | I35: 0 | J35: 0 | K35: 0 | L35: 0 | M35: 0 | N35: 0 | O35: 0 | P35: 0 | Q35: 0 | R35: 0 | S35: 0 | T35: 0 | U35: 0 | V35: 0 | W35: 0 | X35: 0 | Y35: 0 | Z35: 0 | AA35: 0 | AB35: 0 | AC35: 0 | AD35: 0 | AE35: 0 | AF35: =IF('FD mesh'!G52=1,-'FD mesh'!I51,0) -> -83.039216 | AG35: ='FD mesh'!K52 -> 208.1148 | AH35: =IF('FD mesh'!G53=1,-'FD mesh'!I52,0) -> -83.039216 | AI35: 0 | AJ35: 0 | AK35: 0 | AL35: 0 | AM35: 0 | AN35: 0 | AO35: 0 | AP35: 0 | AQ35: 0 | AR35: 0 | AS35: 0 | AT35: 0 | AU35: 0 | AV35: 0 | AW35: 0 | AX35: 0 | AY35: 0 | AZ35: 0 | BA35: 0 | BB35: 0 | BC35: 0 | BD35: 0 | BE35: 0 | BF35: 0 | BG35: 0 | BH35: 0
A36: 0 | B36: 0 | C36: 0 | D36: 0 | E36: 0 | F36: 0 | G36: 0 | H36: 0 | I36: 0 | J36: 0 | K36: 0 | L36: 0 | M36: 0 | N36: 0 | O36: 0 | P36: 0 | Q36: 0 | R36: 0 | S36: 0 | T36: 0 | U36: 0 | V36: 0 | W36: 0 | X36: 0 | Y36: 0 | Z36: 0 | AA36: 0 | AB36: 0 | AC36: 0 | AD36: 0 | AE36: 0 | AF36: 0 | AG36: =IF('FD mesh'!G53=1,-'FD mesh'!I52,0) -> -83.039216 | AH36: ='FD mesh'!K53 -> 208.1148 | AI36: =IF('FD mesh'!G54=1,-'FD mesh'!I53,0) -> -83.039216 | AJ36: 0 | AK36: 0 | AL36: 0 | AM36: 0 | AN36: 0 | AO36: 0 | AP36: 0 | AQ36: 0 | AR36: 0 | AS36: 0 | AT36: 0 | AU36: 0 | AV36: 0 | AW36: 0 | AX36: 0 | AY36: 0 | AZ36: 0 | BA36: 0 | BB36: 0 | BC36: 0 | BD36: 0 | BE36: 0 | BF36: 0 | BG36: 0 | BH36: 0
A37: 0 | B37: 0 | C37: 0 | D37: 0 | E37: 0 | F37: 0 | G37: 0 | H37: 0 | I37: 0 | J37: 0 | K37: 0 | L37: 0 | M37: 0 | N37: 0 | O37: 0 | P37: 0 | Q37: 0 | R37: 0 | S37: 0 | T37: 0 | U37: 0 | V37: 0 | W37: 0 | X37: 0 | Y37: 0 | Z37: 0 | AA37: 0 | AB37: 0 | AC37: 0 | AD37: 0 | AE37: 0 | AF37: 0 | AG37: 0 | AH37: =IF('FD mesh'!G54=1,-'FD mesh'!I53,0) -> -83.039216 | AI37: ='FD mesh'!K54 -> 208.1148 | AJ37: =IF('FD mesh'!G55=1,-'FD mesh'!I54,0) -> -83.039216 | AK37: 0 | AL37: 0 | AM37: 0 | AN37: 0 | AO37: 0 | AP37: 0 | AQ37: 0 | AR37: 0 | AS37: 0 | AT37: 0 | AU37: 0 | AV37: 0 | AW37: 0 | AX37: 0 | AY37: 0 | AZ37: 0 | BA37: 0 | BB37: 0 | BC37: 0 | BD37: 0 | BE37: 0 | BF37: 0 | BG37: 0 | BH37: 0
A38: 0 | B38: 0 | C38: 0 | D38: 0 | E38: 0 | F38: 0 | G38: 0 | H38: 0 | I38: 0 | J38: 0 | K38: 0 | L38: 0 | M38: 0 | N38: 0 | O38: 0 | P38: 0 | Q38: 0 | R38: 0 | S38: 0 | T38: 0 | U38: 0 | V38: 0 | W38: 0 | X38: 0 | Y38: 0 | Z38: 0 | AA38: 0 | AB38: 0 | AC38: 0 | AD38: 0 | AE38: 0 | AF38: 0 | AG38: 0 | AH38: 0 | AI38: =IF('FD mesh'!G55=1,-'FD mesh'!I54,0) -> -83.039216 | AJ38: ='FD mesh'!K55 -> 208.1148 | AK38: =IF('FD mesh'!G56=1,-'FD mesh'!I55,0) -> -83.039216 | AL38: 0 | AM38: 0 | AN38: 0 | AO38: 0 | AP38: 0 | AQ38: 0 | AR38: 0 | AS38: 0 | AT38: 0 | AU38: 0 | AV38: 0 | AW38: 0 | AX38: 0 | AY38: 0 | AZ38: 0 | BA38: 0 | BB38: 0 | BC38: 0 | BD38: 0 | BE38: 0 | BF38: 0 | BG38: 0 | BH38: 0
A39: 0 | B39: 0 | C39: 0 | D39: 0 | E39: 0 | F39: 0 | G39: 0 | H39: 0 | I39: 0 | J39: 0 | K39: 0 | L39: 0 | M39: 0 | N39: 0 | O39: 0 | P39: 0 | Q39: 0 | R39: 0 | S39: 0 | T39: 0 | U39: 0 | V39: 0 | W39: 0 | X39: 0 | Y39: 0 | Z39: 0 | AA39: 0 | AB39: 0 | AC39: 0 | AD39: 0 | AE39: 0 | AF39: 0 | AG39: 0 | AH39: 0 | AI39: 0 | AJ39: =IF('FD mesh'!G56=1,-'FD mesh'!I55,0) -> -83.039216 | AK39: ='FD mesh'!K56 -> 208.1148 | AL39: =IF('FD mesh'!G57=1,-'FD mesh'!I56,0) -> -83.039216 | AM39: 0 | AN39: 0 | AO39: 0 | AP39: 0 | AQ39: 0 | AR39: 0 | AS39: 0 | AT39: 0 | AU39: 0 | AV39: 0 | AW39: 0 | AX39: 0 | AY39: 0 | AZ39: 0 | BA39: 0 | BB39: 0 | BC39: 0 | BD39: 0 | BE39: 0 | BF39: 0 | BG39: 0 | BH39: 0
A40: 0 | B40: 0 | C40: 0 | D40: 0 | E40: 0 | F40: 0 | G40: 0 | H40: 0 | I40: 0 | J40: 0 | K40: 0 | L40: 0 | M40: 0 | N40: 0 | O40: 0 | P40: 0 | Q40: 0 | R40: 0 | S40: 0 | T40: 0 | U40: 0 | V40: 0 | W40: 0 | X40: 0 | Y40: 0 | Z40: 0 | AA40: 0 | AB40: 0 | AC40: 0 | AD40: 0 | AE40: 0 | AF40: 0 | AG40: 0 | AH40: 0 | AI40: 0 | AJ40: 0 | AK40: =IF('FD mesh'!G57=1,-'FD mesh'!I56,0) -> -83.039216 | AL40: ='FD mesh'!K57 -> 208.1148 | AM40: =IF('FD mesh'!G58=1,-'FD mesh'!I57,0) -> -83.039216 | AN40: 0 | AO40: 0 | AP40: 0 | AQ40: 0 | AR40: 0 | AS40: 0 | AT40: 0 | AU40: 0 | AV40: 0 | AW40: 0 | AX40: 0 | AY40: 0 | AZ40: 0 | BA40: 0 | BB40: 0 | BC40: 0 | BD40: 0 | BE40: 0 | BF40: 0 | BG40: 0 | BH40: 0
A41: 0 | B41: 0 | C41: 0 | D41: 0 | E41: 0 | F41: 0 | G41: 0 | H41: 0 | I41: 0 | J41: 0 | K41: 0 | L41: 0 | M41: 0 | N41: 0 | O41: 0 | P41: 0 | Q41: 0 | R41: 0 | S41: 0 | T41: 0 | U41: 0 | V41: 0 | W41: 0 | X41: 0 | Y41: 0 | Z41: 0 | AA41: 0 | AB41: 0 | AC41: 0 | AD41: 0 | AE41: 0 | AF41: 0 | AG41: 0 | AH41: 0 | AI41: 0 | AJ41: 0 | AK41: 0 | AL41: =IF('FD mesh'!G58=1,-'FD mesh'!I57,0) -> -83.039216 | AM41: ='FD mesh'!K58 -> 208.1148 | AN41: =IF('FD mesh'!G59=1,-'FD mesh'!I58,0) -> -83.039216 | AO41: 0 | AP41: 0 | AQ41: 0 | AR41: 0 | AS41: 0 | AT41: 0 | AU41: 0 | AV41: 0 | AW41: 0 | AX41: 0 | AY41: 0 | AZ41: 0 | BA41: 0 | BB41: 0 | BC41: 0 | BD41: 0 | BE41: 0 | BF41: 0 | BG41: 0 | BH41: 0
...

Sheet FD inverse
A1: FD: MINVERSE of the system matrix (computed once)
A3: {=MINVERSE('FD A'!A3:BH62)} -> 0.033894335 | B3: 0.019247663 | C3: 0.012955012 | D3: 0.001258068 | E3: 0.00059405174 | F3: 0.00028050845 | G3: 0.00013245688 | H3: 6.2550958e-05 | I3: 2.9548257e-05 | J3: 1.3978156e-05 | K3: 6.6547548e-06 | L3: 3.2574626e-06 | M3: 1.7819771e-06 | N3: 1.3578056e-06 | O3: 7.9439807e-07 | P3: 4.6477057e-07 | Q3: 2.719184e-07 | R3: 1.5908793e-07 | S3: 9.3074774e-08 | T3: 5.4452191e-08 | U3: 3.185411e-08 | V3: 1.8630238e-08 | W3: 1.0888979e-08 | X3: 6.3521905e-09 | Y3: 3.6847613e-09 | Z3: 2.1017046e-09 | AA3: 1.1371496e-09 | AB3: 5.0724147e-10 | AC3: 2.6607262e-11 | AD3: 1.3248745e-11 | AE3: 6.5970487e-12 | AF3: 3.2849301e-12 | AG3: 1.6357189e-12 | AH3: 8.1454622e-13 | AI3: 4.0571561e-13 | AJ3: 2.0226759e-13 | AK3: 1.0121209e-13 | AL3: 5.1392474e-14 | AM3: 2.7588912e-14 | AN3: 1.7751494e-14 | AO3: 0 | AP3: 0 | AQ3: 0 | AR3: 0 | AS3: 0 | AT3: 0 | AU3: 0 | AV3: 0 | AW3: 0 | AX3: 0 | AY3: 0 | AZ3: 0 | BA3: 0 | BB3: 0 | BC3: 0 | BD3: 0 | BE3: 0 | BF3: 0 | BG3: 0 | BH3: 0
